Workbook

Sheet planning
B4: à finir pour
B5: fini
B6: test
B7: TEMPS POUR CORRIGER
B8: entamé
F9: 45989 | H9: 45996 | J9: 45996 | L9: 46010
B10: TACHES | D10: S5 | E10: interséance | F10: S6 | G10: inter | H10: S7 | I10: inter | J10: S8 | K10: inter | L10: S9
B12: Reporter nos valeurs
B13: calcul ecart de soufflage
B14: CLIM tout R9
B15: CLIM recyclage
B16: recup roue
B17: recup plaque
B18: ventilo convecteur

Sheet Données
O3: Hiver | P3: 20°C
O4: été | P4: 25°C
K6: Local | L6: Surface [m²] | M6: Hauteur [m] | N6: Volume [m³] | O6: T°_Hiv [°C] | P6: HR Hiv [%] | Q6: T°_Eté [°C] | R6: HR été [%] | S6: Occup. [Pers.] | T6: Occup. [m²/occup.] | U6: Apports internes [kW] | V6: Q+ [kW] | W6: Q- [kW]
K7: 1.COFFRE FORT | L7: {=TRANSPOSE(K58:AE58)/3.6} -> 30.36 | M7: 3.6 | N7: =L7*M7 -> 109.296 | O7: 20 | P7: 50 | Q7: 25 | R7: 50 | S7: 1 | T7: =0 -> 0 | U7: =U35/1000 -> 0.444645 | V7: =30/(10^3)*L7+U7 -> 1.355445 | W7: =50*L7/1000 -> 1.518
K8: 2.KITCHENETTE | L8: 22.85 | M8: 3.6 | N8: =L8*M8 -> 82.26 | O8: 20 | P8: 50 | Q8: 25 | R8: 50 | S8: 10 | T8: =L8/S8 -> 2.285 | U8: =U36/1000 -> 1.453242 | V8: =30/(10^3)*L8+U8 -> 2.138742 | W8: =50*L8/1000 -> 1.1425
K9: 3.ESCALIER | L9: 12.41 | M9: 3.6 | N9: =L9*M9 -> 44.676 | O9: 20 | P9: 50 | Q9: 25 | R9: 50 | S9: 1 | T9: =0 -> 0 | U9: =U37/1000 -> 0.116128 | V9: =30/(10^3)*L9+U9 -> 0.488428 | W9: =50*L9/1000 -> 0.6205
K10: 4.Bureau 4 | L10: 27.488889 | M10: 3.6 | N10: =L10*M10 -> 98.96 | O10: 20 | P10: 50 | Q10: 25 | R10: 50 | S10: 3 | T10: 0 | U10: =U38/1000 -> 1.4143466 | V10: =30/(10^3)*L10+U10 -> 2.2390133 | W10: =50*L10/1000 -> 1.3744444
K11: 5.Bureau5 | L11: 18.019444 | M11: 3.6 | N11: =L11*M11 -> 64.87 | O11: 20 | P11: 50 | Q11: 25 | R11: 50 | S11: 3 | T11: =L11/S11 -> 6.0064815 | U11: =U39/1000 -> 0.82667667 | V11: =30/(10^3)*L11+U11 -> 1.36726 | W11: =50*L11/1000 -> 0.90097222
K12: 6.Bureau 6 | L12: 18.13 | M12: 3.6 | N12: =L12*M12 -> 65.268 | O12: 20 | P12: 50 | Q12: 25 | R12: 50 | S12: 3 | T12: =L12/S12 -> 6.0433333 | U12: =U40/1000 -> 0.82667667 | V12: =30/(10^3)*L12+U12 -> 1.3705767 | W12: =50*L12/1000 -> 0.9065
K13: 7.Bureau 7 | L13: 18.13 | M13: 3.6 | N13: =L13*M13 -> 65.268 | O13: 20 | P13: 50 | Q13: 25 | R13: 50 | S13: 3 | T13: =L13/S13 -> 6.0433333 | U13: =U41/1000 -> 0.86315667 | V13: =30/(10^3)*L13+U13 -> 1.4070567 | W13: =50*L13/1000 -> 0.9065
K14: 8.SDR | L14: 33.3 | M14: 3.6 | N14: =L14*M14 -> 119.88 | O14: 20 | P14: 50 | Q14: 25 | R14: 50 | S14: 14 | T14: =L14/S14 -> 2.3785714 | U14: =U42/1000 -> 2.0638063 | V14: =30/(10^3)*L14+U14 -> 3.0628063 | W14: =50*L14/1000 -> 1.665
K15: 9.Couloir droite | L15: 45.8 | M15: 3.6 | N15: =L15*M15 -> 164.88 | O15: 20 | P15: 50 | Q15: 25 | R15: 50 | S15: 1 | T15: 0 | U15: =U43/1000 -> 0.3925 | V15: =30/(10^3)*L15+U15 -> 1.7665 | W15: =50*L15/1000 -> 2.29
K16: 10.Approvisionnement | L16: 7.24 | M16: 3.6 | N16: =L16*M16 -> 26.064 | O16: 20 | P16: 50 | Q16: 25 | R16: 50 | S16: 1 | T16: 0 | U16: =U44/1000 -> 0.068724 | V16: =30/(10^3)*L16+U16 -> 0.285924 | W16: =50*L16/1000 -> 0.362
K17: 11/12/13. Entrée | L17: 18.2075 | M17: 3.6 | N17: =L17*M17 -> 65.547 | O17: 20 | P17: 50 | Q17: 25 | R17: 50 | S17: 1 | T17: =0 -> 0 | U17: =U45/1000 -> 0.14566 | V17: =30/(10^3)*L17+U17 -> 0.691885 | W17: =50*L17/1000 -> 0.910375
K18: 14.Distrib | L18: 21.21 | M18: 3.6 | N18: =L18*M18 -> 76.356 | O18: 20 | P18: 50 | Q18: 25 | R18: 50 | S18: 3 | T18: =L18/S18 -> 7.07 | U18: =U46/1000 -> 2.3345607 | V18: =30/(10^3)*L18+U18 -> 2.9708607 | W18: =50*L18/1000 -> 1.0605
K19: 15.Secretariat | L19: 30.02 | M19: 3.6 | N19: =L19*M19 -> 108.072 | O19: 20 | P19: 50 | Q19: 25 | R19: 50 | S19: 6 | T19: =L19/S19 -> 5.0033333 | U19: =U47/1000 -> 1.4059333 | V19: =30/(10^3)*L19+U19 -> 2.3065333 | W19: =50*L19/1000 -> 1.501
K20: 16.SDR | L20: 52.62 | M20: 3.6 | N20: =L20*M20 -> 189.432 | O20: 20 | P20: 50 | Q20: 25 | R20: 50 | S20: 26 | T20: =L20/S20 -> 2.0238462 | U20: =U48/1000 -> 3.6597178 | V20: =30/(10^3)*L20+U20 -> 5.2383178 | W20: =50*L20/1000 -> 2.631
K21: 17. Salle d'attente | L21: 55.32 | M21: 3.6 | N21: =L21*M21 -> 199.152 | O21: 20 | P21: 50 | Q21: 25 | R21: 50 | S21: 9 | T21: 0 | U21: =U49/1000 -> 1.4499468 | V21: =30/(10^3)*L21+U21 -> 3.1095468 | W21: =50*L21/1000 -> 2.766
K22: 18.WC individuelle | L22: 4.73 | M22: 3.6 | N22: =L22*M22 -> 17.028 | O22: 20 | P22: 50 | Q22: 25 | R22: 50 | S22: 1 | T22: =L22/S22 -> 4.73 | U22: =U50/1000 -> 0.15447889 | V22: =30/(10^3)*L22+U22 -> 0.29637889 | W22: =50*L22/1000 -> 0.2365
K23: 19.WC PMR | L23: 4.37 | M23: 3.6 | N23: =L23*M23 -> 15.732 | O23: 20 | P23: 50 | Q23: 25 | R23: 50 | S23: 1 | T23: =L23/S23 -> 4.37 | U23: =U51/1000 -> 0.15159889 | V23: =30/(10^3)*L23+U23 -> 0.28269889 | W23: =50*L23/1000 -> 0.2185
K24: 20.WC femme | L24: 17.4 | M24: 3.6 | N24: =L24*M24 -> 62.64 | O24: 20 | P24: 50 | Q24: 25 | R24: 50 | S24: 5 | T24: =L24/S24 -> 3.48 | U24: =U52/1000 -> 0.72239444 | V24: =30/(10^3)*L24+U24 -> 1.2443944 | W24: =50*L24/1000 -> 0.87
K25: 21.WC homme | L25: 12.27 | M25: 3.6 | N25: =L25*M25 -> 44.172 | O25: 20 | P25: 50 | Q25: 25 | R25: 50 | S25: 5 | T25: =L25/S25 -> 2.454 | U25: =U53/1000 -> 0.68135444 | V25: =30/(10^3)*L25+U25 -> 1.0494544 | W25: =50*L25/1000 -> 0.6135
K26: 22.Trappe | L26: 10.89 | M26: 3.6 | N26: =L26*M26 -> 39.204 | O26: 20 | P26: 50 | Q26: 25 | R26: 50 | S26: 0 | T26: =0 -> 0 | U26: =U54/1000 -> 0 | V26: =30/(10^3)*L26+U26 -> 0.3267 | W26: =50*L26/1000 -> 0.5445
K27: 23.Trémis | L27: 3.514 | M27: 3.6 | N27: =L27*M27 -> 12.6504 | O27: 20 | P27: 50 | Q27: 25 | R27: 50 | S27: 0 | T27: =0 -> 0 | U27: =U55/1000 -> 0 | V27: =30/(10^3)*L27+U27 -> 0.10542 | W27: =50*L27/1000 -> 0.1757
L28: =SUM(_xlfn.ANCHORARRAY(L7)) -> 464.27983 | U28: =SUM(U7:U27) -> 19.175547 | V28: =SUM(V7:V27) -> 33.103942 | W28: =SUM(W7:W27) -> 23.213992
I29: =SUM(L22:L25) -> 38.77
K34: 1.COFFRE FORT
K35: 2.KITCHENETTE | O35: 0 | U35: 444.645 | W35: 1270.8671
K36: 3.ESCALIER | O36: 10 | U36: 1453.242 | W36: 2449.9142
K37: 4.Bureau 4 | O37: 0 | U37: 116.128 | W37: 290.32
K38: 5.Bureau5 | O38: 7 | U38: 1414.3466 | W38: 2795.9102
K39: 6.Bureau 6 | O39: 3 | U39: 826.67667 | W39: 1953.3871
K40: 7.Bureau 7 | O40: 3 | U40: 826.67667 | W40: 1518.0605
K41: 8.SDR | O41: 3 | U41: 863.15667 | W41: 1703.1369
K42: 9.Couloir droite | O42: 14 | U42: 2063.8063 | W42: 4765.3844
K43: 10.Approvisionnement | O43: 0 | U43: 392.5 | W43: 2254.6884
K44: 11/12/13. Entrée | O44: 0 | U44: 68.724 | W44: 314.45948
K45: 14.Distrib | O45: 0 | U45: 145.66 | W45: 1584.5081
K46: 15.Secretariat | O46: 3 | U46: 2334.5607 | W46: 856.61342
... K54: 23.Trémis | O54: 0 | U54: 0 | W54: 217.8
...

Sheet Ecart de soufflage
L3: [W/m²] | N3: ΔT soufflage hiver min | O3: =MIN(L9:L29) -> 5.6694677 | P3: [°C] | R3: %recyclageété min | S3: =MIN($Q$9:$Q$26) -> 30.581462
F4: diagramme psychométrique a une temperature donné | K4: Apports | L4: 30 | N4: ΔT soufflage été min | O4: =IF(MIN(M9:M29)<8,MIN(M9:M29),8) -> 8 | R4: %recyclage hiver min | S4: =$P$22 -> 0
K5: Déperditions | L5: 50 | N5: qm tot hiver | O5: =SUM(N9:N29) -> 4.0945628 | P5: [kgas/s]
N6: qm tot été | O6: =SUM(O9:O29) -> 4.1379928
H7: qm [kgas/s] | L7: ΔT soufflage [°C] | N7: new qm [kgas/s] | R7: Apport en eau kg/s
B8: Nom du local | C8: Surface [m²] | D8: Présence humaine | E8: Débit minimum [m3/h] | F8: v hiver [m³/kgas] | G8: v été [m³/kgas] | H8: hiver | I8: été | J8: Q- [kW] | K8: Q+ [kW] | L8: hiver | M8: été | N8: hiver | O8: été | P8: %recyclagehiv | Q8: %recyclageété | R8: HIVER | S8: ÉTÉ
B9: 1.COFFRE FORT | C9: =Données!L7 -> 30.36 | D9: =Données!S7 -> 1 | E9: =54*D9 -> 54 | F9: 0.8404 | G9: 0.858 | H9: =E9/F9/3600 -> 0.017848644 | I9: =E9/G9/3600 -> 0.017482517 | J9: =Données!W7 -> 1.518 | K9: =Données!V7 -> 1.355445 | N9: =J9/O$3 -> 0.26775 | O9: =K9/O$4 -> 0.16943063 | P9: =100 * (1-H9/N9) -> 93.33384 | Q9: =100 * (1-I9/O9) -> 89.681607 | R9: =$D9*38/3600/1000 -> 1.0555556e-05 | S9: =$D9*70/3600/1000 -> 1.9444444e-05
B10: 2.KITCHENETTE | C10: =Données!L8 -> 22.85 | D10: =Données!S8 -> 10 | E10: =54*D10 -> 540 | F10: 0.8404 | G10: 0.858 | H10: =E10/F10/3600 -> 0.17848644 | I10: =E10/G10/3600 -> 0.17482517 | J10: =Données!W8 -> 1.1425 | K10: =Données!V8 -> 2.138742 | L10: =J10/H10 -> 6.4010467 | M10: =K10/I10 -> 12.233604 | N10: =J10/O$3 -> 0.20151804 | O10: =K10/O$4 -> 0.26734275 | P10: =100 * (1-H10/N10) -> 11.429052 | Q10: =100 * (1-I10/O10) -> 34.606353 | R10: =$D10*38/3600/1000 -> 0.00010555556 | S10: =$D10*70/3600/1000 -> 0.00019444444
B11: 3.ESCALIER | C11: =Données!L9 -> 12.41 | D11: =Données!S9 -> 1 | E11: =54*D11 -> 54 | F11: 0.8404 | G11: 0.858 | H11: =E11/F11/3600 -> 0.017848644 | I11: =E11/G11/3600 -> 0.017482517 | J11: =Données!W9 -> 0.6205 | K11: =Données!V9 -> 0.488428 | L11: =J11/H11 -> 34.764547 | M11: =K11/I11 -> 27.938082 | N11: =J11/O$3 -> 0.1094459 | O11: =K11/O$4 -> 0.0610535 | P11: =100 * (1-H11/N11) -> 83.691812 | Q11: =100 * (1-I11/O11) -> 71.365249 | R11: =$D11*38/3600/1000 -> 1.0555556e-05 | S11: =$D11*70/3600/1000 -> 1.9444444e-05
B12: 4.Bureau 4 | C12: =Données!L10 -> 27.488889 | D12: =Données!S10 -> 3 | E12: =54*D12 -> 162 | F12: 0.8404 | G12: 0.858 | H12: =E12/F12/3600 -> 0.053545931 | I12: =E12/G12/3600 -> 0.052447552 | J12: =Données!W10 -> 1.3744444 | K12: =Données!V10 -> 2.2390133 | L12: =J12/H12 -> 25.668514 | M12: =K12/I12 -> 42.69052 | N12: =J12/O$3 -> 0.24242919 | O12: =K12/O$4 -> 0.27987666 | P12: =100 * (1-H12/N12) -> 77.912754 | Q12: =100 * (1-I12/O12) -> 81.260477 | R12: =$D12*38/3600/1000 -> 3.1666667e-05 | S12: =$D12*70/3600/1000 -> 5.8333333e-05
B13: 5.Bureau5 | C13: =Données!L11 -> 18.019444 | D13: =Données!S11 -> 3 | E13: =54*D13 -> 162 | F13: 0.8404 | G13: 0.858 | H13: =E13/F13/3600 -> 0.053545931 | I13: =E13/G13/3600 -> 0.052447552 | J13: =Données!W11 -> 0.90097222 | K13: =Données!V11 -> 1.36726 | L13: =J13/H13 -> 16.826157 | M13: =K13/I13 -> 26.069091 | N13: =J13/O$3 -> 0.15891655 | O13: =K13/O$4 -> 0.1709075 | P13: =100 * (1-H13/N13) -> 66.305629 | Q13: =100 * (1-I13/O13) -> 69.312317 | R13: =$D13*38/3600/1000 -> 3.1666667e-05 | S13: =$D13*70/3600/1000 -> 5.8333333e-05
B14: 6.Bureau 6 | C14: =Données!L12 -> 18.13 | D14: =Données!S12 -> 3 | E14: =54*D14 -> 162 | F14: 0.8404 | G14: 0.858 | H14: =E14/F14/3600 -> 0.053545931 | I14: =E14/G14/3600 -> 0.052447552 | J14: =Données!W12 -> 0.9065 | K14: =Données!V12 -> 1.3705767 | L14: =J14/H14 -> 16.929391 | M14: =K14/I14 -> 26.132328 | N14: =J14/O$3 -> 0.15989155 | O14: =K14/O$4 -> 0.17132208 | P14: =100 * (1-H14/N14) -> 66.511095 | Q14: =100 * (1-I14/O14) -> 69.386578 | R14: =$D14*38/3600/1000 -> 3.1666667e-05 | S14: =$D14*70/3600/1000 -> 5.8333333e-05
B15: 7.Bureau 7 | C15: =Données!L13 -> 18.13 | D15: =Données!S13 -> 3 | E15: =54*D15 -> 162 | F15: 0.8404 | G15: 0.858 | H15: =E15/F15/3600 -> 0.053545931 | I15: =E15/G15/3600 -> 0.052447552 | J15: =Données!W13 -> 0.9065 | K15: =Données!V13 -> 1.4070567 | L15: =J15/H15 -> 16.929391 | M15: =K15/I15 -> 26.82788 | N15: =J15/O$3 -> 0.15989155 | O15: =K15/O$4 -> 0.17588208 | P15: =100 * (1-H15/N15) -> 66.511095 | Q15: =100 * (1-I15/O15) -> 70.180276 | R15: =$D15*38/3600/1000 -> 3.1666667e-05 | S15: =$D15*70/3600/1000 -> 5.8333333e-05
B16: 8.SDR | C16: =Données!L14 -> 33.3 | D16: =Données!S14 -> 14 | E16: =54*D16 -> 756 | F16: 0.8404 | G16: 0.858 | H16: =E16/F16/3600 -> 0.24988101 | I16: =E16/G16/3600 -> 0.24475524 | J16: =Données!W14 -> 1.665 | K16: =Données!V14 -> 3.0628063 | L16: =J16/H16 -> 6.6631714 | M16: =K16/I16 -> 12.513751 | N16: =J16/O$3 -> 0.29367836 | O16: =K16/O$4 -> 0.38285079 | P16: =100 * (1-H16/N16) -> 14.913375 | Q16: =100 * (1-I16/O16) -> 36.07033 | R16: =$D16*38/3600/1000 -> 0.00014777778 | S16: =$D16*58/3600/1000 -> 0.00022555556
B17: 9.Couloir droite | C17: =Données!L15 -> 45.8 | D17: =Données!S15 -> 1 | E17: =54*D17 -> 54 | F17: 0.8404 | G17: 0.858 | H17: =E17/F17/3600 -> 0.017848644 | I17: =E17/G17/3600 -> 0.017482517 | J17: =Données!W15 -> 2.29 | K17: =Données!V15 -> 1.7665 | L17: =J17/H17 -> 128.30107 | M17: =K17/I17 -> 101.0438 | N17: =J17/O$3 -> 0.40391799 | O17: =K17/O$4 -> 0.2208125 | P17: =100 * (1-H17/N17) -> 95.581122 | Q17: =100 * (1-I17/O17) -> 92.082641 | R17: =$D17*38/3600/1000 -> 1.0555556e-05 | S17: =$D17*70/3600/1000 -> 1.9444444e-05
B18: 10.Approvisionnement | C18: =Données!L16 -> 7.24 | D18: =Données!S16 -> 1 | E18: =54*D18 -> 54 | F18: 0.8404 | G18: 0.858 | H18: =E18/F18/3600 -> 0.017848644 | I18: =E18/G18/3600 -> 0.017482517 | J18: =Données!W16 -> 0.362 | K18: =Données!V16 -> 0.285924 | L18: =J18/H18 -> 20.281653 | M18: =K18/I18 -> 16.354853 | N18: =J18/O$3 -> 0.063850792 | O18: =K18/O$4 -> 0.0357405 | P18: =100 * (1-H18/N18) -> 72.046324 | Q18: =100 * (1-I18/O18) -> 51.084855 | R18: =$D18*38/3600/1000 -> 1.0555556e-05 | S18: =$D18*70/3600/1000 -> 1.9444444e-05
B19: 11/12/13. Entrée | C19: =Données!L17 -> 18.2075 | D19: =Données!S17 -> 1 | E19: =54*D19 -> 54 | F19: 0.8404 | G19: 0.858 | H19: =E19/F19/3600 -> 0.017848644 | I19: =E19/G19/3600 -> 0.017482517 | J19: =Données!W17 -> 0.910375 | K19: =Données!V17 -> 0.691885 | L19: =J19/H19 -> 51.005277 | M19: =K19/I19 -> 39.575822 | N19: =J19/O$3 -> 0.16057504 | O19: =K19/O$4 -> 0.086485625 | P19: =100 * (1-H19/N19) -> 88.884547 | Q19: =100 * (1-I19/O19) -> 79.785638 | R19: =$D19*38/3600/1000 -> 1.0555556e-05 | S19: =$D19*70/3600/1000 -> 1.9444444e-05
B20: 14.Distrib | C20: =Données!L18 -> 21.21 | D20: =Données!S18 -> 3 | E20: =54*D20 -> 162 | F20: 0.8404 | G20: 0.858 | H20: =E20/F20/3600 -> 0.053545931 | I20: =E20/G20/3600 -> 0.052447552 | J20: =Données!W18 -> 1.0605 | K20: =Données!V18 -> 2.9708607 | L20: =J20/H20 -> 19.805427 | M20: =K20/I20 -> 56.64441 | N20: =J20/O$3 -> 0.1870546 | O20: =K20/O$4 -> 0.37135758 | P20: =100 * (1-H20/N20) -> 71.37417 | Q20: =100 * (1-I20/O20) -> 85.876806 | R20: =$D20*38/3600/1000 -> 3.1666667e-05 | S20: =$D20*70/3600/1000 -> 5.8333333e-05
B21: 15.Secretariat | C21: =Données!L19 -> 30.02 | D21: =Données!S19 -> 6 | E21: =54*D21 -> 324 | F21: 0.8404 | G21: 0.858 | H21: =E21/F21/3600 -> 0.10709186 | I21: =E21/G21/3600 -> 0.1048951 | J21: =Données!W19 -> 1.501 | K21: =Données!V19 -> 2.3065333 | L21: =J21/H21 -> 14.016004 | M21: =K21/I21 -> 21.988951 | N21: =J21/O$3 -> 0.26475149 | O21: =K21/O$4 -> 0.28831667 | P21: =100 * (1-H21/N21) -> 59.550044 | Q21: =100 * (1-I21/O21) -> 63.618092 | R21: =$D21*38/3600/1000 -> 6.3333333e-05 | S21: =$D21*70/3600/1000 -> 0.00011666667
B22: 16.SDR | C22: =Données!L20 -> 52.62 | D22: =Données!S20 -> 26 | E22: =54*D22 -> 1404 | F22: 0.8404 | G22: 0.858 | H22: =E22/F22/3600 -> 0.46406473 | I22: =E22/G22/3600 -> 0.45454545 | J22: =Données!W20 -> 2.631 | K22: =Données!V20 -> 5.2383178 | L22: =J22/H22 -> 5.6694677 | M22: =K22/I22 -> 11.524299 | N22: =J22/O$3 -> 0.46406473 | O22: =K22/O$4 -> 0.65478972 | P22: =100 * (1-H22/N22) -> 0 | Q22: =100 * (1-I22/O22) -> 30.581462 | R22: =$D22*38/3600/1000 -> 0.00027444444 | S22: =$D22*58/3600/1000 -> 0.00041888889
B23: 17. Salle d'attente | C23: =Données!L21 -> 55.32 | D23: =Données!S21 -> 9 | E23: =54*D23 -> 486 | F23: 0.8404 | G23: 0.858 | H23: =E23/F23/3600 -> 0.16063779 | I23: =E23/G23/3600 -> 0.15734266 | J23: =Données!W21 -> 2.766 | K23: =Données!V21 -> 3.1095468 | L23: =J23/H23 -> 17.218862 | M23: =K23/I23 -> 19.762897 | N23: =J23/O$3 -> 0.48787649 | O23: =K23/O$4 -> 0.38869335 | R23: =$D23*38/3600/1000 -> 9.5e-05 | S23: =$D23*70/3600/1000 -> 0.000175
B24: 18.WC individuelle | C24: =Données!L22 -> 4.73 | D24: =Données!S22 -> 1 | E24: =54*D24 -> 54 | F24: 0.8404 | G24: 0.858 | H24: =E24/F24/3600 -> 0.017848644 | I24: =E24/G24/3600 -> 0.017482517 | J24: =Données!W22 -> 0.2365 | K24: =Données!V22 -> 0.29637889 | L24: =J24/H24 -> 13.250307 | M24: =K24/I24 -> 16.952872 | N24: =J24/O$3 -> 0.041714675 | O24: =K24/O$4 -> 0.037047361 | P24: =100 * (1-H24/N24) -> 57.212555 | Q24: =100 * (1-I24/O24) -> 52.810357 | R24: =$D24*38/3600/1000 -> 1.0555556e-05 | S24: =$D24*70/3600/1000 -> 1.9444444e-05
B25: 19.WC PMR | C25: =Données!L23 -> 4.37 | D25: =Données!S23 -> 1 | E25: =54*D25 -> 54 | F25: 0.8404 | G25: 0.858 | H25: =E25/F25/3600 -> 0.017848644 | I25: =E25/G25/3600 -> 0.017482517 | J25: =Données!W23 -> 0.2185 | K25: =Données!V23 -> 0.28269889 | L25: =J25/H25 -> 12.241827 | M25: =K25/I25 -> 16.170376 | N25: =J25/O$3 -> 0.038539773 | O25: =K25/O$4 -> 0.035337361 | P25: =100 * (1-H25/N25) -> 53.687731 | Q25: =100 * (1-I25/O25) -> 50.526817 | R25: =$D25*38/3600/1000 -> 1.0555556e-05 | S25: =$D25*70/3600/1000 -> 1.9444444e-05
B26: 20.WC femme | C26: =Données!L24 -> 17.4 | D26: =Données!S24 -> 5 | E26: =54*D26 -> 270 | F26: 0.8404 | G26: 0.858 | H26: =E26/F26/3600 -> 0.089243218 | I26: =E26/G26/3600 -> 0.087412587 | J26: =Données!W24 -> 0.87 | K26: =Données!V24 -> 1.2443944 | L26: =J26/H26 -> 9.74864 | M26: =K26/I26 -> 14.235872 | N26: =J26/O$3 -> 0.15345356 | O26: =K26/O$4 -> 0.15554931 | P26: =100 * (1-H26/N26) -> 41.843501 | Q26: =100 * (1-I26/O26) -> 43.803936 | R26: =$D26*38/3600/1000 -> 5.2777778e-05 | S26: =$D26*70/3600/1000 -> 9.7222222e-05
B27: 21.WC homme | C27: =Données!L25 -> 12.27 | D27: =Données!S25 -> 5 | E27: =54*D27 -> 270 | F27: 0.8404 | G27: 0.858 | H27: =E27/F27/3600 -> 0.089243218 | I27: =E27/G27/3600 -> 0.087412587 | J27: =Données!W25 -> 0.6135 | K27: =Données!V25 -> 1.0494544 | L27: =J27/H27 -> 6.874472 | M27: =K27/I27 -> 12.005759 | N27: =J27/O$3 -> 0.10821122 | O27: =K27/O$4 -> 0.13118181 | P27: =100 * (1-H27/N27) -> 17.528682 | Q27: =100 * (1-I27/O27) -> 33.365312 | R27: =$D27*38/3600/1000 -> 5.2777778e-05 | S27: =$D27*70/3600/1000 -> 9.7222222e-05
B28: 22.Trappe | C28: =Données!L26 -> 10.89 | D28: =Données!S26 -> 0 | E28: =54*D28 -> 0 | F28: 0.8404 | G28: 0.858 | H28: =E28/F28/3600 -> 0 | I28: =E28/G28/3600 -> 0 | J28: =Données!W26 -> 0.5445 | K28: =Données!V26 -> 0.3267 | N28: =J28/O$3 -> 0.096040762 | O28: =K28/O$4 -> 0.0408375 | P28: =100 * (1-H28/N28) -> 100 | Q28: =100 * (1-I28/O28) -> 100 | R28: =$D28*38/3600/1000 -> 0 | S28: =$D28*70/3600/1000 -> 0
B29: 23.Trémis | C29: =Données!L27 -> 3.514 | D29: =Données!S27 -> 0 | E29: =54*D29 -> 0 | F29: 0.8404 | G29: 0.858 | H29: =E29/F29/3600 -> 0 | I29: =E29/G29/3600 -> 0 | J29: =Données!W27 -> 0.1757 | K29: =Données!V27 -> 0.10542 | N29: =J29/O$3 -> 0.030990564 | O29: =K29/O$4 -> 0.0131775 | P29: =100 * (1-H29/N29) -> 100 | Q29: =100 * (1-I29/O29) -> 100 | R29: =$D29*38/3600/1000 -> 0 | S29: =$D29*70/3600/1000 -> 0
E30: =SUM(E9:E29) -> 5238 | H30: =SUM(H9:H29) -> 1.7313184 | I30: =SUM(I9:I29) -> 1.6958042 | L30: =MIN(L9:L29) -> 5.6694677 | M30: =MIN(M9:M29) -> 11.524299 | N30: =SUM(N9:N29) -> 4.0945628 | O30: =SUM(O9:O29) -> 4.1379928 | P30: %recyclé | R30: =SUM(R9:R29) -> 0.0010238889 | S30: =SUM(S9:S29) -> 0.0017527778
L31: Minimum ecart soufflage | P31: =MIN(P9:P29) -> 0 | Q31: =MIN(Q9:Q29) -> 30.581462 | R31: Ecart Absolu g/kg
P32: fois 1000 pour passer en g/kg | R32: =R30/$O5*1000 -> 0.25006061 | S32: =S30/$O6*1000 -> 0.42358164
C41: 54.648 | D41: 82.26 | E41: 0 | F41: 98.96 | G41: 64.87 | H41: 65.268 | I41: 65.268 | J41: 239.76 | K41: 82.44 | L41: 13.032 | M41: 32.7735 | N41: 38.178 | O41: 108.072 | P41: 378.864 | Q41: 99.576 | R41: 25.542 | S41: 23.598 | T41: 93.96 | U41: 66.258 | V41: 0 | W41: 0

Sheet Climatisation  sans recyclage
C2: Régime hivernal | J2: Régime estival
B3: Local | C3: qm hiver [kgas/s] | D3: ∆he1 [kJ/kg] | E3: Ppré [kW] = qm hiver . ∆he1 | F3: ∆hs [kJ/kg] | G3: Ppost [kW] =qm hiver . ∆hs3 | H3: ∆x13 | I3: qm,eau [kgeau/h] | J3: qm été [kgas/s] | K3: ∆hs3 [kJ/kg] | L3: Ppost [kW] =qm été . ∆hs3 | M3: ∆he3 [kJ/kg] | N3: Pfr [kW] = qm été . ∆he3 | O3: ∆xe3 [geau/kgas] | P3: qm,eau [kgeau/h]
B4: 1.COFFRE FORT | C4: ='Ecart de soufflage'!N9 -> 0.26775 | D4: =W$8-W$7 -> 31.744494 | E4: =C4*D4 -> 8.4995885 | F4: =W$11-W$9 -> 16.6 | G4: =C4*F4 -> 4.4446501 | H4: =V$9-V$8 -> 5.6 | I4: =C4*H4*3.6 -> 5.3978401 | J4: ='Ecart de soufflage'!O9 -> 0.16943063 | K4: =W$19-W$17 -> 3.1728382 | L4: =J4*K4 -> 0.53757597 | M4: =W$17-W$16 -> -31.472838 | N4: =J4*M4 -> -5.3324627 | O4: =V$16-V$17 -> 5.1 | P4: =J4*O4*3.6 -> 3.1107463
B5: 2.KITCHENETTE | C5: ='Ecart de soufflage'!N10 -> 0.20151804 | D5: =W$8-W$7 -> 31.744494 | E5: =C5*D5 -> 6.3970882 | F5: =W$11-W$9 -> 16.6 | G5: =C5*F5 -> 3.3451994 | H5: =V$9-V$8 -> 5.6 | I5: =C5*H5*3.6 -> 4.0626036 | J5: ='Ecart de soufflage'!O10 -> 0.26734275 | K5: =W$19-W$17 -> 3.1728382 | L5: =J5*K5 -> 0.84823531 | M5: =W$17-W$16 -> -31.472838 | N5: =J5*M5 -> -8.4140352 | O5: =V$16-V$17 -> 5.1 | P5: =J5*O5*3.6 -> 4.9084129 | S5: Source | T5: Régime hivernale sans recyclage
B6: 3.ESCALIER | C6: ='Ecart de soufflage'!N11 -> 0.1094459 | D6: =W$8-W$7 -> 31.744494 | E6: =C6*D6 -> 3.4743048 | F6: =W$11-W$9 -> 16.6 | G6: =C6*F6 -> 1.816802 | H6: =V$9-V$8 -> 5.6 | I6: =C6*H6*3.6 -> 2.2064294 | J6: ='Ecart de soufflage'!O11 -> 0.0610535 | K6: =W$19-W$17 -> 3.1728382 | L6: =J6*K6 -> 0.19371288 | M6: =W$17-W$16 -> -31.472838 | N6: =J6*M6 -> -1.9215269 | O6: =V$16-V$17 -> 5.1 | P6: =J6*O6*3.6 -> 1.1209423 | U6: T [°C] | V6: x [geau/kgas] | W6: h [kJ/kgas] | X6: HR [%] | Y6: v [m³/kgas] | Z6: pv [Pa] | AA6: ps [Pa]
B7: 4.Bureau 4 | C7: ='Ecart de soufflage'!N12 -> 0.24242919 | D7: =W$8-W$7 -> 31.744494 | E7: =C7*D7 -> 7.695792 | F7: =W$11-W$9 -> 16.6 | G7: =C7*F7 -> 4.0243245 | H7: =V$9-V$8 -> 5.6 | I7: =C7*H7*3.6 -> 4.8873724 | J7: ='Ecart de soufflage'!O12 -> 0.27987666 | K7: =W$19-W$17 -> 3.1728382 | L7: =J7*K7 -> 0.88800337 | M7: =W$17-W$16 -> -31.472838 | N7: =J7*M7 -> -8.8085129 | O7: =V$16-V$17 -> 5.1 | P7: =J7*O7*3.6 -> 5.1385355 | T7: e | U7: -8 | V7: 1.7 | W7: =1.009*(U7)+V7/1000*(2501.6+1.854*(U7)) -> -3.8444944 | X7: 90 | Y7: =(U7+273.15)*287.05/101325 -> 0.7511602 | Z7: =(X7/100)*AA7 -> 278.96016 | AA7: =4.689*(1.486+(U7)/100)^12.3 -> 309.95574
B8: 5.Bureau5 | C8: ='Ecart de soufflage'!N13 -> 0.15891655 | D8: =W$8-W$7 -> 31.744494 | E8: =C8*D8 -> 5.0447254 | F8: =W$11-W$9 -> 16.6 | G8: =C8*F8 -> 2.6380147 | H8: =V$9-V$8 -> 5.6 | I8: =C8*H8*3.6 -> 3.2037576 | J8: ='Ecart de soufflage'!O13 -> 0.1709075 | K8: =W$19-W$17 -> 3.1728382 | L8: =J8*K8 -> 0.54226185 | M8: =W$17-W$16 -> -31.472838 | N8: =J8*M8 -> -5.3789441 | O8: =V$16-V$17 -> 5.1 | P8: =J8*O8*3.6 -> 3.1378617 | T8: 1 | U8: =23.5 -> 23.5 | V8: =1.7 -> 1.7 | W8: =W9 -> 27.9 | X8: =Z8/AA8*100 -> 9.5419095 | Y8: =(U8+273.15)*287.05/101325 -> 0.84039854 | Z8: =(V8*101325)/(622+V8) -> 276.17845 | AA8: =288.68*(1.098+(U8)/100)^8.02 -> 2894.373 | BP8: Source | BQ8: Régime hivernale sans recyclage
B9: 6.Bureau 6 | C9: ='Ecart de soufflage'!N14 -> 0.15989155 | D9: =W$8-W$7 -> 31.744494 | E9: =C9*D9 -> 5.0756765 | F9: =W$11-W$9 -> 16.6 | G9: =C9*F9 -> 2.6541998 | H9: =V$9-V$8 -> 5.6 | I9: =C9*H9*3.6 -> 3.2234137 | J9: ='Ecart de soufflage'!O14 -> 0.17132208 | K9: =W$19-W$17 -> 3.1728382 | L9: =J9*K9 -> 0.54357726 | M9: =W$17-W$16 -> -31.472838 | N9: =J9*M9 -> -5.3919922 | O9: =V$16-V$17 -> 5.1 | P9: =J9*O9*3.6 -> 3.1454734 | T9: 2 | U9: =9.4 -> 9.4 | V9: =7.3 -> 7.3 | W9: =27.9 -> 27.9 | X9: 100 | Y9: =(U9+273.15)*287.05/101325 -> 0.80045376 | Z9: =(V9*101325)/(622+V9) -> 1175.3893 | AA9: =Z9 -> 1175.3893 | AC9: =Z11-Z7 -> 896.42916 | BR9: T [°C] | BS9: x [geau/kgas] | BT9: h [kJ/kgas] | BU9: HR [%] | BV9: v [m³/kgas] | BW9: pv [Pa] | BX9: ps [Pa]
B10: 7.Bureau 7 | C10: ='Ecart de soufflage'!N15 -> 0.15989155 | D10: =W$8-W$7 -> 31.744494 | E10: =C10*D10 -> 5.0756765 | F10: =W$11-W$9 -> 16.6 | G10: =C10*F10 -> 2.6541998 | H10: =V$9-V$8 -> 5.6 | I10: =C10*H10*3.6 -> 3.2234137 | J10: ='Ecart de soufflage'!O15 -> 0.17588208 | K10: =W$19-W$17 -> 3.1728382 | L10: =J10*K10 -> 0.5580454 | M10: =W$17-W$16 -> -31.472838 | N10: =J10*M10 -> -5.5355084 | O10: =V$16-V$17 -> 5.1 | P10: =J10*O10*3.6 -> 3.229195 | T10: i | U10: 20 | V10: =7.3 -> 7.3 | W10: =38.5 -> 38.5 | X10: 50 | Y10: =0.84 -> 0.84 | Z10: =X10/100*AA10 -> 1169.0948 | AA10: =288.68*(1.098+(U10)/100)^8.02 -> 2338.1896 | BQ10: e | BR10: -8 | BS10: =622*BW10/(101325-BW10) -> 1.7171699 | BT10: =1.009*(BR10)+BS10/1000*(2501.6+1.854*(BR10)) -> -3.8017968 | BU10: 90 | BV10: =(BR10+273.15)*287.05/101325 -> 0.7511602 | BW10: =(BU10/100)*BX10 -> 278.96016 | BX10: =4.689*(1.486+(BR10)/100)^12.3 -> 309.95574
B11: 8.SDR | C11: ='Ecart de soufflage'!N16 -> 0.29367836 | D11: =W$8-W$7 -> 31.744494 | E11: =C11*D11 -> 9.3226712 | F11: =W$11-W$9 -> 16.6 | G11: =C11*F11 -> 4.8750609 | H11: =V$9-V$8 -> 5.6 | I11: =C11*H11*3.6 -> 5.9205558 | J11: ='Ecart de soufflage'!O16 -> 0.38285079 | K11: =W$19-W$17 -> 3.1728382 | L11: =J11*K11 -> 1.2147236 | M11: =W$17-W$16 -> -31.472838 | N11: =J11*M11 -> -12.049401 | O11: =V$16-V$17 -> 5.1 | P11: =J11*O11*3.6 -> 7.0291405 | T11: s | U11: =25.7 -> 25.7 | V11: =7.3 -> 7.3 | W11: =44.5 -> 44.5 | X11: =35.6 -> 35.6 | Y11: =0.857 -> 0.857 | Z11: =(V11*101325)/(622+V11) -> 1175.3893 | AA11: =288.68*(1.098+(U11)/100)^8.02 -> 3300.4248 | BQ11: 1 | BR11: =(BT11-2501.6*BS11/1000)/(1.009+1.854*BS11/1000) -> 23.046947 | BS11: =BS10 -> 1.7171699 | BT11: =BT12 -> 27.623415 | BU11: =BW11/BX11*100 -> 9.9048026 | BV11: =(BR11+273.15)*287.05/101325 -> 0.83911506 | BW11: =(BS11*101325)/(622+BS11) -> 278.96016 | BX11: =288.68*(1.098+(BR11)/100)^8.02 -> 2816.4131
B12: 9.Couloir droite | C12: ='Ecart de soufflage'!N17 -> 0.40391799 | D12: =W$8-W$7 -> 31.744494 | E12: =C12*D12 -> 12.822172 | F12: =W$11-W$9 -> 16.6 | G12: =C12*F12 -> 6.7050386 | H12: =V$9-V$8 -> 5.6 | I12: =C12*H12*3.6 -> 8.1429867 | J12: ='Ecart de soufflage'!O17 -> 0.2208125 | K12: =W$19-W$17 -> 3.1728382 | L12: =J12*K12 -> 0.70060234 | M12: =W$17-W$16 -> -31.472838 | N12: =J12*M12 -> -6.9495961 | O12: =V$16-V$17 -> 5.1 | P12: =J12*O12*3.6 -> 4.0541175 | BQ12: 3 | BR12: =((BX12/288.68)^(1/8.02)-1.098)*100 -> 9.2528456 | BS12: =BS13 -> 7.2604503 | BT12: =1.009*(BR12)+BS12/1000*(2501.6+1.854*(BR12)) -> 27.623415 | BU12: 100 | BV12: =(BR12+273.15)*287.05/101325 -> 0.80003688 | BW12: =(BS12*101325)/(622+BS12) -> 1169.0948 | BX12: =BW12 -> 1169.0948
B13: 10.Approvisionnement | C13: ='Ecart de soufflage'!N18 -> 0.063850792 | D13: =W$8-W$7 -> 31.744494 | E13: =C13*D13 -> 2.0269111 | F13: =W$11-W$9 -> 16.6 | G13: =C13*F13 -> 1.0599231 | H13: =V$9-V$8 -> 5.6 | I13: =C13*H13*3.6 -> 1.287232 | J13: ='Ecart de soufflage'!O18 -> 0.0357405 | K13: =W$19-W$17 -> 3.1728382 | L13: =J13*K13 -> 0.11339882 | M13: =W$17-W$16 -> -31.472838 | N13: =J13*M13 -> -1.124855 | O13: =V$16-V$17 -> 5.1 | P13: =J13*O13*3.6 -> 0.65619558 | BQ13: i | BR13: 20 | BS13: =622*BW13/(101325-BW13) -> 7.2604503 | BT13: =1.009*(BR13)+BS13/1000*(2501.6+1.854*(BR13)) -> 38.61196 | BU13: 50 | BV13: =(BR13+273.15)*287.05/101325 -> 0.83048317 | BW13: =BU13/100*BX13 -> 1169.0948 | BX13: =288.68*(1.098+(BR13)/100)^8.02 -> 2338.1896
B14: 11/12/13. Entrée | C14: ='Ecart de soufflage'!N19 -> 0.16057504 | D14: =W$8-W$7 -> 31.744494 | E14: =C14*D14 -> 5.0973734 | F14: =W$11-W$9 -> 16.6 | G14: =C14*F14 -> 2.6655457 | H14: =V$9-V$8 -> 5.6 | I14: =C14*H14*3.6 -> 3.2371928 | J14: ='Ecart de soufflage'!O19 -> 0.086485625 | K14: =W$19-W$17 -> 3.1728382 | L14: =J14*K14 -> 0.2744049 | M14: =W$17-W$16 -> -31.472838 | N14: =J14*M14 -> -2.7219481 | O14: =V$16-V$17 -> 5.1 | P14: =J14*O14*3.6 -> 1.5878761 | T14: Régime éstival sans recyclage | BQ14: s | BR14: =BR13+'Ecart de soufflage'!$O$3 -> 25.669468 | BS14: =BS13 -> 7.2604503 | BT14: =1.009*(BR14)+BS14/1000*(2501.6+1.854*(BR14)) -> 44.408769 | BU14: =BW14/BX14*100 -> 35.486635 | BV14: =(BR14+273.15)*287.05/101325 -> 0.84654457 | BW14: =(BS14*101325)/(622+BS14) -> 1169.0948 | BX14: =288.68*(1.098+(BR14)/100)^8.02 -> 3294.4652
B15: 14.Distrib | C15: ='Ecart de soufflage'!N20 -> 0.1870546 | D15: =W$8-W$7 -> 31.744494 | E15: =C15*D15 -> 5.9379536 | F15: =W$11-W$9 -> 16.6 | G15: =C15*F15 -> 3.1051063 | H15: =V$9-V$8 -> 5.6 | I15: =C15*H15*3.6 -> 3.7710207 | J15: ='Ecart de soufflage'!O20 -> 0.37135758 | K15: =W$19-W$17 -> 3.1728382 | L15: =J15*K15 -> 1.1782575 | M15: =W$17-W$16 -> -31.472838 | N15: =J15*M15 -> -11.687677 | O15: =V$16-V$17 -> 5.1 | P15: =J15*O15*3.6 -> 6.8181252 | U15: T [°C] | V15: x [geau/kgas] | W15: h [kJ/kgas] | X15: HR [%] | Y15: v [m³/kgas] | Z15: pv [Pa] | AA15: ps [Pa]
B16: 15.Secretariat | C16: ='Ecart de soufflage'!N21 -> 0.26475149 | D16: =W$8-W$7 -> 31.744494 | E16: =C16*D16 -> 8.4044021 | F16: =W$11-W$9 -> 16.6 | G16: =C16*F16 -> 4.3948747 | H16: =V$9-V$8 -> 5.6 | I16: =C16*H16*3.6 -> 5.33739 | J16: ='Ecart de soufflage'!O21 -> 0.28831667 | K16: =W$19-W$17 -> 3.1728382 | L16: =J16*K16 -> 0.91478214 | M16: =W$17-W$16 -> -31.472838 | N16: =J16*M16 -> -9.0741438 | O16: =V$16-V$17 -> 5.1 | P16: =J16*O16*3.6 -> 5.293494 | T16: e | U16: 32 | V16: =15 -> 15 | W16: =70.5 -> 70.5 | X16: 50 | Y16: =0.89 -> 0.89 | Z16: =(X16/100)*AA16 -> 2375.9105 | AA16: =288.68*(1.098+(U16)/100)^8.02 -> 4751.821
B17: 16.SDR | C17: ='Ecart de soufflage'!N22 -> 0.46406473 | D17: =W$8-W$7 -> 31.744494 | E17: =C17*D17 -> 14.7315 | F17: =W$11-W$9 -> 16.6 | G17: =C17*F17 -> 7.7034745 | H17: =V$9-V$8 -> 5.6 | I17: =C17*H17*3.6 -> 9.355545 | J17: ='Ecart de soufflage'!O22 -> 0.65478972 | K17: =W$19-W$17 -> 3.1728382 | L17: =J17*K17 -> 2.0775419 | M17: =W$17-W$16 -> -31.472838 | N17: =J17*M17 -> -20.608091 | O17: =V$16-V$17 -> 5.1 | P17: =J17*O17*3.6 -> 12.021939 | T17: 3 | U17: =((AA17/288.68)^(1/8.02)-1.098)*100 -> 13.881596 | V17: =V18 -> 9.9 | W17: =1.009*(U17)+V17/1000*(2501.6+1.854*(U17)) -> 39.027162 | X17: 100 | Y17: =0.83 -> 0.83 | Z17: =(V17*101325)/(622+V17) -> 1587.4624 | AA17: =Z17 -> 1587.4624 | BQ17: Régime éstival sans recyclage | BZ17: Source | CA17: Régime éstival avec recyclage
B18: 17. Salle d'attente | C18: ='Ecart de soufflage'!N23 -> 0.48787649 | D18: =W$8-W$7 -> 31.744494 | E18: =C18*D18 -> 15.487393 | F18: =W$11-W$9 -> 16.6 | G18: =C18*F18 -> 8.0987497 | H18: =V$9-V$8 -> 5.6 | I18: =C18*H18*3.6 -> 9.83559 | J18: ='Ecart de soufflage'!O23 -> 0.38869335 | K18: =W$19-W$17 -> 3.1728382 | L18: =J18*K18 -> 1.2332611 | M18: =W$17-W$16 -> -31.472838 | N18: =J18*M18 -> -12.233283 | O18: =V$16-V$17 -> 5.1 | P18: =J18*O18*3.6 -> 7.1364099 | T18: i | U18: 25 | V18: =9.9 -> 9.9 | W18: =50.3 -> 50.3 | X18: 50 | Y18: =0.86 -> 0.86 | Z18: =X18/100*AA18 -> 1583.0682 | AA18: =288.68*(1.098+(U18)/100)^8.02 -> 3166.1365 | AC18: =Z19-Z16 -> -788.44806 | BR18: T [°C] | BS18: x [geau/kgas] | BT18: h [kJ/kgas] | BU18: HR [%] | BV18: v [m³/kgas] | BW18: pv [Pa] | BX18: ps [Pa] | CB18: T [°C] | CC18: x [geau/kgas] | CD18: h [kJ/kgas] | CE18: HR [%] | CF18: v [m³/kgas] | CG18: pv [Pa] | CH18: ps [Pa]
B19: 18.WC individuelle | C19: ='Ecart de soufflage'!N24 -> 0.041714675 | D19: =W$8-W$7 -> 31.744494 | E19: =C19*D19 -> 1.3242113 | F19: =W$11-W$9 -> 16.6 | G19: =C19*F19 -> 0.6924636 | H19: =V$9-V$8 -> 5.6 | I19: =C19*H19*3.6 -> 0.84096784 | J19: ='Ecart de soufflage'!O24 -> 0.037047361 | K19: =W$19-W$17 -> 3.1728382 | L19: =J19*K19 -> 0.11754528 | M19: =W$17-W$16 -> -31.472838 | N19: =J19*M19 -> -1.1659856 | O19: =V$16-V$17 -> 5.1 | P19: =J19*O19*3.6 -> 0.68018955 | T19: s | U19: =U18-'Ecart de soufflage'!$O$4 -> 17 | V19: =9.9 -> 9.9 | W19: =42.2 -> 42.2 | X19: =81.9 -> 81.9 | Y19: =0.835 -> 0.835 | Z19: =(V19*101325)/(622+V19) -> 1587.4624 | AA19: =288.68*(1.098+(U19)/100)^8.02 -> 1938.3541 | BQ19: e | BR19: 32 | BS19: =622*BW19/(101325-BW19) -> 14.935118 | BT19: =1.009*(BR19)+BS19/1000*(2501.6+1.854*(BR19)) -> 70.535762 | BU19: 50 | BV19: =(BR19+273.15)*287.05/101325 -> 0.86447873 | BW19: =(BU19/100)*BX19 -> 2375.9105 | BX19: =288.68*(1.098+(BR19)/100)^8.02 -> 4751.821 | CA19: e | CB19: 32 | CC19: =622*CG19/(101325-CG19) -> 14.935118 | CD19: =1.009*(CB19)+CC19/1000*(2501.6+1.854*(CB19)) -> 70.535762 | CE19: 50 | CF19: =(CB19+273.15)*287.05/101325 -> 0.86447873 | CG19: =(CE19/100)*CH19 -> 2375.9105 | CH19: =288.68*(1.098+(CB19)/100)^8.02 -> 4751.821
B20: 19.WC PMR | C20: ='Ecart de soufflage'!N25 -> 0.038539773 | D20: =W$8-W$7 -> 31.744494 | E20: =C20*D20 -> 1.2234256 | F20: =W$11-W$9 -> 16.6 | G20: =C20*F20 -> 0.63976024 | H20: =V$9-V$8 -> 5.6 | I20: =C20*H20*3.6 -> 0.77696183 | J20: ='Ecart de soufflage'!O25 -> 0.035337361 | K20: =W$19-W$17 -> 3.1728382 | L20: =J20*K20 -> 0.11211973 | M20: =W$17-W$16 -> -31.472838 | N20: =J20*M20 -> -1.112167 | O20: =V$16-V$17 -> 5.1 | P20: =J20*O20*3.6 -> 0.64879395 | BQ20: 3 | BR20: =((BX20/288.68)^(1/8.02)-1.098)*100 -> 13.838857 | BS20: =BS21 -> 9.8721614 | BT20: =1.009*(BR20)+BS20/1000*(2501.6+1.854*(BR20)) -> 38.912898 | BU20: 100 | BV20: =(BR20+273.15)*287.05/101325 -> 0.81302888 | BW20: =(BS20*101325)/(622+BS20) -> 1583.0682 | BX20: =BW20 -> 1583.0682 | CA20: m | CB20: =(CD20-2501.6*CC20/1000)/(1.009+1.854*CC20/1000) -> 29.87279 | CC20: ='Ecart de soufflage'!$S$3/100*CC22+(1-'Ecart de soufflage'!$S$3/100)*CC19 -> 13.386792 | CD20: ='Ecart de soufflage'!$S$3/100*CD22+(1-'Ecart de soufflage'!$S$3/100)*CD19 -> 64.37146 | CE20: =CG20/CH20*100 -> 50.715595 | CF20: =(CB20+273.15)*287.05/101325 -> 0.85845243 | CG20: =(CC20*101325)/(622+CC20) -> 2134.7889 | CH20: =288.68*(1.098+(CB20)/100)^8.02 -> 4209.3342
B21: 20.WC femme | C21: ='Ecart de soufflage'!N26 -> 0.15345356 | D21: =W$8-W$7 -> 31.744494 | E21: =C21*D21 -> 4.8713057 | F21: =W$11-W$9 -> 16.6 | G21: =C21*F21 -> 2.5473291 | H21: =V$9-V$8 -> 5.6 | I21: =C21*H21*3.6 -> 3.0936238 | J21: ='Ecart de soufflage'!O26 -> 0.15554931 | K21: =W$19-W$17 -> 3.1728382 | L21: =J21*K21 -> 0.49353278 | M21: =W$17-W$16 -> -31.472838 | N21: =J21*M21 -> -4.8955781 | O21: =V$16-V$17 -> 5.1 | P21: =J21*O21*3.6 -> 2.8558852 | BQ21: i | BR21: 25 | BS21: =622*BW21/(101325-BW21) -> 9.8721614 | BT21: =1.009*(BR21)+BS21/1000*(2501.6+1.854*(BR21)) -> 50.378774 | BU21: 50 | BV21: =(BR21+273.15)*287.05/101325 -> 0.84464799 | BW21: =BU21/100*BX21 -> 1583.0682 | BX21: =288.68*(1.098+(BR21)/100)^8.02 -> 3166.1365 | CA21: 1 | CB21: =((CH21/288.68)^(1/8.02)-1.098)*100 -> 13.838857 | CC21: =CC22 -> 9.8721614 | CD21: =1.009*(CB21)+CC21/1000*(2501.6+1.854*(CB21)) -> 38.912898 | CE21: 100 | CF21: =(CB21+273.15)*287.05/101325 -> 0.81302888 | CG21: =(CC21*101325)/(622+CC21) -> 1583.0682 | CH21: =CG21 -> 1583.0682
B22: 21.WC homme | C22: ='Ecart de soufflage'!N27 -> 0.10821122 | D22: =W$8-W$7 -> 31.744494 | E22: =C22*D22 -> 3.4351104 | F22: =W$11-W$9 -> 16.6 | G22: =C22*F22 -> 1.7963062 | H22: =V$9-V$8 -> 5.6 | I22: =C22*H22*3.6 -> 2.1815381 | J22: ='Ecart de soufflage'!O27 -> 0.13118181 | K22: =W$19-W$17 -> 3.1728382 | L22: =J22*K22 -> 0.41621865 | M22: =W$17-W$16 -> -31.472838 | N22: =J22*M22 -> -4.1286637 | O22: =V$16-V$17 -> 5.1 | P22: =J22*O22*3.6 -> 2.4084979 | BQ22: s | BR22: =BR21-'Ecart de soufflage'!$O$4 -> 17 | BS22: =BS21 -> 9.8721614 | BT22: =1.009*(BR22)+BS22/1000*(2501.6+1.854*(BR22)) -> 42.16035 | BU22: =BW22/BX22*100 -> 81.670747 | BV22: =(BR22+273.15)*287.05/101325 -> 0.82198428 | BW22: =(BS22*101325)/(622+BS22) -> 1583.0682 | BX22: =288.68*(1.098+(BR22)/100)^8.02 -> 1938.3541 | CA22: i | CB22: 25 | CC22: =622*CG22/(101325-CG22) -> 9.8721614 | CD22: =1.009*(CB22)+CC22/1000*(2501.6+1.854*(CB22)) -> 50.378774 | CE22: 50 | CF22: =(CB22+273.15)*287.05/101325 -> 0.84464799 | CG22: =CE22/100*CH22 -> 1583.0682 | CH22: =288.68*(1.098+(CB22)/100)^8.02 -> 3166.1365
B23: 22.Trappe | C23: ='Ecart de soufflage'!N28 -> 0.096040762 | D23: =W$8-W$7 -> 31.744494 | E23: =C23*D23 -> 3.0487654 | F23: =W$11-W$9 -> 16.6 | G23: =C23*F23 -> 1.5942767 | H23: =V$9-V$8 -> 5.6 | I23: =C23*H23*3.6 -> 1.9361818 | J23: ='Ecart de soufflage'!O28 -> 0.0408375 | K23: =W$19-W$17 -> 3.1728382 | L23: =J23*K23 -> 0.12957078 | M23: =W$17-W$16 -> -31.472838 | N23: =J23*M23 -> -1.285272 | O23: =V$16-V$17 -> 5.1 | P23: =J23*O23*3.6 -> 0.7497765 | CA23: s | CB23: =CB22-'Ecart de soufflage'!$O$4 -> 17 | CC23: =CC22 -> 9.8721614 | CD23: =1.009*(CB23)+CC23/1000*(2501.6+1.854*(CB23)) -> 42.16035 | CE23: =CG23/CH23*100 -> 81.670747 | CF23: =(CB23+273.15)*287.05/101325 -> 0.82198428 | CG23: =(CC23*101325)/(622+CC23) -> 1583.0682 | CH23: =288.68*(1.098+(CB23)/100)^8.02 -> 1938.3541
B24: 23.Trémis | C24: ='Ecart de soufflage'!N29 -> 0.030990564 | D24: =W$8-W$7 -> 31.744494 | E24: =C24*D24 -> 0.98377978 | F24: =W$11-W$9 -> 16.6 | G24: =C24*F24 -> 0.51444336 | H24: =V$9-V$8 -> 5.6 | I24: =C24*H24*3.6 -> 0.62476977 | J24: ='Ecart de soufflage'!O29 -> 0.0131775 | K24: =W$19-W$17 -> 3.1728382 | L24: =J24*K24 -> 0.041810076 | M24: =W$17-W$16 -> -31.472838 | N24: =J24*M24 -> -0.41473333 | O24: =V$16-V$17 -> 5.1 | P24: =J24*O24*3.6 -> 0.2419389
C25: =SUM(C4:C24) -> 4.0945628 | E25: =SUM(E4:E24) -> 129.97983 | G25: =SUM(G4:G24) -> 67.969743 | I25: =SUM(I4:I24) -> 82.546387 | J25: =SUM(J4:J24) -> 4.1379928 | L25: =SUM(L4:L24) -> 13.129182 | N25: =SUM(N4:N24) -> -130.23438 | P25: =SUM(P4:P24) -> 75.973547
B26: M³/H | C26: =C25*Y7*3600 -> 11072.422 | J26: =J25*Y16*3600 -> 13258.129
C27: =C26/3600 -> 3.0756726 | J27: =J26/3600 -> 3.6828136
C29: Résumé | L29: =4.09*3600 -> 14724
C30: Ppré [kW] | D30: =E25 -> 129.97983 | H30: T1bat chaude | I30: 70 | J30: =J9*Y$16*3600 -> 548.91596
C31: Ppost [kW] | D31: =MAX(G25,L25) -> 67.969743 | H31: T2 bat chaud | I31: 50 | J31: =J10*Y$16*3600 -> 563.5262
C32: qm,eau hiver [kgeau/h] | D32: =I25 -> 82.546387 | H32: T1batfr | I32: 7 | J32: =J11*Y$16*3600 -> 1226.6539
C33: Pfr [kW] | D33: =N25 -> -130.23438 | H33: T2batfr | I33: 12 | J33: =J12*Y$16*3600 -> 707.48325
C34: qm,eau été [kgeau/h] | D34: =P25 -> 75.973547 | J34: =J13*Y$16*3600 -> 114.51256
C35: qm bat pré [kg/h] | D35: =E25*1000/4186/(I30-I31)*3600 -> 5589.1947 | F35: =(E25*1000)/(4186*20) -> 1.5525541 | J35: =J14*Y$16*3600 -> 277.09994
C36: qm bat post [kg/h] | D36: =G25*1000*3600/4186/(I30-I31) -> 2922.7314 | J36: =J15*Y$16*3600 -> 1189.8297
C37: qm bat fr [kg/h] | D37: =ABS(E25*1000*3600/4186/(I32-I33)) -> 22356.779 | J37: =J16*Y$16*3600 -> 923.7666
J38: =J17*Y$16*3600 -> 2097.9463
J39: =J18*Y$16*3600 -> 1245.3735 | O39: ²
Z55: ÉTÉ
G59: HIVER
Q81: #VALUE!

Sheet Climatisation avec recyclage
C3: Régime estival
B4: Local | C4: qm été [kgas/s] | D4: ∆hs1 [kJ/kg] | E4: Ppost [kW] = qm été . ∆hs1 | F4: ∆hm1 [kJ/kg] | G4: Pfr [kW] = qm été . ∆hm1 | H4: ∆xm1 [geau/kgas] | I4: qm,eau [kgeau/h] | K4: interpolation T pour m | M4: ; | N4: =+'Ecart de soufflage'!S3 -> 30.581462
B5: 1.COFFRE FORT | C5: ='Ecart de soufflage'!O9 -> 0.16943063 | D5: =O$15-O$13 -> 2.1904592 | E5: =C5*D5 -> 0.37113088 | F5: =O$13-O$12 -> -24.272838 | G5: =C5*F5 -> -4.1125622 | H5: =N$12-N$13 -> 3.5403455 | I5: =C5*H5*3.6 -> 2.1594346 | K5: interpolation x pour m | M5: =N11+(N14-N11)*'Ecart de soufflage'!S3/100 -> 13.440345
B6: 2.KITCHENETTE | C6: ='Ecart de soufflage'!O10 -> 0.26734275 | D6: =O$15-O$13 -> 2.1904592 | E6: =C6*D6 -> 0.5856034 | F6: =O$13-O$12 -> -24.272838 | G6: =C6*F6 -> -6.4891674 | H6: =N$12-N$13 -> 3.5403455 | I6: =C6*H6*3.6 -> 3.4073485
B7: 3.ESCALIER | C7: ='Ecart de soufflage'!O11 -> 0.0610535 | D7: =O$15-O$13 -> 2.1904592 | E7: =C7*D7 -> 0.1337352 | F7: =O$13-O$12 -> -24.272838 | G7: =C7*F7 -> -1.4819417 | H7: =N$12-N$13 -> 3.5403455 | I7: =C7*H7*3.6 -> 0.77814173 | K7: nouveaux poi,nt exterieur est le point m plus e
B8: 4.Bureau 4 | C8: ='Ecart de soufflage'!O12 -> 0.27987666 | D8: =O$15-O$13 -> 2.1904592 | E8: =C8*D8 -> 0.61305842 | F8: =O$13-O$12 -> -24.272838 | G8: =C8*F8 -> -6.7934009 | H8: =N$12-N$13 -> 3.5403455 | I8: =C8*H8*3.6 -> 3.5670962
B9: 5.Bureau5 | C9: ='Ecart de soufflage'!O13 -> 0.1709075 | D9: =O$15-O$13 -> 2.1904592 | E9: =C9*D9 -> 0.37436591 | F9: =O$13-O$12 -> -24.272838 | G9: =C9*F9 -> -4.1484101 | H9: =N$12-N$13 -> 3.5403455 | I9: =C9*H9*3.6 -> 2.1782577 | K9: Source | L9: Régime éstival avec recyclage
B10: 6.Bureau 6 | C10: ='Ecart de soufflage'!O14 -> 0.17132208 | D10: =O$15-O$13 -> 2.1904592 | E10: =C10*D10 -> 0.37527404 | F10: =O$13-O$12 -> -24.272838 | G10: =C10*F10 -> -4.1584732 | H10: =N$12-N$13 -> 3.5403455 | I10: =C10*H10*3.6 -> 2.1835417 | M10: T [°C] | N10: x [geau/kgas] | O10: h [kJ/kgas] | P10: HR [%] | Q10: v [m³/kgas] | R10: pv [Pa] | S10: ps [Pa]
B11: 7.Bureau 7 | C11: ='Ecart de soufflage'!O15 -> 0.17588208 | D11: =O$15-O$13 -> 2.1904592 | E11: =C11*D11 -> 0.38526253 | F11: =O$13-O$12 -> -24.272838 | G11: =C11*F11 -> -4.2691574 | H11: =N$12-N$13 -> 3.5403455 | I11: =C11*H11*3.6 -> 2.24166 | L11: e | M11: 32 | N11: =15 -> 15 | O11: =70.5 -> 70.5 | P11: 50 | Q11: =0.89 -> 0.89 | R11: =(P11/100)*S11 -> 2375.9105 | S11: =288.68*(1.098+(M11)/100)^8.02 -> 4751.821
B12: 8.SDR | C12: ='Ecart de soufflage'!O16 -> 0.38285079 | D12: =O$15-O$13 -> 2.1904592 | E12: =C12*D12 -> 0.83861905 | F12: =O$13-O$12 -> -24.272838 | G12: =C12*F12 -> -9.2928753 | H12: =N$12-N$13 -> 3.5403455 | I12: =C12*H12*3.6 -> 4.8795266 | L12: m | M12: =M4 -> ; | N12: =M5 -> 13.440345 | O12: =63.3 -> 63.3 | P12: 53.6 | Q12: =0.874 -> 0.874 | R12: =(N12*101325)/(622+N12) -> 2143.1485 | S12: =288.68*(1.098+(M12)/100)^8.02 -> #VALUE!
B13: 9.Couloir droite | C13: ='Ecart de soufflage'!O17 -> 0.2208125 | D13: =O$15-O$13 -> 2.1904592 | E13: =C13*D13 -> 0.48368078 | F13: =O$13-O$12 -> -24.272838 | G13: =C13*F13 -> -5.3597461 | H13: =N$12-N$13 -> 3.5403455 | I13: =C13*H13*3.6 -> 2.8143091 | L13: 1 | M13: =((S13/288.68)^(1/8.02)-1.098)*100 -> 13.881596 | N13: =N14 -> 9.9 | O13: =1.009*(M13)+N13/1000*(2501.6+1.854*(M13)) -> 39.027162 | P13: 100 | Q13: =0.83 -> 0.83 | R13: =(N13*101325)/(622+N13) -> 1587.4624 | S13: =R13 -> 1587.4624
B14: 10.Approvisionnement | C14: ='Ecart de soufflage'!O18 -> 0.0357405 | D14: =O$15-O$13 -> 2.1904592 | E14: =C14*D14 -> 0.078288108 | F14: =O$13-O$12 -> -24.272838 | G14: =C14*F14 -> -0.86752337 | H14: =N$12-N$13 -> 3.5403455 | I14: =C14*H14*3.6 -> 0.45552138 | L14: i | M14: 25 | N14: =9.9 -> 9.9 | O14: =50 -> 50 | P14: 50 | Q14: =0.86 -> 0.86 | R14: =P14/100*S14 -> 1583.0682 | S14: =288.68*(1.098+(M14)/100)^8.02 -> 3166.1365
B15: 11/12/13. Entrée | C15: ='Ecart de soufflage'!O19 -> 0.086485625 | D15: =O$15-O$13 -> 2.1904592 | E15: =C15*D15 -> 0.18944324 | F15: =O$13-O$12 -> -24.272838 | G15: =C15*F15 -> -2.0992516 | H15: =N$12-N$13 -> 3.5403455 | I15: =C15*H15*3.6 -> 1.1022804 | L15: s | M15: =M14-'Ecart de soufflage'!$O$4 -> 17 | N15: =9.5 -> 9.5 | O15: =1.009*(M15)+N15/1000*(2501.6+1.854*(M15)) -> 41.217621 | P15: =R15/S15*100 -> 78.638234 | Q15: =0.84 -> 0.84 | R15: =(N15*101325)/(622+N15) -> 1524.2874 | S15: =288.68*(1.098+(M15)/100)^8.02 -> 1938.3541
B16: 14.Distrib | C16: ='Ecart de soufflage'!O20 -> 0.37135758 | D16: =O$15-O$13 -> 2.1904592 | E16: =C16*D16 -> 0.81344365 | F16: =O$13-O$12 -> -24.272838 | G16: =C16*F16 -> -9.0139025 | H16: =N$12-N$13 -> 3.5403455 | I16: =C16*H16*3.6 -> 4.7330429
B17: 15.Secretariat | C17: ='Ecart de soufflage'!O21 -> 0.28831667 | D17: =O$15-O$13 -> 2.1904592 | E17: =C17*D17 -> 0.63154591 | F17: =O$13-O$12 -> -24.272838 | G17: =C17*F17 -> -6.9982638 | H17: =N$12-N$13 -> 3.5403455 | I17: =C17*H17*3.6 -> 3.6746662
B18: 16.SDR | C18: ='Ecart de soufflage'!O22 -> 0.65478972 | D18: =O$15-O$13 -> 2.1904592 | E18: =C18*D18 -> 1.4342902 | F18: =O$13-O$12 -> -24.272838 | G18: =C18*F18 -> -15.893605 | H18: =N$12-N$13 -> 3.5403455 | I18: =C18*H18*3.6 -> 8.3454545
B19: 17. Salle d'attente | C19: ='Ecart de soufflage'!O23 -> 0.38869335 | D19: =O$15-O$13 -> 2.1904592 | E19: =C19*D19 -> 0.85141694 | F19: =O$13-O$12 -> -24.272838 | G19: =C19*F19 -> -9.4346908 | H19: =N$12-N$13 -> 3.5403455 | I19: =C19*H19*3.6 -> 4.9539915
B20: 18.WC individuelle | C20: ='Ecart de soufflage'!O24 -> 0.037047361 | D20: =O$15-O$13 -> 2.1904592 | E20: =C20*D20 -> 0.081150734 | F20: =O$13-O$12 -> -24.272838 | G20: =C20*F20 -> -0.8992446 | H20: =N$12-N$13 -> 3.5403455 | I20: =C20*H20*3.6 -> 0.47217764
B21: 19.WC PMR | C21: ='Ecart de soufflage'!O25 -> 0.035337361 | D21: =O$15-O$13 -> 2.1904592 | E21: =C21*D21 -> 0.077405049 | F21: =O$13-O$12 -> -24.272838 | G21: =C21*F21 -> -0.85773805 | H21: =N$12-N$13 -> 3.5403455 | I21: =C21*H21*3.6 -> 0.45038328
B22: 20.WC femme | C22: ='Ecart de soufflage'!O26 -> 0.15554931 | D22: =O$15-O$13 -> 2.1904592 | E22: =C22*D22 -> 0.34072441 | F22: =O$13-O$12 -> -24.272838 | G22: =C22*F22 -> -3.7756231 | H22: =N$12-N$13 -> 3.5403455 | I22: =C22*H22*3.6 -> 1.9825138
B23: 21.WC homme | C23: ='Ecart de soufflage'!O27 -> 0.13118181 | D23: =O$15-O$13 -> 2.1904592 | E23: =C23*D23 -> 0.2873484 | F23: =O$13-O$12 -> -24.272838 | G23: =C23*F23 -> -3.1841547 | H23: =N$12-N$13 -> 3.5403455 | I23: =C23*H23*3.6 -> 1.6719441
B24: 22.Trappe | C24: ='Ecart de soufflage'!O28 -> 0.0408375 | D24: =O$15-O$13 -> 2.1904592 | E24: =C24*D24 -> 0.089452879 | F24: =O$13-O$12 -> -24.272838 | G24: =C24*F24 -> -0.99124203 | H24: =N$12-N$13 -> 3.5403455 | I24: =C24*H24*3.6 -> 0.52048389
B25: 23.Trémis | C25: ='Ecart de soufflage'!O29 -> 0.0131775 | D25: =O$15-O$13 -> 2.1904592 | E25: =C25*D25 -> 0.028864777 | F25: =O$13-O$12 -> -24.272838 | G25: =C25*F25 -> -0.31985533 | H25: =N$12-N$13 -> 3.5403455 | I25: =C25*H25*3.6 -> 0.16795045
C26: =SUM(C5:C25) -> 4.1379928 | E26: =SUM(E5:E25) -> 9.0641045 | G26: =SUM(G5:G25) -> -100.44083 | I26: =SUM(I5:I25) -> 52.739726
C27: =C26*Q12*3600 -> 13019.78
B29: débit recyclé | C29: ='Ecart de soufflage'!S3/100*C26 -> 1.2654587
C30: =C26-C29 -> 2.8725341 | G30: T1bat chaude | H30: 70
G31: T2 bat chaud | H31: 50
B32: Résumé | G32: T1batfr | H32: 7
B33: Ppost [kW] | C33: =MAX('Climatisation avec recyclage'!E26,'Climatisation sans recyclage'!G25) -> 67.969743 | G33: T2batfr | H33: 12
B34: Pfr [kW] | C34: =G26 -> -100.44083
B35: qm,eau été [kgeau/h] | C35: =I26 -> 52.739726
B36: qm bat post [kg/h] | C36: =C33*3600*1000/4186/(H30-H31) -> 2922.7314
B37: qm bat fr [kg/h] | C37: =G26*3600*1000/4186/(H32-H33) -> 17276.015
B159: Largeur x hauteur x longueur | C159: 128x096x920
B160: Filtre | C160: G3 et F8
C162: correction ->
D163: G4 et F7

Sheet Clim récupérateur à roue
C2: Régime hivernal | K2: Régime estival
B3: Local | C3: qm hiver [kgas/s] | D3: qm min [kgas/s] | E3: ∆h01 [kJ/kg] | F3: Ppré [kW] = qm hiver . ∆he1 | G3: ∆hs3 [kJ/kg] | H3: Ppost [kW] =qm hiver . ∆hs3 | I3: ∆x13 | J3: qm,eau [kgeau/h] | K3: qm été [kgas/s] | L3: qm min [kgas/s] | M3: ∆hs3 [kJ/kg] | N3: Ppost [kW] =qm été . ∆hs3 | O3: ∆h03 [kJ/kg] | P3: Pfr [kW] = qm hiver . ∆he3 | Q3: ∆xe3 [geau/kgas] | R3: qm,eau [kgeau/h]
B4: 1.COFFRE FORT | C4: ='Ecart de soufflage'!N9 -> 0.26775 | D4: ='Ecart de soufflage'!H9 -> 0.017848644 | E4: =W$14-W$13 -> 0.2 | F4: =C4*E4 -> 0.053550001 | G4: =W$17-W$15 -> 16.6 | H4: =C4*G4 -> 4.4446501 | I4: =V$15-V$14 -> 1.9 | J4: =C4*I4*3.6 -> 1.83141 | K4: ='Ecart de soufflage'!O9 -> 0.16943063 | L4: ='Ecart de soufflage'!I9 -> 0.017482517 | M4: =W$26-W$24 -> 3.1728382 | N4: =K4*M4 -> 0.53757597 | O4: =W$24-W$23 -> -11.272838 | P4: =K4*O4 -> -1.909964 | Q4: =V$24-V$22 -> -5.1 | R4: =K4*Q4*3.6 -> -3.1107463
B5: 2.KITCHENETTE | C5: ='Ecart de soufflage'!N10 -> 0.20151804 | D5: ='Ecart de soufflage'!H10 -> 0.17848644 | E5: =W$14-W$13 -> 0.2 | F5: =C5*E5 -> 0.040303607 | G5: =W$17-W$15 -> 16.6 | H5: =C5*G5 -> 3.3451994 | I5: =V$15-V$14 -> 1.9 | J5: =C5*I5*3.6 -> 1.3783834 | K5: ='Ecart de soufflage'!O10 -> 0.26734275 | L5: ='Ecart de soufflage'!I10 -> 0.17482517 | M5: =W$26-W$24 -> 3.1728382 | N5: =K5*M5 -> 0.84823531 | O5: =W$24-W$23 -> -11.272838 | P5: =K5*O5 -> -3.0137116 | Q5: =V$24-V$22 -> -5.1 | R5: =K5*Q5*3.6 -> -4.9084129
B6: 3.ESCALIER | C6: ='Ecart de soufflage'!N11 -> 0.1094459 | D6: ='Ecart de soufflage'!H11 -> 0.017848644 | E6: =W$14-W$13 -> 0.2 | F6: =C6*E6 -> 0.02188918 | G6: =W$17-W$15 -> 16.6 | H6: =C6*G6 -> 1.816802 | I6: =V$15-V$14 -> 1.9 | J6: =C6*I6*3.6 -> 0.74860996 | K6: ='Ecart de soufflage'!O11 -> 0.0610535 | L6: ='Ecart de soufflage'!I11 -> 0.017482517 | M6: =W$26-W$24 -> 3.1728382 | N6: =K6*M6 -> 0.19371288 | O6: =W$24-W$23 -> -11.272838 | P6: =K6*O6 -> -0.68824623 | Q6: =V$24-V$22 -> -5.1 | R6: =K6*Q6*3.6 -> -1.1209423 | W6: [%]
B7: 4.Bureau 4 | C7: ='Ecart de soufflage'!N12 -> 0.24242919 | D7: ='Ecart de soufflage'!H12 -> 0.053545931 | E7: =W$14-W$13 -> 0.2 | F7: =C7*E7 -> 0.048485837 | G7: =W$17-W$15 -> 16.6 | H7: =C7*G7 -> 4.0243245 | I7: =V$15-V$14 -> 1.9 | J7: =C7*I7*3.6 -> 1.6582156 | K7: ='Ecart de soufflage'!O12 -> 0.27987666 | L7: ='Ecart de soufflage'!I12 -> 0.052447552 | M7: =W$26-W$24 -> 3.1728382 | N7: =K7*M7 -> 0.88800337 | O7: =W$24-W$23 -> -11.272838 | P7: =K7*O7 -> -3.1550043 | Q7: =V$24-V$22 -> -5.1 | R7: =K7*Q7*3.6 -> -5.1385355 | V7: η (Data sheet) | W7: 72.7
B8: 5.Bureau5 | C8: ='Ecart de soufflage'!N13 -> 0.15891655 | D8: ='Ecart de soufflage'!H13 -> 0.053545931 | E8: =W$14-W$13 -> 0.2 | F8: =C8*E8 -> 0.031783309 | G8: =W$17-W$15 -> 16.6 | H8: =C8*G8 -> 2.6380147 | I8: =V$15-V$14 -> 1.9 | J8: =C8*I8*3.6 -> 1.0869892 | K8: ='Ecart de soufflage'!O13 -> 0.1709075 | L8: ='Ecart de soufflage'!I13 -> 0.052447552 | M8: =W$26-W$24 -> 3.1728382 | N8: =K8*M8 -> 0.54226185 | O8: =W$24-W$23 -> -11.272838 | P8: =K8*O8 -> -1.9266126 | Q8: =V$24-V$22 -> -5.1 | R8: =K8*Q8*3.6 -> -3.1378617
B9: 6.Bureau 6 | C9: ='Ecart de soufflage'!N14 -> 0.15989155 | D9: ='Ecart de soufflage'!H14 -> 0.053545931 | E9: =W$14-W$13 -> 0.2 | F9: =C9*E9 -> 0.031978311 | G9: =W$17-W$15 -> 16.6 | H9: =C9*G9 -> 2.6541998 | I9: =V$15-V$14 -> 1.9 | J9: =C9*I9*3.6 -> 1.0936582 | K9: ='Ecart de soufflage'!O14 -> 0.17132208 | L9: ='Ecart de soufflage'!I14 -> 0.052447552 | M9: =W$26-W$24 -> 3.1728382 | N9: =K9*M9 -> 0.54357726 | O9: =W$24-W$23 -> -11.272838 | P9: =K9*O9 -> -1.9312861 | Q9: =V$24-V$22 -> -5.1 | R9: =K9*Q9*3.6 -> -3.1454734 | T9: Source
B10: 7.Bureau 7 | C10: ='Ecart de soufflage'!N15 -> 0.15989155 | D10: ='Ecart de soufflage'!H15 -> 0.053545931 | E10: =W$14-W$13 -> 0.2 | F10: =C10*E10 -> 0.031978311 | G10: =W$17-W$15 -> 16.6 | H10: =C10*G10 -> 2.6541998 | I10: =V$15-V$14 -> 1.9 | J10: =C10*I10*3.6 -> 1.0936582 | K10: ='Ecart de soufflage'!O15 -> 0.17588208 | L10: ='Ecart de soufflage'!I15 -> 0.052447552 | M10: =W$26-W$24 -> 3.1728382 | N10: =K10*M10 -> 0.5580454 | O10: =W$24-W$23 -> -11.272838 | P10: =K10*O10 -> -1.9826903 | Q10: =V$24-V$22 -> -5.1 | R10: =K10*Q10*3.6 -> -3.229195 | T10: Régime hivernale à roue
B11: 8.SDR | C11: ='Ecart de soufflage'!N16 -> 0.29367836 | D11: ='Ecart de soufflage'!H16 -> 0.24988101 | E11: =W$14-W$13 -> 0.2 | F11: =C11*E11 -> 0.058735673 | G11: =W$17-W$15 -> 16.6 | H11: =C11*G11 -> 4.8750609 | I11: =V$15-V$14 -> 1.9 | J11: =C11*I11*3.6 -> 2.00876 | K11: ='Ecart de soufflage'!O16 -> 0.38285079 | L11: ='Ecart de soufflage'!I16 -> 0.24475524 | M11: =W$26-W$24 -> 3.1728382 | N11: =K11*M11 -> 1.2147236 | O11: =W$24-W$23 -> -11.272838 | P11: =K11*O11 -> -4.315815 | Q11: =V$24-V$22 -> -5.1 | R11: =K11*Q11*3.6 -> -7.0291405 | U11: T [°C] | V11: x [geau/kgas] | W11: h [kJ/kgas] | X11: HR [%] | Y11: v [m³/kgas] | Z11: pv [Pa] | AA11: ps [Pa]
B12: 9.Couloir droite | C12: ='Ecart de soufflage'!N17 -> 0.40391799 | D12: ='Ecart de soufflage'!H17 -> 0.017848644 | E12: =W$14-W$13 -> 0.2 | F12: =C12*E12 -> 0.080783598 | G12: =W$17-W$15 -> 16.6 | H12: =C12*G12 -> 6.7050386 | I12: =V$15-V$14 -> 1.9 | J12: =C12*I12*3.6 -> 2.7627991 | K12: ='Ecart de soufflage'!O17 -> 0.2208125 | L12: ='Ecart de soufflage'!I17 -> 0.017482517 | M12: =W$26-W$24 -> 3.1728382 | N12: =K12*M12 -> 0.70060234 | O12: =W$24-W$23 -> -11.272838 | P12: =K12*O12 -> -2.4891836 | Q12: =V$24-V$22 -> -5.1 | R12: =K12*Q12*3.6 -> -4.0541175 | T12: e | U12: -8 | V12: =622*Z12/(101325-Z12) -> 1.7171699 | W12: =1.009*(U12)+V12/1000*(2501.6+1.854*(U12)) -> -3.8017968 | X12: 90 | Y12: =(U12+273.15)*287.05/101325 -> 0.7511602 | Z12: =(X12/100)*AA12 -> 278.96016 | AA12: =4.689*(1.486+(U12)/100)^12.3 -> 309.95574
B13: 10.Approvisionnement | C13: ='Ecart de soufflage'!N18 -> 0.063850792 | D13: ='Ecart de soufflage'!H18 -> 0.017848644 | E13: =W$14-W$13 -> 0.2 | F13: =C13*E13 -> 0.012770158 | G13: =W$17-W$15 -> 16.6 | H13: =C13*G13 -> 1.0599231 | I13: =V$15-V$14 -> 1.9 | J13: =C13*I13*3.6 -> 0.43673941 | K13: ='Ecart de soufflage'!O18 -> 0.0357405 | L13: ='Ecart de soufflage'!I18 -> 0.017482517 | M13: =W$26-W$24 -> 3.1728382 | N13: =K13*M13 -> 0.11339882 | O13: =W$24-W$23 -> -11.272838 | P13: =K13*O13 -> -0.40289687 | Q13: =V$24-V$22 -> -5.1 | R13: =K13*Q13*3.6 -> -0.65619558 | T13: 0 | U13: 14 | V13: 5.4 | W13: 27.7 | X13: 54.6 | Y13: =(U13+273.15)*287.05/101325 -> 0.81348539 | Z13: =(X13/100)*AA13 -> 873.43162 | AA13: =288.68*(1.098+(U13)/100)^8.02 -> 1599.6916
B14: 11/12/13. Entrée | C14: ='Ecart de soufflage'!N19 -> 0.16057504 | D14: ='Ecart de soufflage'!H19 -> 0.017848644 | E14: =W$14-W$13 -> 0.2 | F14: =C14*E14 -> 0.032115008 | G14: =W$17-W$15 -> 16.6 | H14: =C14*G14 -> 2.6655457 | I14: =V$15-V$14 -> 1.9 | J14: =C14*I14*3.6 -> 1.0983333 | K14: ='Ecart de soufflage'!O19 -> 0.086485625 | L14: ='Ecart de soufflage'!I19 -> 0.017482517 | M14: =W$26-W$24 -> 3.1728382 | N14: =K14*M14 -> 0.2744049 | O14: =W$24-W$23 -> -11.272838 | P14: =K14*O14 -> -0.97493846 | Q14: =V$24-V$22 -> -5.1 | R14: =K14*Q14*3.6 -> -1.5878761 | T14: 1 | U14: =14.2 -> 14.2 | V14: =V13 -> 5.4 | W14: =W15 -> 27.9 | X14: 54 | Y14: =(U14+273.15)*287.05/101325 -> 0.81405199 | Z14: =(V14*101325)/(622+V14) -> 872.09914 | AA14: =288.68*(1.098+(U14)/100)^8.02 -> 1620.5357
B15: 14.Distrib | C15: ='Ecart de soufflage'!N20 -> 0.1870546 | D15: ='Ecart de soufflage'!H20 -> 0.053545931 | E15: =W$14-W$13 -> 0.2 | F15: =C15*E15 -> 0.03741092 | G15: =W$17-W$15 -> 16.6 | H15: =C15*G15 -> 3.1051063 | I15: =V$15-V$14 -> 1.9 | J15: =C15*I15*3.6 -> 1.2794535 | K15: ='Ecart de soufflage'!O20 -> 0.37135758 | L15: ='Ecart de soufflage'!I20 -> 0.052447552 | M15: =W$26-W$24 -> 3.1728382 | N15: =K15*M15 -> 1.1782575 | O15: =W$24-W$23 -> -11.272838 | P15: =K15*O15 -> -4.186254 | Q15: =V$24-V$22 -> -5.1 | R15: =K15*Q15*3.6 -> -6.8181252 | T15: 2 | U15: =9.4 -> 9.4 | V15: =7.3 -> 7.3 | W15: =27.9 -> 27.9 | X15: 100 | Y15: =(U15+273.15)*287.05/101325 -> 0.80045376 | Z15: =(V15*101325)/(622+V15) -> 1175.3893 | AA15: =Z15 -> 1175.3893
B16: 15.Secretariat | C16: ='Ecart de soufflage'!N21 -> 0.26475149 | D16: ='Ecart de soufflage'!H21 -> 0.10709186 | E16: =W$14-W$13 -> 0.2 | F16: =C16*E16 -> 0.052950297 | G16: =W$17-W$15 -> 16.6 | H16: =C16*G16 -> 4.3948747 | I16: =V$15-V$14 -> 1.9 | J16: =C16*I16*3.6 -> 1.8109002 | K16: ='Ecart de soufflage'!O21 -> 0.28831667 | L16: ='Ecart de soufflage'!I21 -> 0.1048951 | M16: =W$26-W$24 -> 3.1728382 | N16: =K16*M16 -> 0.91478214 | O16: =W$24-W$23 -> -11.272838 | P16: =K16*O16 -> -3.2501471 | Q16: =V$24-V$22 -> -5.1 | R16: =K16*Q16*3.6 -> -5.293494 | T16: i | U16: 20 | V16: =7.3 -> 7.3 | W16: =38.5 -> 38.5 | X16: 50 | Y16: =0.84 -> 0.84 | Z16: =X16/100*AA16 -> 1169.0948 | AA16: =288.68*(1.098+(U16)/100)^8.02 -> 2338.1896
B17: 16.SDR | C17: ='Ecart de soufflage'!N22 -> 0.46406473 | D17: ='Ecart de soufflage'!H22 -> 0.46406473 | E17: =W$14-W$13 -> 0.2 | F17: =C17*E17 -> 0.092812946 | G17: =W$17-W$15 -> 16.6 | H17: =C17*G17 -> 7.7034745 | I17: =V$15-V$14 -> 1.9 | J17: =C17*I17*3.6 -> 3.1742028 | K17: ='Ecart de soufflage'!O22 -> 0.65478972 | L17: ='Ecart de soufflage'!I22 -> 0.45454545 | M17: =W$26-W$24 -> 3.1728382 | N17: =K17*M17 -> 2.0775419 | O17: =W$24-W$23 -> -11.272838 | P17: =K17*O17 -> -7.3813386 | Q17: =V$24-V$22 -> -5.1 | R17: =K17*Q17*3.6 -> -12.021939 | T17: s | U17: =25.7 -> 25.7 | V17: =7.3 -> 7.3 | W17: =44.5 -> 44.5 | X17: =35.6 -> 35.6 | Y17: =0.857 -> 0.857 | Z17: =(V17*101325)/(622+V17) -> 1175.3893 | AA17: =288.68*(1.098+(U17)/100)^8.02 -> 3300.4248
B18: 17. Salle d'attente | C18: ='Ecart de soufflage'!N23 -> 0.48787649 | D18: ='Ecart de soufflage'!H23 -> 0.16063779 | E18: =W$14-W$13 -> 0.2 | F18: =C18*E18 -> 0.097575298 | G18: =W$17-W$15 -> 16.6 | H18: =C18*G18 -> 8.0987497 | I18: =V$15-V$14 -> 1.9 | J18: =C18*I18*3.6 -> 3.3370752 | K18: ='Ecart de soufflage'!O23 -> 0.38869335 | L18: ='Ecart de soufflage'!I23 -> 0.15734266 | M18: =W$26-W$24 -> 3.1728382 | N18: =K18*M18 -> 1.2332611 | O18: =W$24-W$23 -> -11.272838 | P18: =K18*O18 -> -4.3816773 | Q18: =V$24-V$22 -> -5.1 | R18: =K18*Q18*3.6 -> -7.1364099
B19: 18.WC individuelle | C19: ='Ecart de soufflage'!N24 -> 0.041714675 | D19: ='Ecart de soufflage'!H24 -> 0.017848644 | E19: =W$14-W$13 -> 0.2 | F19: =C19*E19 -> 0.0083429349 | G19: =W$17-W$15 -> 16.6 | H19: =C19*G19 -> 0.6924636 | I19: =V$15-V$14 -> 1.9 | J19: =C19*I19*3.6 -> 0.28532837 | K19: ='Ecart de soufflage'!O24 -> 0.037047361 | L19: ='Ecart de soufflage'!I24 -> 0.017482517 | M19: =W$26-W$24 -> 3.1728382 | N19: =K19*M19 -> 0.11754528 | O19: =W$24-W$23 -> -11.272838 | P19: =K19*O19 -> -0.41762891 | Q19: =V$24-V$22 -> -5.1 | R19: =K19*Q19*3.6 -> -0.68018955
B20: 19.WC PMR | C20: ='Ecart de soufflage'!N25 -> 0.038539773 | D20: ='Ecart de soufflage'!H25 -> 0.017848644 | E20: =W$14-W$13 -> 0.2 | F20: =C20*E20 -> 0.0077079547 | G20: =W$17-W$15 -> 16.6 | H20: =C20*G20 -> 0.63976024 | I20: =V$15-V$14 -> 1.9 | J20: =C20*I20*3.6 -> 0.26361205 | K20: ='Ecart de soufflage'!O25 -> 0.035337361 | L20: ='Ecart de soufflage'!I25 -> 0.017482517 | M20: =W$26-W$24 -> 3.1728382 | N20: =K20*M20 -> 0.11211973 | O20: =W$24-W$23 -> -11.272838 | P20: =K20*O20 -> -0.39835236 | Q20: =V$24-V$22 -> -5.1 | R20: =K20*Q20*3.6 -> -0.64879395 | T20: Régime éstival à roue
B21: 20.WC femme | C21: ='Ecart de soufflage'!N26 -> 0.15345356 | D21: ='Ecart de soufflage'!H26 -> 0.089243218 | E21: =W$14-W$13 -> 0.2 | F21: =C21*E21 -> 0.030690712 | G21: =W$17-W$15 -> 16.6 | H21: =C21*G21 -> 2.5473291 | I21: =V$15-V$14 -> 1.9 | J21: =C21*I21*3.6 -> 1.0496223 | K21: ='Ecart de soufflage'!O26 -> 0.15554931 | L21: ='Ecart de soufflage'!I26 -> 0.087412587 | M21: =W$26-W$24 -> 3.1728382 | N21: =K21*M21 -> 0.49353278 | O21: =W$24-W$23 -> -11.272838 | P21: =K21*O21 -> -1.7534822 | Q21: =V$24-V$22 -> -5.1 | R21: =K21*Q21*3.6 -> -2.8558852 | U21: T [°C] | V21: x [geau/kgas] | W21: h [kJ/kgas] | X21: HR [%] | Y21: v [m³/kgas] | Z21: pv [Pa] | AA21: ps [Pa]
B22: 21.WC homme | C22: ='Ecart de soufflage'!N27 -> 0.10821122 | D22: ='Ecart de soufflage'!H27 -> 0.089243218 | E22: =W$14-W$13 -> 0.2 | F22: =C22*E22 -> 0.021642243 | G22: =W$17-W$15 -> 16.6 | H22: =C22*G22 -> 1.7963062 | I22: =V$15-V$14 -> 1.9 | J22: =C22*I22*3.6 -> 0.74016473 | K22: ='Ecart de soufflage'!O27 -> 0.13118181 | L22: ='Ecart de soufflage'!I27 -> 0.087412587 | M22: =W$26-W$24 -> 3.1728382 | N22: =K22*M22 -> 0.41621865 | O22: =W$24-W$23 -> -11.272838 | P22: =K22*O22 -> -1.4787913 | Q22: =V$24-V$22 -> -5.1 | R22: =K22*Q22*3.6 -> -2.4084979 | T22: e | U22: 32 | V22: =15 -> 15 | W22: =70.5 -> 70.5 | X22: 50 | Y22: =0.89 -> 0.89 | Z22: =(X22/100)*AA22 -> 2375.9105 | AA22: =288.68*(1.098+(U22)/100)^8.02 -> 4751.821
B23: 22.Trappe | C23: ='Ecart de soufflage'!N28 -> 0.096040762 | D23: ='Ecart de soufflage'!H28 -> 0 | E23: =W$14-W$13 -> 0.2 | F23: =C23*E23 -> 0.019208152 | G23: =W$17-W$15 -> 16.6 | H23: =C23*G23 -> 1.5942767 | I23: =V$15-V$14 -> 1.9 | J23: =C23*I23*3.6 -> 0.65691882 | K23: ='Ecart de soufflage'!O28 -> 0.0408375 | L23: ='Ecart de soufflage'!I28 -> 0 | M23: =W$26-W$24 -> 3.1728382 | N23: =K23*M23 -> 0.12957078 | O23: =W$24-W$23 -> -11.272838 | P23: =K23*O23 -> -0.46035453 | Q23: =V$24-V$22 -> -5.1 | R23: =K23*Q23*3.6 -> -0.7497765 | T23: 0 | U23: 19.3 | V23: 11.9 | W23: 50.3 | X23: 79.9 | Y23: =(U23+273.15)*287.05/101325 -> 0.8285001 | Z23: =(X23/100)*AA23 -> 1788.9242 | AA23: =288.68*(1.098+(U23)/100)^8.02 -> 2238.9539
B24: 23.Trémis | C24: ='Ecart de soufflage'!N29 -> 0.030990564 | D24: ='Ecart de soufflage'!H29 -> 0 | E24: =W$14-W$13 -> 0.2 | F24: =C24*E24 -> 0.0061981128 | G24: =W$17-W$15 -> 16.6 | H24: =C24*G24 -> 0.51444336 | I24: =V$15-V$14 -> 1.9 | J24: =C24*I24*3.6 -> 0.21197546 | K24: ='Ecart de soufflage'!O29 -> 0.0131775 | L24: ='Ecart de soufflage'!I29 -> 0 | M24: =W$26-W$24 -> 3.1728382 | N24: =K24*M24 -> 0.041810076 | O24: =W$24-W$23 -> -11.272838 | P24: =K24*O24 -> -0.14854783 | Q24: =V$24-V$22 -> -5.1 | R24: =K24*Q24*3.6 -> -0.2419389 | T24: 3 | U24: =((AA24/288.68)^(1/8.02)-1.098)*100 -> 13.881596 | V24: =V25 -> 9.9 | W24: =1.009*(U24)+V24/1000*(2501.6+1.854*(U24)) -> 39.027162 | X24: 100 | Y24: =0.83 -> 0.83 | Z24: =(V24*101325)/(622+V24) -> 1587.4624 | AA24: =Z24 -> 1587.4624
