Workbook

Sheet Données
J6: b=tint
D9: Données climatiques
D10: Description | E10: Symbole | F10: Unité | G10: Valeur
D11: Température extérieure de base | E11: T ext | F11: [°C] | G11: =-8 -> -8
D12: Moyenne annuelle de la température extérieure | E12: T m,ext | F12: [°C] | G12: 10
D13: Coefficients d'exposition e et e
D14: Orientation | G14: Valeur
G15: p.u. | J15: =('Données'!E25-
D16: Toutes | G16: 1.00
D17: Données sur les pièces chauffées
D18: Nom de la pièce | E18: Température hiver | F18: Température été | G18: Aire de la pièce | H18: Volume intérieur
K19: Amélioration / précision ?
E20: T int | F20: T int | G20: A1 | H20: V | K20: Ajout hauteur des pieces
E21: [°C] | F21: [°C] | G21: [m ²] | H21: [m³] | K21: precision piece chauffé en hiver / été
D22: 2.kitchenette et cafèt | E22: 20 | F22: 24 | G22: 33.5018 | H22: =G22*3.6 -> 120.60648 | K22: nb de personne ( occupant )
D23: 4. Bureau 4 | E23: 22 | F23: 26 | G23: 31.1704 | H23: =G23*3.6 -> 112.21344 | K23: puissance des eclairages pour chaque piece
D24: 5. Bureau 5 | E24: 22 | F24: 26 | G24: 20.16 | H24: =G24*3.6 -> 72.576 | K24: Données des matériaux
D25: 17. Salle d'attente 17 | E25: 20 | F25: 26 | G25: 50.024601 | H25: =G25*3.6 -> 180.08856
D26: 6. Bureau 6 | E26: 22 | F26: 26 | G26: 20.16 | H26: =G26*3.6 -> 72.576 | J26: Données relatives aux matériaux
D27: 7.Bureau 7 | E27: 22 | F27: 26 | G27: 21.52 | H27: =G27*3.6 -> 77.472 | J27: Coefficient de transmission
D28: 8. Salle de réunion 8 | E28: 20 | F28: 24 | G28: 36.0996 | H28: =G28*3.6 -> 129.95856 | J28: béton | K28: 1.3
D29: 15. Secrétariat 15 | E29: 22 | F29: 26 | G29: 32.175 | H29: =G29*3.6 -> 115.83 | J29: enduit | K29: 0.93
D30: 16. Salle de réunion 16 | E30: 20 | F30: 24 | G30: 52.62 | H30: =G30*3.6 -> 189.432 | J30: béton armé | K30: 1.7
D31: Data center | E31: 20 | F31: 20 | H31: =G31*3.6 -> 0 | J31: polystyrène expansé | K31: 0.045
A32: pieces | B32: A PORTE | D32: Etage | E32: 20 | F32: 20 | H32: =G32*3.6 -> 0 | J32: isolant Ytong
A33: 16 17 18 20 21 porte de 81cm | B33: 1,6443m² | D33: 9.Couloirs droite 9 | E33: =18 -> 18 | F33: 25 | G33: 49.0625 | H33: =G33*3.6 -> 176.625 | J33: brique de terres cuites (rho = 1600) | K33: 1.09
A34: 19 porte de 101cm PMR | B34: 2,0503m² | D34: 20.Toilette Femme | E34: 16 | F34: 26 | G34: 17.4 | H34: =G34*3.6 -> 62.64 | J34: vitrages
D35: 21.Toilette Homme | E35: 16 | F35: 26 | G35: 12.27 | H35: =G35*3.6 -> 44.172 | J35: hourdis
D36: 14. distributeur 14 | E36: 18 | F36: 25 | G36: 23.0805 | H36: =G36*3.6 -> 83.0898 | J36: polyruéthane projeté
J37: chape armée
J38: dalle FXPI
A39: V16 (mcube) | B39: =(52.73-0.1)*3.78-0.02*2.1 -> 198.8994 | J39: lame d'air
A40: V18 | B40: =4.73*3.6 -> 17.028 | D40: Total | E40: 18 | G40: =SUM(G22:G31) -> 297.4314 | H40: =SUM(H22:H36) -> 1437.2798
A41: V19 | B41: =(4.37-0.16)*3.78-0.02*2.1 -> 15.8718
A42: V20 | B42: =(17.4-0.16-0.16)*3.78-0.02*2.1 -> 64.5204 | D42: Nom de la pièce | E42: Aire du sol | F42: Température été | G42: Temperature hiver | H42: Volume de la pièce
A43: V21 | B43: =(12.27-0.16)*3.78-0.02*2.1 -> 45.7338 | E43: A | F43: T int | G43: T | H43: V | I43: z
A44: V17 | B44: =3.78*(5.08+0.14+26.02+21.74+1.4+0.54+0.24)-0.02*2.1*6 -> 208.2528 | E44: [m^2] | F44: [°C] | G44: [°C] | H44: [m^3]
D45: 1.Coffre | E45: 37.05375 | F45: 26 | G45: 16 | H45: =E45*3.6 -> 133.3935
A46: V1 | B46: =30.36*3.78 -> 114.7608 | D46: 3. Escalier 3 | E46: 14.516 | F46: 25 | G46: 16 | H46: =E46*3.6 -> 52.2576
A47: V9 | B47: =3.6*(2.7+0.57+37.4+0.22+4.31)-0.02*2.1*9 -> 162.342 | D47: 18. Toilette individuelle | E47: 4.73 | F47: 26 | G47: 16 | H47: =E47*3.6 -> 17.028
...

Sheet Parois
M2: Coefficient de convection exterieur | N2: he | R2: Coefficient de convection intérieur | S2: hi | T2: h=1/R | X2: Rsi | Y2: 0.13
D3: R=d/lambda | M3: horizontal | N3: =1/0.04 -> 25 | R3: horizontal | S3: =1/0.13 -> 7.6923077 | X3: Rse | Y3: 0.04
D4: U=1/R | M4: ascendant | N4: 25 | R4: ascendant | S4: =1/0.1 -> 10
D5: Ufinal=1/somme(Rmat +Rconvection) | M5: descendant | N5: 25 | R5: descendant | S5: =1/0.17 -> 5.8823529
X6: Base vitrage | Y6: Hauteur vitrage | Z6: Base encadrement | AA6: Hauteur encadrement | AB6: Aire vitrage | AC6: Aire encadrement | AD6: Périmètre du vitrage | AE6: Uw | AG6: Ufinal avec h | AI6: Hypothèse : profilé en Aluminium
B7: Paroi extérieure | R7: Pour les apports | X7: [m] | Y7: [m] | Z7: [m] | AA7: [m] | AB7: [m²] | AC7: [m²] | AD7: [m] | AE7: [W/K] | AI7: Ug [ W/m²*K ] | AJ7: 1.1 | AK7: Double vitrage H.P en 4/16/4
B8: Couches | I8: d [m] | J8: λ [W/m.K] | K8: R [K/W] | L8: U [W/K] | M8: Source | R8: Masse volumique kg/m³ | S8: kg/m² | W8: SDR 8 | X8: 2.44 | Y8: 0.74 | Z8: 2.65 | AA8: 0.9 | AB8: =X8*Y8 -> 1.8056 | AC8: =Z8*AA8-AB8 -> 0.5794 | AD8: =2*X8+2*Y8 -> 6.36 | AE8: =(AB8*AJ$7+AC8*AJ$8+AD8*AJ$9)/(AB8+AC8) -> 1.9229317 | AG8: =1/(1/AE8+1/N$3+1/S$3) -> 1.4491929 | AI8: Uf | AJ8: 3.28 | AK8: la plus ptit d on a pris 20
B9: Brique de terre cuite | I9: 0.07 | J9: 1.19 | K9: =I9/J9 -> 0.058823529 | L9: =1/(K9) -> 17 | M9: caract_materiaux.pdf page 3 | R9: 1700 | S9: =R9*I9 -> 119 | W9: BR 4 | X9: 3.565 | Y9: 0.74 | Z9: 3.725 | AA9: 0.9 | AB9: =X9*Y9 -> 2.6381 | AC9: =Z9*AA9-AB9 -> 0.7144 | AD9: =2*X9+2*Y9 -> 8.61 | AE9: =(AB9*AJ$7+AC9*AJ$8+AD9*AJ$9)/(AB9+AC9) -> 1.8470521 | AG9: =1/(1/AE9+1/N$3+1/S$3) -> 1.4056725 | AI9: ψg | AJ9: 0.11 | AK9: Pg 54 : C.2.4
B10: Polystyrène expansé | I10: 0.13 | J10: 0.045 | K10: =I10/J10 -> 2.8888889 | L10: =1/K10 -> 0.34615385 | M10: caract_materiaux.pdf page 10 | R10: 20 | S10: =R10*I10 -> 2.6 | W10: BR 5 | X10: 3.44 | Y10: 0.74 | Z10: 3.65 | AA10: 0.9 | AB10: =X10*Y10 -> 2.5456 | AC10: =Z10*AA10-AB10 -> 0.7394 | AD10: =2*X10+2*Y10 -> 8.36 | AE10: =(AB10*AJ$7+AC10*AJ$8+AD10*AJ$9)/(AB10+AC10) -> 1.8706216 | AG10: =1/(1/AE10+1/N$3+1/S$3) -> 1.4192819 | AI10: Ug double vitrage [W/m²K] | AJ10: 2.9 | AK10: Double vitrage standard
B11: Béton armé | I11: 0.14 | J11: 1.7 | K11: =I11/J11 -> 0.082352941 | L11: =1/K11 -> 12.142857 | M11: caract_materiaux.pdf page 7 | R11: 2400 | S11: =R11*I11 -> 336 | W11: BR 6a | X11: 2.44 | Y11: 0.74 | Z11: 2.65 | AA11: 0.9 | AB11: =X11*Y11 -> 1.8056 | AC11: =Z11*AA11-AB11 -> 0.5794 | AD11: =2*X11+2*Y11 -> 6.36 | AE11: =(AB11*AJ$7+AC11*AJ$8+AD11*AJ$9)/(AB11+AC11) -> 1.9229317 | AG11: =1/(1/AE11+1/N$3+1/S$3) -> 1.4491929
B12: Enduit | I12: 0.005 | J12: 0.93 | K12: =I12/J12 -> 0.0053763441 | L12: =1/K12 -> 186 | M12: caract_materiaux.pdf page 8 | R12: 1400 | S12: =R12*I12 -> 7 | W12: BR 6b | X12: 0.44 | Y12: 0.74 | Z12: 0.65 | AA12: 0.9 | AB12: =X12*Y12 -> 0.3256 | AC12: =Z12*AA12-AB12 -> 0.2594 | AD12: =2*X12+2*Y12 -> 2.36 | AE12: =(AB12*AJ$7+AC12*AJ$8+AD12*AJ$9)/(AB12+AC12) -> 2.5104137 | AG12: =1/(1/AE12+1/N$3+1/S$3) -> 1.7595079
L13: =1/(K9+K10+K11+K12+N3^-1+S3^-1) -> 0.31196949 | M13: / | R13: =SUM(R9:R12) -> 5520 | S13: =SUM(S9:S12) -> 464.6 | W13: BR 7a | X13: 1.44 | Y13: 0.74 | Z13: 1.65 | AA13: 0.9 | AB13: =X13*Y13 -> 1.0656 | AC13: =Z13*AA13-AB13 -> 0.4194 | AD13: =2*X13+2*Y13 -> 4.36 | AE13: =(AB13*AJ$7+AC13*AJ$8+AD13*AJ$9)/(AB13+AC13) -> 2.0386478 | AG13: =1/(1/AE13+1/N$3+1/S$3) -> 1.5139559
W14: BR 7b | X14: 1.44 | Y14: 0.74 | Z14: 1.65 | AA14: 0.9 | AB14: =X14*Y14 -> 1.0656 | AC14: =Z14*AA14-AB14 -> 0.4194 | AD14: =2*X14+2*Y14 -> 4.36 | AE14: =(AB14*AJ$7+AC14*AJ$8+AD14*AJ$9)/(AB14+AC14) -> 2.0386478 | AG14: =1/(1/AE14+1/N$3+1/S$3) -> 1.5139559
W15: Kitchen/cafet 2 | X15: 3.94 | Y15: 0.74 | Z15: 4.1 | AA15: 0.95 | AB15: =X15*Y15 -> 2.9156 | AC15: =Z15*AA15-AB15 -> 0.9794 | AD15: =2*X15+2*Y15 -> 9.36 | AE15: =(AB15*AJ$7+AC15*AJ$8+AD15*AJ$9)/(AB15+AC15) -> 1.9125012 | AG15: =1/(1/AE15+1/N$3+1/S$3) -> 1.4432607
B16: Paroi extérieure rouge | R16: Pour les apports | W16: SDR 8 coin | X16: 0.755 | Y16: 3.36 | Z16: 1.045 | AA16: 3.6 | AB16: =X16*Y16 -> 2.5368 | AC16: =Z16*AA16-AB16 -> 1.2252 | AD16: =2*X16+2*Y16 -> 8.23 | AE16: =(AB16*AJ$7+AC16*AJ$8+AD16*AJ$9)/(AB16+AC16) -> 2.0506209 | AG16: =1/(1/AE16+1/N$3+1/S$3) -> 1.5205491
B17: Couches | I17: d [m] | J17: λ [W/m.K] | K17: R [K/W] | L17: U [W/K] | M17: Source | R17: Masse volumique | S17: kg/m² | W17: SDR 8 (x5) | X17: 1.26 | Y17: 3.36 | Z17: 1.5 | AA17: 3.6 | AB17: =X17*Y17 -> 4.2336 | AC17: =Z17*AA17-AB17 -> 1.1664 | AD17: =2*X17+2*Y17 -> 9.24 | AE17: =(AB17*AJ$7+AC17*AJ$8+AD17*AJ$9)/(AB17+AC17) -> 1.7591022 | AG17: =1/(1/AE17+1/N$3+1/S$3) -> 1.3541479
B18: Enduit | I18: 0.005 | J18: 0.93 | K18: =I18/J18 -> 0.0053763441 | L18: =1/K18 -> 186 | M18: caract_materiaux.pdf page 8 | R18: 1600 | S18: =R18*I18 -> 8 | W18: mini hall 11 | X18: 0.96 | Y18: 3.36 | Z18: 1.19 | AA18: 3.6 | AB18: =X18*Y18 -> 3.2256 | AC18: =Z18*AA18-AB18 -> 1.0584 | AD18: =2*X18+2*Y18 -> 8.64 | AE18: =(AB18*AJ$7+AC18*AJ$8+AD18*AJ$9)/(AB18+AC18) -> 1.860437 | AG18: =1/(1/AE18+1/N$3+1/S$3) -> 1.4134113
B19: Bloc de béton | I19: 0.14 | J19: 1.3 | K19: =I19/J19 -> 0.10769231 | L19: =1/K19 -> 9.2857143 | M19: caract_materiaux.pdf page 6 | R19: 2400 | S19: =R19*I19 -> 336 | W19: Vitrage 12a/12b | X19: 1.26 | Y19: 3.36 | Z19: 1.5 | AA19: 3.6 | AB19: =X19*Y19 -> 4.2336 | AC19: =Z19*AA19-AB19 -> 1.1664 | AD19: =2*X19+2*Y19 -> 9.24 | AE19: =(AB19*AJ$7+AC19*AJ$8+AD19*AJ$9)/(AB19+AC19) -> 1.7591022 | AG19: =1/(1/AE19+1/N$3+1/S$3) -> 1.3541479
B20: Enduit | I20: 0.005 | J20: 0.93 | K20: =I20/J20 -> 0.0053763441 | L20: =1/K20 -> 186 | M20: caract_materiaux.pdf page 8 | R20: 1600 | S20: =R20*I20 -> 8 | W20: Porte de l'entrée | X20: 1.18 | Y20: 3.32 | Z20: 1.4 | AA20: 3.6 | AB20: 3.37 | AC20: =Z20*AA20-AB20 -> 1.67 | AD20: =2*X20+2*Y20 -> 9 | AE20: =(AB20*AJ$7+AC20*AJ$8+AD20*AJ$9)/(AB20+AC20) -> 2.0187698 | AG20: =1/(1/AE20+1/N$3+1/S$3) -> 1.5029657
L21: =1/(SUM(K18:K20)+N3^-1+S3^-1) -> 3.4668655 | M21: / | R21: =SUM(R18:R20) -> 5600 | S21: =SUM(S18:S20) -> 352 | W21: secretariat (x2) | X21: 1.26 | Y21: 3.36 | Z21: 1.5 | AA21: 3.6 | AB21: =X21*Y21 -> 4.2336 | AC21: =Z21*AA21-AB21 -> 1.1664 | AD21: =2*X21+2*Y21 -> 9.24 | AE21: =(AB21*AJ$7+AC21*AJ$8+AD21*AJ$9)/(AB21+AC21) -> 1.7591022 | AG21: =1/(1/AE21+1/N$3+1/S$3) -> 1.3541479
W22: int vitre entrée (x2) | X22: 0.98 | Y22: 2.15 | Z22: 1.08 | AA22: 2.25 | AB22: =X22*Y22 -> 2.107 | AC22: =Z22*AA22-AB22 -> 0.323 | AD22: =2*X22+2*Y22 -> 6.26 | AE22: =(AB22*AJ$7+AC22*AJ$8+AD22*AJ$9)/(AB22+AC22) -> 1.673144 | AG22: =1/(1/AE22+1/N$3+1/S$3) -> 1.3026309
B23: Paroi intérieure rouge | R23: Pour les apports | W23: mini hall 13 | X23: 0.96 | Y23: 3.36 | Z23: 1.09 | AA23: 3.6 | AB23: =X23*Y23 -> 3.2256 | AC23: =Z23*AA23-AB23 -> 0.6984 | AD23: =2*X23+2*Y23 -> 8.64 | AE23: =(AB23*AJ$7+AC23*AJ$8+AD23*AJ$9)/(AB23+AC23) -> 1.7302018 | AG23: =1/(1/AE23+1/N$3+1/S$3) -> 1.3369569
B24: Couches | I24: d [m] | J24: λ [W/m.K] | K24: R [K/W] | L24: U [W/K] | M24: Source | R24: Masse volumique | S24: kg/m² | W24: secretariat extreme(x2) | X24: 1.26 | Y24: 3.36 | Z24: 1.49 | AA24: 3.6 | AB24: =X24*Y24 -> 4.2336 | AC24: =Z24*AA24-AB24 -> 1.1304 | AD24: =2*X24+2*Y24 -> 9.24 | AE24: =(AB24*AJ$7+AC24*AJ$8+AD24*AJ$9)/(AB24+AC24) -> 1.7488949 | AG24: =1/(1/AE24+1/N$3+1/S$3) -> 1.348091
B25: Enduit | I25: 0.005 | J25: 0.93 | K25: =I25/J25 -> 0.0053763441 | L25: =1/K25 -> 186 | M25: caract_materiaux.pdf page 8 | R25: 1600 | S25: =R25*I25 -> 8 | W25: Porte coulissante | X25: 0.519 | Y25: 2.2 | Z25: 0.569 | AA25: 2.25 | AB25: =X25*Y25 -> 1.1418 | AC25: =Z25*AA25-AB25 -> 0.13845 | AD25: =2*X25+2*Y25 -> 5.438 | AE25: =(AB25*AJ7+AC25*AJ$8+AD25*AJ$9)/(AB25+AC25) -> 1.8029885 | AG25: =1/(1/AE25+1/N$3+1/S$3) -> 1.3800056
B26: Bloc de béton | I26: 0.14 | J26: 1.3 | K26: =I26/J26 -> 0.10769231 | L26: =1/K26 -> 9.2857143 | M26: caract_materiaux.pdf page 6 | R26: 2400 | S26: =R26*I26 -> 336
B27: Enduit | I27: 0.005 | J27: 0.93 | K27: =I27/J27 -> 0.0053763441 | L27: =1/K27 -> 186 | M27: caract_materiaux.pdf page 8 | R27: 1600 | S27: =R27*I27 -> 8
L28: =1/(K25+K26+K27+2*S3^-1) -> 2.6423919 | M28: / | R28: =SUM(R25:R27) -> 5600 | S28: =SUM(S25:S27) -> 352
B30: Paroi coffre-fort | R30: Pour les apports
B31: Couches | I31: d [m] | J31: λ [W/m.K] | K31: R [K/W] | L31: U [W/K] | M31: Source | R31: Masse volumique | S31: kg/m²
B32: Enduit | I32: 0.005 | J32: 0.93 | K32: =I32/J32 -> 0.0053763441 | L32: =1/K32 -> 186 | M32: caract_materiaux.pdf page 8 | R32: 2500 | S32: =R32*I32 -> 12.5
B33: Béton haute densité | I33: 0.5 | J33: 1.7 | K33: =I33/J33 -> 0.29411765 | L33: =1/K33 -> 3.4 | M33: caract_materiaux.pdf page 25 | R33: 2400 | S33: =R33*I33 -> 1200
B34: Enduit | I34: 0.005 | J34: 0.93 | K34: =I34/J34 -> 0.0053763441 | L34: =1/K34 -> 186 | M34: caract_materiaux.pdf page 8 | R34: 2500 | S34: =R34*I34 -> 12.5
L35: =1/(K32+K33+K34+2*S3^-1) -> 1.7703178 | M35: / | R35: =SUM(R32:R34) -> 7400 | S35: =SUM(S32:S34) -> 1225
B37: Paroi blanche | R37: Pour les apports
B38: Couches | I38: d [m] | J38: λ [W/m.K] | K38: R [K/W] | L38: U [W/K] | M38: Source | R38: Masse volumique | S38: kg/m²
B39: Enduit | I39: 0.005 | J39: 0.93 | K39: =I39/J39 -> 0.0053763441 | L39: =1/K39 -> 186 | M39: caract_materiaux.pdf page 8 | R39: 2500 | S39: =R39*I39 -> 12.5
B40: Ytong haute densité | I40: 0.09 | J40: 0.32 | K40: =I40/J40 -> 0.28125 | L40: =1/K40 -> 3.5555556 | M40: caract_materiaux.pdf page 6 | R40: 1000 | S40: =R40*I40 -> 90
B41: Enduit | I41: 0.005 | J41: 0.93 | K41: =I41/J41 -> 0.0053763441 | L41: =1/K41 -> 186 | M41: caract_materiaux.pdf page 8 | R41: 2500 | S41: =R41*I41 -> 12.5
L42: =1/(K39+K40+K41+2*S3^-1) -> 1.8115854 | M42: / | R42: =SUM(R39:R41) -> 6000 | S42: =SUM(S39:S41) -> 115
B44: Sol
...

Sheet Entrée (1)
B4: Déperdition vers l'exterieur
B5: Code | C5: Paroi | G5: Ak | H5: Uk | I5: ek | J5: Ak.Uk.ek
G6: m2 | H6: W/(m²*K) | I6: - | J6: W/K | O6: Apport depuis des espaces chauffés à des températures différentes
C7: fenetre mini hall 13 | G7: =Parois!AB23+Parois!AC23 -> 3.924 | H7: =Parois!AG23 -> 1.3369569 | I7: 1 | J7: =G7*H7*I7 -> 5.246219 | O7: Code | P7: Paroi | T7: fij | U7: Ak | V7: Uk | W7: fij.Ak.Uk
C8: vitrage 12a/12b | G8: =2*SUM(Parois!AB19:AC19) -> 10.8 | H8: =Parois!AG21 -> 1.3541479 | I8: 1 | J8: =G8*H8*I8 -> 14.624797 | T8: - | U8: m2 | V8: W/(m²*K) | W8: W/K
C9: porte entrée | G9: =SUM(Parois!AB20:AC20) -> 5.04 | H9: =Parois!AG20 -> 1.5029657 | I9: 1 | J9: =G9*H9*I9 -> 7.5749472 | P9: Salle d'attente | T9: =X30/W26 -> -0.14285714 | U9: =(0.05+1.95+0.2*2+0.075)*3.945 -> 9.763875 | V9: =Parois!L28 -> 2.6423919 | W9: =T9*U9*V9 -> -3.6857121
C10: fenetre mini hall 11 | G10: =SUM(Parois!AB18:AC18) -> 4.284 | H10: =Parois!AG18 -> 1.4134113 | I10: 1 | J10: =G10*H10*I10 -> 6.0550541 | P10: Secretariat | T10: =X31/W26 -> -0.14285714 | U10: =3.945*(3.97+0.3+0.05)-U11 -> 15.3981 | V10: =Parois!L28 -> 2.6423919 | W10: =T10*U10*V10 -> -5.812545
C11: Mur les petits bouts | G11: =2*0.235*3.78*0.1 -> 0.17766 | H11: =Parois!L13 -> 0.31196949 | I11: 1 | J11: =G11*H11*I11 -> 0.055424499 | P11: Portes vers secretariat | T11: =X31/W26 -> -0.14285714 | U11: =0.81*2.03 -> 1.6443 | V11: 2.5 | W11: =T11*U11*V11 -> -0.58725
I12: 1 | J12: =G12*H12*I12 -> 0 | P12: Salle de réunion | T12: =X33/W26 -> 0.14285714 | U12: =(4.17+0.05+0.3)*3.945 -> 17.8314 | V12: =Parois!L28 -> 2.6423919 | W12: =T12*U12*V12 -> 6.7310782
J13: = | P13: Vers couloir | T13: =X32/W26 -> 0 | U13: =(1.75+0.05+0.2)*3.945-U14 -> 6.2457 | V13: =Parois!L28 -> 2.6423919 | W13: =T13*U13*V13 -> 0
B14: Coefficients total de déperditions directe vers l'extérieur | H14: HT,ie | J14: =SUM(J7:J11) -> 33.556442 | P14: Portes vers couloir | T14: =X32/W26 -> 0 | U14: =0.81*2.03 -> 1.6443 | V14: 2.5 | W14: =T14*U14*V14 -> 0
B15: Déperdition à travers espaces non-chauffés | P15: vers distrib | T15: =X35/W26 -> 0 | U15: =(5.35+0.15+0.075)*3.945-U16 -> 16.872375 | V15: =Parois!L42 -> 1.8115854 | W15: =T15*U15*V15 -> 0
B16: Code | C16: Paroi | G16: Ak | H16: Uk | I16: bu | J16: Ak.Uk.bu | P16: portes coullissante vers distrib | T16: =X36/W26 -> 0 | U16: =4*SUM(Parois!AB25:AC25) -> 5.121 | V16: =Parois!AG25 -> 1.3800056 | W16: =T16*U16*V16 -> 0
G17: m2 | H17: W/(m²*K) | I17: - | J17: W/K | P17: Approv | T17: =X36/W26 -> 0 | U17: =2*0.3945 -> 0.789 | V17: =Parois!L28 -> 2.6423919 | W17: =T17*U17*V17 -> 0
P18: Sol | T18: =X34/W26 -> 0.71428571 | U18: =Données!E52 -> 18.2075 | V18: =Parois!L49 -> 0.3993743 | W18: =T18*U18*V18 -> 5.1940054
B19: Coefficients total de déperditions directe à travers espaces non chauffées (H iue) | O19: Coefficient total de déperditions vers des espaces chauffés à des températures différentes | W19: HT,ij | X19: =SUM(W12:W18) -> 11.925084
B20: Déperditions vers des espaces chauffés à des températures différentes | O20: Coefficient total de déperditions par transmission | T20: HT,l = Ht,ie+HT,lue+HT,lg+HT,ij W/K
B21: Code | C21: Paroi | G21: fij | H21: Ak | I21: Uk | J21: fij.Ak.Uk | O21: Données de température de base
G22: - | H22: m2 | I22: W/(m²*K) | J22: W/K | O22: Température extérieure de base | U22: θe | V22: °C | W22: 32 | Y22: [W]
C23: Salle d'attente | G23: =(($J$37-H42)/$J$38) -> -0.076923077 | H23: =(0.05+1.95+0.2*2+0.075)*3.945 -> 9.763875 | I23: =Parois!L28 -> 2.6423919 | J23: =G23*H23*I23 -> -1.9846142 | O23: Température intérieure de base | U23: θint,l | V23: °C | W23: 25
C24: Secretariat | G24: =(($J$37-H43)/$J$38) -> -0.15384615 | H24: =3.945*(3.97+0.3+0.05)-H25 -> 15.3981 | I24: =Parois!L28 -> 2.6423919 | J24: =G24*H24*I24 -> -6.2596639
C25: Portes vers secretariat | G25: =(($J$37-H43)/$J$38) -> -0.15384615 | H25: =0.81*2.03 -> 1.6443 | I25: 2.5 | J25: =G25*H25*I25 -> -0.63242308
C26: Salle de réunion | G26: =(($J$37-H45)/$J$38) -> -0.076923077 | H26: =(4.17+0.05+0.3)*3.945 -> 17.8314 | I26: =Parois!L28 -> 2.6423919 | J26: =G26*H26*I26 -> -3.6244267 | O26: Ecart de température de base | U26: θint,l - θe | V26: °C | W26: =W22-W23 -> 7
C27: Vers couloir | G27: =(($J$37-H44)/$J$38) -> 0 | H27: =(1.75+0.05+0.2)*3.945-H28 -> 6.2457 | I27: =Parois!L28 -> 2.6423919 | J27: =G27*H27*I27 -> 0 | O27: Déperditions de base par transmission avec l'extérieur 𝚽T,i=HT,i.(θint,i-θe) | X27: =W26*#REF! -> #REF!
C28: Portes vers couloir | G28: =ABS(($J$37-H44)/$J$38) -> 0 | H28: =0.81*2.03 -> 1.6443 | I28: 2.5 | J28: =G28*H28*I28 -> 0 | O28: Données de température de pièces adjacentes
C29: vers distrib | G29: =(($J$37-H47)/$J$38) -> 0 | H29: =(5.35+0.15+0.075)*3.945-H30 -> 16.872375 | I29: =Parois!L42 -> 1.8115854 | J29: =G29*H29*I29 -> 0 | O29: Nom de pièce | U29: T hiver | V29: T été | W29: ΔT hiver | X29: ΔT été
C30: portes coullissante vers distrib | G30: =(($J$37-H47)/$J$38) -> 0 | H30: =4*SUM(Parois!AB25:AC25) -> 5.121 | I30: =Parois!AG25 -> 1.3800056 | J30: =G30*H30*I30 -> 0 | O30: Salle d'attente | U30: / | V30: =Données!F25 -> 26 | W30: / | X30: =W$23-V30 -> -1 | Y30: [W]
C31: Approv | G31: =(($J$37-H48)/$J$38) -> 0 | H31: =2*0.3945 -> 0.789 | I31: =Parois!L28 -> 2.6423919 | J31: =G31*H31*I31 -> 0 | O31: Secretariat | U31: / | V31: =Données!F29 -> 26 | W31: / | X31: =W$23-V31 -> -1 | Y31: [W]
C32: Sol | G32: =((Données!G53-Données!G58)/(Données!G53-Données!G11)) -> 0.30769231 | H32: =Données!E52 -> 18.2075 | I32: =Parois!L49 -> 0.3993743 | J32: =G32*H32*I32 -> 2.2374177 | O32: Couloir | U32: / | V32: =Données!F33 -> 25 | W32: / | X32: =W$23-V32 -> 0
B33: Coefficient total de déperditions vers des espaces chauffés à des températures différentes | J33: HT,ij | K33: =J32 -> 2.2374177 | O33: Salle de réunion | U33: / | V33: =Données!F30 -> 24 | W33: / | X33: =W$23-V33 -> 1
B34: Coefficient total de déperditions par transmission | G34: HT,l = Ht,ie+HT,lue+HT,lg+HT,ij W/K | O34: Sol | U34: / | V34: =Données!F58 -> 20 | X34: =W$23-V34 -> 5
B35: Données de température de base | O35: distrib | U35: / | V35: =Données!F36 -> 25 | X35: =W$23-V35 -> 0
B36: Température extérieure de base | H36: θe | I36: °C | J36: -8 | O36: approv | U36: / | V36: =Données!F51 -> 25 | W36: / | X36: =W$23-V36 -> 0
B37: Température intérieure de base | H37: θint,l | I37: °C | J37: =Données!G52 -> 18 | O37: Déperditions de base par transmission avec les pièces adjacentes | X37: =X19*W26 -> 83.475585
B38: Ecart de température de base | H38: θint,l - θe | I38: °C | J38: =J37-J36 -> 26 | O38: Déperditions totales de la pièce | X38: =X27+X37 -> #REF!
B39: Déperditions de base par transmission 𝚽T,i=HT,i.(θint,i-θe) | K39: =(J14+K33)*J38 -> 930.64034
B40: Données de température de pièces adjacentes
B41: Nom de pièce | H41: T hiver | I41: T été | J41: ΔT hiver
B42: Salle d'attente | H42: =Données!E25 -> 20 | I42: =Données!F25 -> 26 | J42: =J$37-H42 -> -2
B43: Secretariat | H43: =Données!E29 -> 22 | I43: =Données!F29 -> 26 | J43: =J$37-H43 -> -4
...

Sheet Distrib et Approv
A2: DISTRIBUTEUR
B4: Déperdition vers l'exterieur | Q4: Apport depuis des espaces chauffés à des températures différentes
B5: Code | C5: Paroi | G5: Ak | H5: Uk | I5: ek | J5: Ak.Uk.ek | Q5: Code | R5: Paroi | V5: fij | W5: Ak | X5: Uk | Y5: fij.Ak.Uk
G6: m2 | H6: W/(m²*K) | I6: - | J6: W/K | V6: - | W6: m2 | X6: W/(m²*K) | Y6: W/K
C7: / | R7: Salle d'attente | V7: =Z28/Y24 -> -0.14285714 | W7: =(5.225+1.95+0.05+0.075)*3.945 -> 28.7985 | X7: =Parois!L28 -> 2.6423919 | Y7: =V7*W7*X7 -> -10.870989
B8: Total des ponts thermiques ΣkΨk.lk.ek W/K | J8: =0 -> 0 | R8: secretariat | V8: =Z29/Y24 -> -0.14285714 | W8: =(1.79+0.1+0.05)*3.945 -> 7.6533 | X8: =Parois!L28 -> 2.6423919 | Y8: =V8*W8*X8 -> -2.8890026
B9: Coefficients total de déperditions directe vers l'extérieur | H9: HT,ie | R9: Vers approvisionnement | V9: =Z31/Y24 -> 0 | W9: =(3.975+0.1+0.075)*3.945 -> 16.37175 | X9: =Parois!L28 -> 2.6423919 | Y9: =V9*W9*X9 -> 0
B10: Déperdition à travers espaces non-chauffés | R10: vers entrée | V10: =Z30/Y24 -> 0 | W10: =(5.35+0.15+0.075)*3.945 -> 21.993375 | X10: =Parois!L42 -> 1.8115854 | Y10: =V10*W10*X10 -> 0
B11: Code | C11: Paroi | G11: Ak | H11: Uk | I11: bu | J11: Ak.Uk.bu | R11: vers portes coulissantes entree | V11: =Z30/Y24 -> 0 | W11: =4*SUM(Parois!AB25:AC25) -> 5.121 | X11: =Parois!AG25 -> 1.3800056 | Y11: =V11*W11*X11 -> 0
G12: m2 | H12: W/(m²*K) | I12: - | J12: W/K | R12: Sol | V12: =Z32/Y24 -> 0.71428571 | W12: =Données!E36 -> 18 | X12: =Parois!L49 -> 0.3993743 | Y12: =V12*W12*X12 -> 5.1348124
B13: Coefficients total de déperditions directe à travers espaces non chauffées (H iue) | K13: =J8 -> 0
B14: Coefficients total de déperditions directe à travers le sol | H14: Ht,ig
B15: Déperditions vers des espaces chauffés à des températures différentes
B16: Code | C16: Paroi | G16: fij | H16: Ak | I16: Uk | J16: fij.Ak.Uk
G17: - | H17: m2 | I17: W/(m²*K) | J17: W/K | Q17: Coefficient total de déperditions vers des espaces chauffés à des températures différentes | Y17: HT,ij | Z17: =SUM(Y10:Y12) -> 5.1348124
C18: Salle d'attente | G18: =(($J$27-H33)/$J$29) -> -1.0769231 | H18: =(5.225+1.95+0.05+0.075)*3.945 -> 28.7985 | I18: =Parois!L28 -> 2.6423919 | J18: =G18*H18*I18 -> -81.950533 | Q18: Coefficient total de déperditions par transmission | V18: HT,l = Ht,ie+HT,lue+HT,lg+HT,ij W/K
C19: secretariat | G19: =(($J$28-H34)/$J$29) -> -0.15384615 | H19: =(1.79+0.1+0.05)*3.945 -> 7.6533 | I19: =Parois!L28 -> 2.6423919 | J19: =G19*H19*I19 -> -3.1112336 | Q19: Données de température de base
C20: Vers approvisionnement | G20: =(($J$28-H35)/$J$29) -> 0 | H20: =(3.975+0.1+0.075)*3.945 -> 16.37175 | I20: =Parois!L28 -> 2.6423919 | J20: =G20*H20*I20 -> 0 | Q20: Température extérieure de base | W20: θe | X20: °C | Y20: 32 | AA20: [W]
C21: vers entrée | G21: =(($J$28-H35)/$J$29) -> 0 | H21: =(5.35+0.15+0.075)*3.945 -> 21.993375 | I21: =Parois!L42 -> 1.8115854 | J21: =G21*H21*I21 -> 0 | Q21: Température intérieure de base | W21: θint,l | X21: °C | Y21: 25
C22: vers portes coulissantes entree | G22: =(($J$28-H35)/$J$29) -> 0 | H22: =4*SUM(Parois!AB25:AC25) -> 5.121 | I22: =Parois!AG25 -> 1.3800056 | J22: =G22*H22*I22 -> 0
C23: Sol | G23: =(($J$28-H37)/$J$29) -> 0.30769231 | H23: =Données!E36 -> 18 | I23: =Parois!L49 -> 0.3993743 | J23: =G23*H23*I23 -> 2.2119192
B24: Coefficient total de déperditions vers des espaces chauffés à des températures différentes | I24: HT,ij | J24: HT,ij | K24: =J23 -> 2.2119192 | Q24: Ecart de température de base | W24: θint,l - θe | X24: °C | Y24: =Y20-Y21 -> 7
B25: Coefficient total de déperditions par transmission | G25: HT,l = Ht,ie+HT,lue+HT,lg+HT,ij W/K | Q25: Déperditions de base par transmission avec l'extérieur 𝚽T,i=HT,i.(θint,i-θe) | Z25: =Y24*#REF! -> #REF!
B26: Données de température de base | Q26: Données de température de pièces adjacentes
B27: Température extérieure de base | H27: θe | I27: °C | J27: -8 | Q27: Nom de pièce | W27: T hiver | X27: T été | Y27: ΔT hiver | Z27: ΔT été
B28: Température intérieure de base | H28: θint,l | I28: °C | J28: =Données!E36 -> 18 | Q28: Salle d'attente | W28: / | X28: =Données!F25 -> 26 | Y28: / | Z28: =Y$21-X28 -> -1 | AA28: [W]
B29: Ecart de température de base | H29: θint,l - θe | I29: °C | J29: =J28-J27 -> 26 | Q29: Secretariat | W29: / | X29: =Données!F29 -> 26 | Y29: / | Z29: =Y$21-X29 -> -1 | AA29: [W]
B30: Déperditions de base par transmission 𝚽T,i=HT,i.(θint,i-θe) | K30: =K24*J29 -> 57.509899 | Q30: Entrée | W30: / | X30: =Données!F53 -> 25 | Y30: / | Z30: =Y$21-X30 -> 0
B31: Données de température de pièces adjacentes | Q31: Approvisionnement | W31: / | X31: =Données!F51 -> 25 | Y31: / | Z31: =Y$21-X31 -> 0
B32: Nom de pièce | H32: T hiver | I32: T été | J32: ΔT hiver | K32: ΔT été | Q32: Sol | W32: / | X32: =Données!F58 -> 20 | Z32: =Y$21-X32 -> 5
B33: Salle d'attente | H33: =Données!E25 -> 20 | I33: =Données!F25 -> 26 | J33: =J$28-H33 -> -2 | K33: =$J$28-I33 -> -8 | W33: / | Z33: =Y$23-X33 -> 0
B34: Secretariat | H34: =Données!E29 -> 22 | I34: =Données!F29 -> 26 | J34: =J$28-H34 -> -4 | K34: =$J$28-I34 -> -8 | W34: / | Y34: / | Z34: =Y$23-X34 -> 0
B35: Entrée | H35: =Données!G53 -> 18 | I35: =Données!#REF! -> #REF! | J35: =J$28-H35 -> 0 | K35: =$J$28-H35 -> 0 | Q35: Déperditions de base par transmission avec les pièces adjacentes | Z35: =Z17*Y24 -> 35.943687
B36: Approvisionnement | H36: =Données!G51 -> 18 | I36: =Données!F30 -> 24 | J36: =J$28-H36 -> 0 | K36: =$J$28-I36 -> -6 | Q36: Déperditions totales de la pièce | Z36: =Z25+Z35 -> #REF!
B37: Sol | H37: =Données!G58 -> 10 | I37: =Données!F31 -> 20 | J37: =J$28-H37 -> 8 | K37: =$J$28-I37 -> -2
B38: Déperditions de base par transmission avec les pièces adjacentes | K38: =#REF!*J37 -> #REF!
B39: Déperditions totales de la pièce | K39: =K30+K38 -> #REF!
C52: Approv | D52: Déperdition vers l'exterieur
C53: By Anis | D53: Code | E53: Paroi | I53: Ak | J53: Uk | K53: ek | L53: Ak.Uk.ek
I54: m2 | J54: W/(m²*K) | K54: - | L54: W/K | S54: Apport depuis des espaces chauffés à des températures différentes
...

Sheet Escalier (1)
B3: Déperdition vers l'exterieur
B4: Code | C4: Paroi | G4: Ak | H4: Uk | I4: ek | J4: Ak.Uk.ek
G5: m2 | H5: W/(m²*K) | I5: - | J5: W/K
B6: a | C6: Mur | G6: =3.8*3.94 -> 14.972 | H6: =Parois!L13 -> 0.31196949 | I6: 0 | J6: =G6*H6*I6 -> 0 | O6: Apport vers l'exterieur
J7: =SUM(J6:J6) -> 0 | O7: Code | P7: Paroi | T7: Ak | U7: Uk | V7: ek | W7: Ak.Uk.ek
B8: Code | C8: Ponts thermiques | G8: Ψk | H8: lk | I8: ek | J8: Ψk.Ik.Ek | T8: m2 | U8: W/(m²*K) | V8: - | W8: W/K
G9: W/(m.K) | H9: m | I9: - | J9: W/K | O9: N | P9: Mur | T9: =3.8*3.94 -> 14.972 | U9: =Parois!L13 -> 0.31196949 | V9: 1 | W9: =T9*U9*V9 -> 4.6708071
C10: /
B11: Total des ponts thermiques ΣkΨk.lk.ek W/K | J11: =0 -> 0 | O11: Code | P11: Ponts thermiques | T11: Ψk | U11: lk | V11: ek | W11: Ψk.Ik.Ek
B12: Coefficients total de déperditions directe vers l'extérieur | H12: HT,ie | T12: W/(m.K) | U12: m | V12: - | W12: W/K
B13: Déperdition à travers espaces non-chauffés | P13: /
B14: Code | C14: Paroi | G14: Ak | H14: Uk | I14: bu | J14: Ak.Uk.bu | O14: Total des ponts thermiques ΣkΨk.lk.ek W/K | W14: 0
G15: m2 | H15: W/(m²*K) | I15: - | J15: W/K | O15: Coefficients total de déperditions directe vers l'extérieur | U15: HT,ie
G16: / | H16: / | I16: / | O16: Apport à travers espaces non-chauffés
C17: / | G17: / | H17: / | I17: / | O17: Code | P17: Paroi | T17: Ak | U17: Uk | V17: bu | W17: Ak.Uk.bu
B18: Total des parois | J18: =J17+J16 -> 0 | T18: m2 | U18: W/(m²*K) | V18: - | W18: W/K
B19: Code | C19: Ponts thermiques | G19: Ψk | H19: lk | I19: bu | J19: Ψk.Ik.bu | P19: Couloir | U19: 2.642 | V19: 0 | W19: 0
G20: W/(m.K) | H20: m | I20: - | J20: W/K | P20: Portes vers couloir | U20: 2.5 | V20: 0 | W20: 0
C21: / | O21: Total des parois | W21: 0
B22: Coefficients total de déperditions directe à travers espaces non chauffées (H iue) | O22: Code | P22: Ponts thermiques | T22: Ψk | U22: lk | V22: bu | W22: Ψk.Ik.bu
B23: Déperditions directes par le sol | T23: W/(m.K) | U23: m | V23: - | W23: W/K
B24: Code | C24: Paroi | G24: Ak | H24: Uk | I24: ek | J24: Ak.Uk.ek | P24: /
G25: m2 | H25: W/(m²*K) | I25: - | J25: W/K | O25: Coefficients total de déperditions directe à travers espaces non chauffées (H iue)
O26: Apport directes par le sol
B27: Coefficients total de déperditions directe à travers le sol | H27: Ht,ig | O27: Code | P27: Paroi | T27: Ak | U27: Uk | V27: ek | W27: Ak.Uk.ek
B28: Déperditions vers des espaces chauffés à des températures différentes | T28: m2 | U28: W/(m²*K) | V28: - | W28: W/K
B29: Code | C29: Paroi | G29: fij | H29: Ak | I29: Uk | J29: fij.Ak.Uk
G30: - | H30: m2 | I30: W/(m²*K) | J30: W/K | O30: Coefficients total de déperditions directe à travers le sol | U30: Ht,ig
C31: Salle de réunion | G31: =0 -> 0 | H31: =0 -> 0 | I31: =Parois!L28 -> 2.6423919 | J31: =G31*H31*I31 -> 0 | O31: Apport vers des espaces chauffés à des températures différentes
C32: Bureau | G32: =0 -> 0 | H32: =0 -> 0 | I32: =Parois!L28 -> 2.6423919 | J32: =G32*H32*I32 -> 0 | O32: Code | P32: Paroi | T32: fij | U32: Ak | V32: Uk | W32: fij.Ak.Uk
B33: Coefficient total de déperditions vers des espaces chauffés à des températures différentes | I33: HT,ij | J33: =SUM(J31:J32) -> 0 | T33: - | U33: m2 | V33: W/(m²*K) | W33: W/K
B34: Coefficient total de déperditions par transmission | G34: HT,l = Ht,ie+HT,lue+HT,lg+HT,ij W/K | P34: kitchennette | T34: =X46/W41 -> 0.14285714 | U34: =(3.74+0.15)*3.945 -> 15.34605 | V34: =Parois!L$28 -> 2.6423919 | W34: =T34*U34*V34 -> 5.7928969
B35: Données de température de base | P35: Bureau | T35: =X47/W41 -> -0.14285714 | U35: =(3.74+0.15)*3.945 -> 15.34605 | V35: =Parois!L$28 -> 2.6423919 | W35: =T35*U35*V35 -> -5.7928969
B36: Température extérieure de base | H36: θe | I36: °C | J36: -8 | O36: Coefficient total de déperditions vers des espaces chauffés à des températures différentes | W36: HT,ij | X36: =W34 -> 5.7928969
B37: Température intérieure de base | H37: θint,l | I37: °C | J37: =Données!G46 -> 16 | O37: Coefficient total de déperditions par transmission | T37: HT,l = Ht,ie+HT,lue+HT,lg+HT,ij W/K
B38: Ecart de température de base | H38: θint,l - θe | I38: °C | J38: =J37-J36 -> 24 | O38: Données de température de base
B39: Déperditions de base par transmission avec l'extérieur 𝚽T,i=HT,i.(θint,i-θe) | K39: =J38*J7 -> 0 | L39: [W] | O39: Température extérieure de base | U39: θe | V39: °C | W39: 32
B40: Données de température de pièces adjacentes | O40: Température intérieure de base | U40: θint,l | V40: °C | W40: 25
B41: Nom de pièce | H41: T hiver | I41: T été | J41: ΔT hiver | K41: ΔT été | O41: Ecart de température de base | U41: θint,l - θe | V41: °C | W41: =W39-W40 -> 7
B42: Couloir | H42: =Données!#REF! -> #REF! | I42: =Données!#REF! -> #REF! | K42: =$J$38-I42 -> #REF! | O42: Déperditions de base par transmission avec l'extérieur 𝚽T,i=HT,i.(θint,i-θe) | X42: 0 | Y42: [W]
...

Sheet Trappe (2)
C4: Déperdition vers l'exterieur
C5: Code | D5: Paroi | H5: Ak | I5: Uk | J5: ek | K5: Ak.Uk.ek
H6: m2 | I6: W/(m²*K) | J6: - | K6: W/K
D7: / | H7: / | I7: / | J7: / | K7: / | P7: TRAPPE BEN | Q7: Déperdition vers l'exterieur
K8: =SUM(K7:K7) -> 0 | Q8: Code | R8: Paroi | V8: Ak | W8: Uk | X8: ek | Y8: Ak.Uk.ek
C9: Code | D9: Ponts thermiques | H9: Ψk | I9: lk | J9: ek | K9: Ψk.Ik.Ek | V9: m2 | W9: W/(m²*K) | X9: - | Y9: W/K
H10: W/(m.K) | I10: m | J10: - | K10: W/K | Q10: b | R10: mur | V10: =5*3.94 -> 19.7 | W10: =Parois!L13 -> 0.31196949 | X10: 1 | Y10: =V10*W10*X10 -> 6.1457989
D11: / | Y11: =0 -> 0
C12: Total des ponts thermiques ΣkΨk.lk.ek W/K | K12: =0 -> 0 | Q12: Code | R12: Ponts thermiques | V12: Ψk | W12: lk | X12: ek | Y12: Ψk.Ik.Ek
C13: Coefficients total de déperditions directe vers l'extérieur | I13: HT,ie | V13: W/(m.K) | W13: m | X13: - | Y13: W/K
C14: Déperdition à travers espaces non-chauffés | R14: /
C15: Code | D15: Paroi | H15: Ak | I15: Uk | J15: bu | K15: Ak.Uk.bu | Q15: Total des ponts thermiques ΣkΨk.lk.ek W/K | Y15: =0 -> 0
H16: m2 | I16: W/(m²*K) | J16: - | K16: W/K | Q16: Coefficients total de déperditions directe vers l'extérieur | W16: HT,ie
D17: Couloir | H17: = | I17: = | J17: 1 | K17: 0 | Q17: Déperdition à travers espaces non-chauffés
D18: Coffre-fort | H18: = | I18: = | J18: 1 | K18: =0 -> 0 | Q18: Code | R18: Paroi | V18: Ak | W18: Uk | X18: bu | Y18: Ak.Uk.bu
C19: Total des parois | K19: =K18+K17 -> 0 | V19: m2 | W19: W/(m²*K) | X19: - | Y19: W/K
C20: Code | D20: Ponts thermiques | H20: Ψk | I20: lk | J20: bu | K20: Ψk.Ik.bu | R20: Couloir | V20: =3.7*(1.975+3.025) -> 18.5 | W20: =Parois!AD68 -> 0 | X20: 0
H21: W/(m.K) | I21: m | J21: - | K21: W/K | R21: Coffre-fort | V21: =2.875*3.7 -> 10.6375 | W21: =Parois!AD75 -> 0 | X21: 0 | Y21: =V21*W21*X21 -> 0
D22: / | H22: / | I22: / | J22: / | K22: / | Q22: Total des parois | Y22: =Y21+Y20 -> 0
C23: Coefficients total de déperditions directe à travers espaces non chauffées (H iue) | Q23: Code | R23: Ponts thermiques | V23: Ψk | W23: lk | X23: bu | Y23: Ψk.Ik.bu
C24: Déperditions directes par le sol | V24: W/(m.K) | W24: m | X24: - | Y24: W/K
C25: Code | D25: Paroi | H25: Ak | I25: Uk | J25: ek | K25: Ak.Uk.ek | R25: / | V25: / | W25: / | X25: / | Y25: /
H26: m2 | I26: W/(m²*K) | J26: - | K26: W/K | Q26: Coefficients total de déperditions directe à travers espaces non chauffées (H iue)
D27: sol | H27: =(3.49+3.025+3.6+3.025) -> 13.14 | I27: =0 -> 0 | J27: 1 | K27: =H27*I27*J27 -> 0 | Q27: Déperditions directes par le sol
C28: Coefficients total de déperditions directe à travers le sol | I28: Ht,ig | Q28: Code | R28: Paroi | V28: Ak | W28: Uk | X28: ek | Y28: Ak.Uk.ek
C29: Déperditions vers des espaces chauffés à des températures différentes | V29: m2 | W29: W/(m²*K) | X29: - | Y29: W/K
C30: Code | D30: Paroi | H30: fij | I30: Ak | J30: Uk | K30: fij.Ak.Uk
H31: - | I31: m2 | J31: W/(m²*K) | K31: W/K | Q31: Coefficients total de déperditions directe à travers le sol | W31: Ht,ig
D32: Salle d'attente | H32: = | I32: = | J32: =K3 -> 0 | K32: =0 -> 0 | Q32: Déperditions vers des espaces chauffés à des températures différentes
C33: Coefficient total de déperditions vers des espaces chauffés à des températures différentes | K33: HT,ij | Q33: Code | R33: Paroi | V33: fij | W33: Ak | X33: Uk | Y33: fij.Ak.Uk
C34: Coefficient total de déperditions par transmission | H34: HT,l = Ht,ie+HT,lue+HT,lg+HT,ij W/K | K34: =K27 -> 0 | V34: - | W34: m2 | X34: W/(m²*K) | Y34: W/K
C35: Données de température de base | Q35: a | R35: bureau 2 | V35: 0 | W35: =5*3.94 -> 19.7 | X35: =Parois!L28 -> 2.6423919 | Y35: =0 -> 0
C36: Température extérieure de base | I36: θe | J36: °C | K36: -8 | Q36: c | R36: bureau 1 | V36: 0 | W36: =5*3.94 -> 19.7 | X36: =Parois!L28 -> 2.6423919 | Y36: =0 -> 0
C37: Température intérieure de base | I37: θint,l | J37: °C | K37: =16 -> 16 | Q37: d | R37: couloir | V37: =0 -> 0 | W37: =0.7*3.94 -> 2.758 | X37: =Parois!L28 -> 2.6423919 | Y37: =V37*W37*X37 -> 0
C38: Ecart de température de base | I38: θint,l - θe | J38: °C | K38: =K37-K36 -> 24 | Q38: Coefficient total de déperditions vers des espaces chauffés à des températures différentes | Y38: HT,ij
C39: Déperditions de base par transmission avec l'extérieur 𝚽T,i=HT,i.(θint,i-θe) | L39: =K34*K38 -> 0 | M39: [W] | Q39: Coefficient total de déperditions par transmission | V39: HT,l = Ht,ie+HT,lue+HT,lg+HT,ij W/K
C40: Données de température de pièces adjacentes | Q40: Données de température de base
C41: Nom de pièce | I41: T hiver | J41: T été | K41: ΔT hiver | L41: ΔT été | Q41: Température extérieure de base | W41: θe | X41: °C | Y41: -10
C42: Couloir | I42: =Données!#REF! -> #REF! | J42: / | L42: =$K$37-J42 -> #VALUE! | Q42: Température intérieure de base | W42: θint,l | X42: °C | Y42: =Données!Y77 -> 0
C43: Coffre-fort | I43: =Données!G35 -> 12.27 | J43: / | K43: =$K$37-I43 -> 3.73 | L43: =$K$37-J43 -> #VALUE! | Q43: Ecart de température de base | W43: θint,l - θe | X43: °C | Y43: =Y42-Y41 -> 10
...

Sheet Coffre-fort (1)
B2: Coffre-fort
C3: Déperdition à travers espaces chauffés
C4: Code | D4: Paroi | H4: Ak | I4: Uk | J4: fij | K4: Ht ij
H5: m2 | I5: W/(m²*K) | J5: - | K5: W/K
C6: a | D6: kitchenette et couloir | H6: =(6.9+0.5)*3.94 -> 29.156 | I6: =Parois!L35 -> 1.7703178 | J6: =0 -> 0 | K6: =H6*I6*J6 -> 0 | N6: aucun mur mittoyen avec l'exterieur
C7: b | D7: couloir | H7: =(4.4+0.75)*3.94 -> 20.291 | I7: =Parois!L35 -> 1.7703178 | J7: =0 -> 0 | K7: =H7*I7*J7 -> 0
C9: d | D9: salle d'attente | H9: =(4.37+0.25)*3.94 -> 18.2028 | I9: =Parois!L35 -> 1.7703178 | J9: =0 -> 0 | K9: =H9*J9*I9 -> 0
C10: e | D10: salle d'attente | H10: =(4.4+0.5)*3.94 -> 19.306 | I10: =Parois!L35 -> 1.7703178 | J10: =0 -> 0 | K10: =H11*J11*I11 -> 0
C11: f | D11: porte blindée | H11: =2 -> 2 | I11: 0.5 | J11: =0 -> 0
D12: sol | H12: =((7.9-0.5)*4.9)+(0.25*3.175) -> 37.05375 | I12: =Parois!M99 -> 0.37721962 | J12: =(16-10)/(16--8) -> 0.25 | K12: =H12*I12*J12 -> 3.4943504
C13: Coefficients total de déperditions directe à travers espaces non chauffées (H iue) | L13: =K6+K7+K8+K9+K10+K11+K12 -> 3.4943504
C14: Déperditions vers des espaces non-chauffés à des températures différentes
C15: Code | D15: Paroi | H15: Bu | I15: Ak | J15: Uk | K15: HT
I16: m2 | J16: W/(m²*K) | K16: W/K
C17: c | D17: trémis | H17: =0 -> 0 | I17: =(2.875)*3.78 -> 10.8675 | J17: =Parois!L35 -> 1.7703178 | K17: =H17*I17*J17 -> 0 | N17: logique car je suis dans une non chauféé et dans ce cas en face c'est que y'as pas de deperdition car je suis dans un espace ou mes mures mittoyen sont a plus haute température
C18: Coefficient total de déperditions vers des espaces chauffés à des températures différentes | K18: HT,ij
C19: Coefficient total de déperditions par transmission | G19: HT,l = Ht,ie+HT,lue+HT,lg+HT,ij W/K
C20: Données de température | L20: =#REF!+K17 -> #REF!
C21: Température extérieure de base | I21: θe | J21: °C | K21: =Données!G11 -> -8 | L21: z
C22: Température intérieure de base | I22: θint,l | J22: °C | K22: =Données!G45 -> 16
C23: Ecart de température de base | I23: θint,l - θe | J23: °C | K23: =K22-K21 -> 24
C24: Déperditions de base par transmission 𝚽T,i=HT,i.(θint,i-θe) W | L24: =L13*K23 -> 83.864409
C25: Données de température de pièces adjacentes
C26: Nom de pièce | I26: T hiver | J26: T été | K26: ΔT hiver
I27: =Données!G44 -> [°C] | J27: / | K27: =K22-I27 -> #VALUE! | N27: ON EST AU 1 ER DONC PAS DE DEPERDITION DIRECT PAR LE SOL
C28: 3.Salle de réunion | I28: =Données!E23 -> 22 | J28: / | L28: ΔT été
C29: 10.Couloir | I29: =Données!E33 -> 18 | J29: / | L29: /
C30: 15.Trappe | I30: =Données!G36 -> 23.0805 | J30: / | L30: /
C31: 7.Salle d'attente | I31: =Données!E25 -> 20 | J31: / | L31: /
C32: Sous sol | I32: =Données!E31 -> 20 | J32: / | L32: / | N32: mittoyen avec tremis donc meme temperature donc pas de déperdition
L33: /
L34: /
D43: Apport depuis des espaces chauffés à des températures différentes
D44: Code | E44: Paroi | I44: fij | J44: Ak | K44: Uk | L44: fij.Ak.Uk
I45: - | J45: m2 | K45: W/(m²*K) | L45: W/K
E46: kitchenette et couloir | I46: =M66/L62 -> 0.33333333 | J46: =(6.9+0.5)*3.94 -> 29.156 | K46: =Parois!L$35 -> 1.7703178 | L46: =I46*J46*K46 -> 17.205128
E47: couloir | I47: =M67/L62 -> 0.16666667 | J47: =(4.4+0.75)*3.94-J50 -> 18.291 | K47: =Parois!L$35 -> 1.7703178 | L47: =I47*J47*K47 -> 5.3968138
E48: salle d'attente | I48: =M69/L62 -> 0 | J48: =(4.4+0.5)*3.94 -> 19.306 | K48: =Parois!L$35 -> 1.7703178 | L48: =I48*J48*K48 -> 0
E49: salle d'attente | I49: =M69/L62 -> 0 | J49: =(4.37+0.25)*3.94 -> 18.2028 | K49: =Parois!L$35 -> 1.7703178 | L49: =I49*J49*K49 -> 0
E50: porte blindée | I50: =M67/L62 -> 0.16666667 | J50: =2 -> 2 | K50: 1.5 | L50: =I50*J50*K50 -> 0.5
...

Sheet Bureau (5)
A1: Bureau 5 by BEN
B2: Déperdition vers l'exterieur | Y2: SDR8 | Z2: Déperdition vers l'exterieur
B3: Code | C3: Paroi | G3: Ak | H3: Uk | I3: ek | J3: Ak.Uk.ek | Y3: by Anis | Z3: Code | AA3: Paroi | AE3: Ak | AF3: Uk | AG3: ek | AH3: Ak.Uk.ek
G4: m2 | H4: W/(m²*K) | I4: - | J4: W/K | AE4: m2 | AF4: W/(m²*K) | AG4: - | AH4: W/K
B5: a | C5: Mur | G5: =(4.21*3.94) -> 16.5874 | H5: =Parois!L13 -> 0.31196949 | I5: 1 | J5: =G5*H5*I5 -> 5.1747626 | Z5: N-E | AA5: Mur | AE5: =3.31*3.945-AE6 -> 10.67295 | AF5: =Parois!L13 -> 0.31196949 | AG5: 1 | AH5: =AE5*AF5*AG5 -> 3.3296347
C6: fenetre | G6: =SUM(Parois!AB10:AC10) -> 3.285 | H6: =Parois!AG9 -> 1.4056725 | I6: 1 | J6: =G6*H6*I6 -> 4.6176342 | Z6: E | AA6: Fenêtre | AE6: =Parois!AB8+Parois!AC8 -> 2.385 | AF6: =Parois!AG8 -> 1.4491929 | AG6: 1 | AH6: =AE6*AF6*AG6 -> 3.456325
Z7: Coin | AA7: Vitrage | AE7: =Parois!AB16+Parois!AC16 -> 3.762 | AF7: =Parois!AG16 -> 1.5205491 | AG7: =1 -> 1 | AH7: =AE7*AF7*AG7 -> 5.7203056
J8: =J5+J7+J6 -> 9.7923968 | Z8: S | AA8: Vitrage | AE8: =(Parois!AB17+Parois!AC17)*5 -> 27 | AF8: =Parois!AG17 -> 1.3541479 | AG8: 1 | AH8: =AE8*AF8*AG8 -> 36.561992
B9: Code | C9: Ponts thermiques | G9: Ψk | H9: lk | I9: ek | J9: Ψk.Ik.Ek | AH9: =AH5+AH6+AH7+AH8 -> 49.068257
G10: W/(m.K) | H10: m | I10: - | J10: W/K | Z10: Total des ponts thermiques ΣkΨk.lk.ek W/K
Z11: Coefficients total de déperditions directe vers l'extérieur | AF11: HT,ie
B12: Total des ponts thermiques ΣkΨk.lk.ek W/K | J12: =J11 -> 0 | Z12: Déperdition à travers espaces non-chauffés
B13: Coefficients total de déperditions directe vers l'extérieur | H13: HT,ie | K13: =J8+J12 -> 9.7923968 | Z13: Code | AA13: Paroi | AE13: Ak | AF13: Uk | AG13: bu | AH13: Ak.Uk.bu | AI13: =AH15 -> 6.7906453
B14: Déperdition à travers espaces non chauffés | AE14: m2 | AF14: W/(m²*K) | AG14: - | AH14: W/K
B15: Code | C15: Paroi | G15: Ak | H15: Uk | I15: bu | J15: Ak.Uk.bu | AA15: Vers mini hall/approv | AE15: =4.56*3.945 -> 17.9892 | AF15: =Parois!L28 -> 2.6423919 | AG15: =($AH$39-AF44)/$AH$40 -> 0.14285714 | AH15: =AE15*AF15*AG15 -> 6.7906453
AV16: SDR8 | AW16: Apport depuis des espaces chauffés à des températures différentes
Z17: Total des parois | AW17: Code | AX17: Paroi | BB17: fij | BC17: Ak | BD17: Uk | BE17: fij.Ak.Uk
G18: m2 | H18: W/(m²*K) | I18: - | J18: W/K | Z18: Code | AA18: Ponts thermiques | AE18: Ψk | AF18: lk | AG18: bu | AH18: Ψk.Ik.bu | BB18: - | BC18: m2 | BD18: W/(m²*K) | BE18: W/K
B19: d | C19: Vers tremis | G19: =5*3.94 -> 19.7 | H19: =Parois!L28 -> 2.6423919 | I19: =(22-16)/(22--8) -> 0.2 | J19: =G19*H19*I19 -> 10.411024 | AE19: W/(m.K) | AF19: m | AG19: - | AH19: W/K | AX19: sol | BB19: =(BE30-BD37)/BE33 -> 0.5 | BC19: =(5.35+2.075)*3.7 -> 27.4725 | BD19: =Parois!L49 -> 0.3993743 | BE19: =BB19*BC19*BD19 -> 5.4859052
C20: sol | G20: =4.045*5.04 -> 20.3868 | H20: =Parois!L49 -> 0.3993743 | I20: =(22-10)/(22--8) -> 0.4 | J20: =G20*H20*I20 -> 3.2567856 | AA20: / | AX20: Couloir | BB20: =(BE30-BD38)/BE33 -> -0.125 | BC20: =3.7*3.97-BC21 -> 13.0447 | BD20: =Parois!L42 -> 1.8115854 | BE20: =BB20*BC20*BD20 -> -2.9539485
G21: =0 -> 0 | H21: =0 -> 0 | I21: =0 -> 0 | J21: =G21*H21*I21 -> 0 | Z21: Coefficients total de déperditions directe à travers espaces non chauffées (H iue) | AX21: Portes vers couloir | BB21: =(BE30-BD38)/BE33 -> -0.125 | BC21: =0.81*2.03 -> 1.6443 | BD21: 2.5 | BE21: =BB21*BC21*BD21 -> -0.51384375
B22: Total des parois | J22: =J19+J20 -> 13.66781 | Z22: Déperditions directes par le sol | AX22: Bureau
B23: Code | C23: Ponts thermiques | G23: Ψk | H23: lk | I23: bu | J23: Ψk.Ik.bu | Z23: Code | AA23: Paroi | AE23: Ak | AF23: Uk | AG23: ek | AH23: Ak.Uk.ek
G24: W/(m.K) | H24: m | I24: - | J24: W/K | AE24: m2 | AF24: W/(m²*K) | AG24: - | AH24: W/K
C25: / | AA25: Aucune
B26: Coefficients total de déperditions directe à travers espaces non chauffées (H iue) | Z26: Coefficients total de déperditions directe à travers le sol | AF26: Ht,ig | AI26: =AH9+AI13 -> 55.858903 | AW26: Coefficient total de déperditions vers des espaces chauffés à des températures différentes | BE26: HT,ij
B27: Déperditions directes par le sol | Z27: Déperditions vers des espaces chauffés à des températures différentes | AW27: Coefficient total de déperditions par transmission | BB27: HT,l = Ht,ie+HT,lue+HT,lg+HT,ij W/K | BF27: =BE19 -> 5.4859052
B28: Code | C28: Paroi | G28: Ak | H28: Uk | I28: ek | J28: Ak.Uk.ek | AW28: Données de température de base
G29: m2 | H29: W/(m²*K) | I29: - | J29: W/K | AW29: Température extérieure de base | BC29: θe | BD29: °C | BE29: =32 -> 32
Z30: Code | AA30: Paroi | AE30: fij | AF30: Ak | AG30: Uk | AH30: fij.Ak.Uk | AW30: Température intérieure de base | BC30: θint,l | BD30: °C | BE30: 24
B31: Coefficients total de déperditions directe à travers le sol | H31: Ht,ig | AE31: - | AF31: m2 | AG31: W/(m²*K) | AH31: W/K
B32: Déperditions vers des espaces chauffés à des températures différentes | AA32: Sol | AE32: =ABS(($AH$39-AF45)/$AH$40) -> 0.35714286 | AF32: =4.505*8.04 -> 36.2202 | AG32: =Parois!L49 -> 0.3993743 | AH32: =AE32*AF32*AG32 -> 5.1662204 | BG32: [W]
B33: Code | C33: Paroi | G33: fij | H33: Ak | I33: Uk | J33: fij.Ak.Uk | AA33: Couloir | AE33: =ABS(($AH$39-AF46)/$AH$40) -> 0.071428571 | AF33: =3.075*3.945 -> 12.130875 | AG33: =Parois!L42 -> 1.8115854 | AH33: =AE33*AF33*AG33 -> 1.5697226 | AW33: Ecart de température de base | BC33: θint,l - θe | BD33: °C | BE33: =BE29-BE30 -> 8
G34: - | H34: m2 | I34: W/(m²*K) | J34: W/K | AA34: porte vers couloir | AE34: =ABS(($AH$39-AF46)/$AH$40) -> 0.071428571 | AF34: =0.81*2.03 -> 1.6443 | AG34: =2.5 -> 2.5 | AH34: =AE34*AF34*AG34 -> 0.293625 | AW34: Déperditions de base par transmission avec l'extérieur 𝚽T,i=HT,i.(θint,i-θe) | BF34: =BE33*#REF! -> #REF!
B35: c | C35: couloir | G35: =G37 -> 0.13333333 | H35: =(3.87+0.075+0.005)*3.94 -> 15.563 | I35: =Parois!L42 -> 1.8115854 | J35: =G35*H35*I35 -> 3.7591604 | Z35: Coefficient total de déperditions vers des espaces chauffés à des températures différentes | AH35: HT,ij | AI35: =AH32+AH33+AH34 -> 7.0295679 | AW35: Données de température de pièces adjacentes
B36: b | C36: bureau | G36: =(22-22)/(22--8) -> 0 | H36: =5.01*3.94 -> 19.7394 | I36: =Parois!L42 -> 1.8115854 | J36: =G36*H36*I36 -> 0 | Z36: Coefficient total de déperditions par transmission | AE36: HT,l = Ht,ie+HT,lue+HT,lg+HT,ij W/K | AW36: Nom de pièce | BC36: T hiver | BD36: T été | BE36: ΔT hiver | BF36: ΔT été
B37: c | C37: porte | G37: =(22-18)/(22--8) -> 0.13333333 | H37: =1.64 -> 1.64 | I37: =Parois!L72 -> 2.5 | J37: =G37*H37*I37 -> 0.54666667 | Z37: Données de température | AW37: sol | BC37: / | BD37: 20 | BE37: / | BF37: =BE29-BD37 -> 12
B38: Coefficient total de déperditions vers des espaces chauffés à des températures différentes | J38: =J35+J36+J37 -> 4.3058271 | Z38: Température extérieure de base | AF38: θe | AG38: °C | AH38: -8 | AW38: couloir | BC38: / | BD38: 25 | BE38: / | BF38: =BE29-BD38 -> 7
B39: Coefficient total de déperditions par transmission | G39: HT,l = Ht,ie+HT,lue+HT,lg+HT,ij W/K | K39: =K13+J22+J38 -> 27.766034 | Z39: Température intérieure de base | AF39: θint,l | AG39: °C | AH39: 20 | BC39: / | BD39: 0 | BE39: / | BF39: =BE29-BD39 -> 32
B40: Données de température | Z40: Ecart de température de base | AF40: θint,l - θe | AG40: °C | AH40: =AH39-AH38 -> 28 | BC40: / | BD40: 0 | BE40: / | BF40: =BE29-BD40 -> 32 | BG40: [W]
...

Sheet Couloir (1)
B2: Couloir gauche | C2: Déperdition vers l'exterieur
A3: VOIR SALLE DATTENTE | C3: Code | D3: Paroi | H3: Ak | I3: Uk | J3: ek | K3: Ak.Uk.ek | R3: Couloir droite | S3: Déperdition vers l'exterieur
H4: m2 | I4: W/(m²*K) | J4: - | K4: W/K | R4: By Anis | S4: Code | T4: Paroi | X4: Ak | Y4: Uk | Z4: ek | AA4: Ak.Uk.ek
D5: Aucune | K5: 0 | X5: m2 | Y5: W/(m²*K) | Z5: - | AA5: W/K
C6: Total des parois ΣkAk.Uk.ek W/K | K6: =K5 -> 0 | T6: Aucune | AA6: 0
C7: Code | D7: Ponts thermiques | H7: Ψk | I7: lk | J7: ek | K7: Ψk.Ik.Ek | S7: Total des parois ΣkAk.Uk.ek W/K | AA7: =AA6 -> 0
H8: W/(m.K) | I8: m | J8: - | K8: W/K | S8: Code | T8: Ponts thermiques | X8: Ψk | Y8: lk | Z8: ek | AA8: Ψk.Ik.Ek
D9: / | X9: W/(m.K) | Y9: m | Z9: - | AA9: W/K
C10: Total des ponts thermiques ΣkΨk.lk.ek W/K | K10: =0 -> 0 | T10: /
C11: Coefficients total de déperditions directe vers l'extérieur | I11: HT,ie | L11: =K6+K10 -> 0 | M11: [W/K] | S11: Total des ponts thermiques ΣkΨk.lk.ek W/K | AA11: =0 -> 0
C12: Déperdition à travers espaces non-chauffés | S12: Coefficients total de déperditions directe vers l'extérieur | Y12: HT,ie | AB12: =AA7+AA11 -> 0 | AC12: [W/K]
C13: Code | D13: Paroi | H13: Ak | I13: Uk | J13: bu | K13: Ak.Uk.bu | S13: Déperdition à travers espaces non-chauffés
H14: m2 | I14: W/(m²*K) | J14: - | K14: W/K | S14: Code | T14: Paroi | X14: Ak | Y14: Uk | Z14: bu | AA14: Ak.Uk.bu
C15: N | D15: Paroi intérieur rouge | H15: =3.85*3.6 -> 13.86 | I15: =Parois!L28 -> 2.6423919 | J15: =(Données!G51-Données!G46)/(Données!G51-Données!G11) -> 0.076923077 | K15: =PRODUCT(H15:J15) -> 2.8171963 | X15: m2 | Y15: W/(m²*K) | Z15: - | AA15: W/K
C16: N-O | D16: Paroi coffre-fort | H16: =(2.975*3.6)+(5.4*3.6) -> 30.15 | I16: =Parois!L35 -> 1.7703178 | J16: =(Données!#REF!-Données!G35)/(Données!#REF!-Données!G11) -> #REF! | K16: =PRODUCT(H16:J16) -> #REF! | T16: Paroi escalier | X16: =3.8*3.945 -> 14.991 | Y16: =Parois!L28 -> 2.6423919 | Z16: =($AA$48-Y55)/$AA$49 -> 0.076923077 | AA16: =PRODUCT(X16:Z16) -> 3.0470844
C17: S-O | D17: Paroi intérieur rouge | H17: =((3.175+2.125+1.725+1.73)*3.6)-(0.81*2.03) -> 29.8737 | I17: =Parois!L28 -> 2.6423919 | J17: 1 | T17: Paroi coffre-fort | X17: =31.185-X21 -> 29.185 | Y17: =Parois!L35 -> 1.7703178 | Z17: =(($AA$48-Y59)/$AA$49) -> 0.076923077 | AA17: =PRODUCT(X17:Z17) -> 3.9743634
C18: O | D18: Porte | H18: =0.81*2.03 -> 1.6443 | I18: 2.5 | J18: 1 | T18: Paroi trémis | X18: =7*3.945 -> 27.615 | Y18: =Parois!L65 -> 2.9148685 | Z18: =(($AA$48-Y58)/($AA$49)) -> 0.30769231 | AA18: =PRODUCT(X18:Z18) -> 24.767413
C19: Total des parois ΣkAk.Uk.ek W/K | K19: =SUM(K15:K18) -> #REF! | T19: Paroi approv | X19: =(4.14+2.075)*3.945 -> 24.518175 | Y19: =Parois!L28 -> 2.6423919 | Z19: =(($AA$48-Y57)/$AA$49) -> 0 | AA19: =PRODUCT(X19:Z19) -> 0
C20: Code | D20: Ponts thermiques | H20: Ψk | I20: lk | J20: bu | K20: Ψk.Ik.bu | T20: Porte escalier | X20: =0.81*2.03 -> 1.6443 | Y20: =2.5 -> 2.5 | Z20: =Z16 -> 0.076923077 | AA20: =PRODUCT(X20:Z20) -> 0.31621154
H21: W/(m.K) | I21: m | J21: - | K21: W/K | T21: Porte coffre fort | X21: =2*1 -> 2 | Y21: =5.5 -> 5.5 | Z21: =($AA$48-Y59)/$AA$49 -> 0.076923077 | AA21: =PRODUCT(X21:Z21) -> 0.84615385
D22: /
C23: Total des ponts thermiques ΣkΨk.lk.ek W/K | K23: 0 | S23: Total des parois ΣkAk.Uk.ek W/K | AA23: =SUM(AA16:AA21) -> 32.951226
C24: Coefficients total de déperditions directe à travers des espaces non chauffées | K24: Hₜ,ᵢᵤₑ | L24: =K19+K22 -> #REF! | M24: [W/K] | S24: Code | T24: Ponts thermiques | X24: Ψk | Y24: lk | Z24: bu | AA24: Ψk.Ik.bu
C25: Déperditions directes par le sol | X25: W/(m.K) | Y25: m | Z25: - | AA25: W/K
C26: Code | D26: Paroi | H26: Ak | I26: Uk | J26: ek | K26: Ak.Uk.ek | T26: /
H27: m2 | I27: W/(m²*K) | J27: - | K27: W/K | S27: Total des ponts thermiques ΣkΨk.lk.ek W/K | AA27: 0
D28: Aucune | S28: Coefficients total de déperditions directe à travers des espaces non chauffées | AA28: Hₜ,ᵢᵤₑ | AB28: =AA23+AA26 -> 32.951226 | AC28: [W/K]
C29: Coefficients total de déperditions directe à travers le sol | I29: Ht,ig | L29: =K28 -> 0 | M29: [W/K] | S29: Déperditions directes par le sol
C30: Déperditions vers des espaces chauffés à des températures différentes | S30: Code | X30: Ak | Y30: Uk | Z30: ek | AA30: Ak.Uk.ek
C31: Code | D31: Paroi | H31: fij | I31: Ak | J31: Uk | K31: fij.Ak.Uk | X31: m2 | Y31: W/(m²*K) | Z31: - | AA31: W/K
H32: - | I32: m2 | J32: W/(m²*K) | K32: W/K | T32: Aucune
C33: O | D33: Paroi blanche | H33: =(K44-I49)/(K44-K43) -> -0.076923077 | I33: =3.6*1.45-0.81-2.03 -> 2.38 | J33: =Parois!L42 -> 1.8115854 | K33: =J33*I33*H33 -> -0.33165948 | S33: Coefficients total de déperditions directe à travers le sol | Y33: Ht,ig | AB33: =AA32 -> 0 | AC33: [W/K]
C34: N-E | D34: Paroi blanche | H34: =(K44-I50)/(K44-K43) -> #REF! | I34: =((1.875+0.875+11.875)*3.6)-4*(0.81*2.03) -> 46.0728 | J34: =Parois!L42 -> 1.8115854 | K34: =J34*I34*H34 -> #REF! | S34: Déperditions vers des espaces chauffés à des températures différentes
C35: N-E | D35: Porte | H35: =(K44-I50)/(K44-K43) -> #REF! | I35: =4*(0.81*2.03) -> 6.5772 | J35: 2.5 | K35: =PRODUCT(H35:J35) -> #REF! | S35: Code | T35: Paroi | X35: fij | Y35: Ak | Z35: Uk | AA35: fij.Ak.Uk
C36: B | D36: Sol | H36: =(K44-I56)/(K44-K43) -> -0.076923077 | I36: =(13.6*2.875)+(1.55*2.125)+(2.975*1.45) -> 46.7075 | J36: =Parois!L49 -> 0.3993743 | K36: =PRODUCT(H36:J36) -> -1.4349058 | X36: - | Y36: m2 | Z36: W/(m²*K) | AA36: W/K
C37: S | D37: Paroi blanche | H37: =(K44-I49)/(K44-K43) -> -0.076923077 | I37: =(2.875*3.6)-(2.03*0.81) -> 8.7057 | J37: =Parois!L42 -> 1.8115854 | K37: =PRODUCT(H37:J37) -> -1.213163 | S37: O | T37: Paroi blanche | X37: =(AA48-Y53)/(AA48-AA47) -> -0.076923077 | Y37: =3.6*1.45-0.81-2.03 -> 2.38 | Z37: =J33 -> 1.8115854 | AA37: =Z37*Y37*X37 -> -0.33165948
C38: O | D38: Porte | H38: =(K44-I52)/(K44-K43) -> -0.076923077 | I38: =(0.81*2.03) -> 1.6443 | J38: 2.5 | K38: =PRODUCT(H38:J38) -> -0.31621154 | S38: N-E | T38: Paroi blanche | X38: =(AA48-Y54)/(AA48-AA47) -> -0.15384615 | Y38: =((1.875+0.875+11.875)*3.6)-4*(0.81*2.03) -> 46.0728 | Z38: =J34 -> 1.8115854 | AA38: =Z38*Y38*X38 -> -12.84074
C39: O | D39: Paroi intérieur rouge | H39: =(K44-I52)/(K44-K43) -> -0.076923077 | I39: =(1.55*3.6)-(0.81*2.03) -> 3.9357 | J39: =Parois!L28 -> 2.6423919 | K39: =PRODUCT(H39:J39) -> -0.79997399 | S39: N-E | T39: Porte | X39: =(AA48-Y54)/(AA48-AA47) -> -0.15384615 | Y39: =4*(0.81*2.03) -> 6.5772 | Z39: =J35 -> 2.5 | AA39: =PRODUCT(X39:Z39) -> -2.5296923
C40: Coefficient total de déperditions vers des espaces chauffés à des températures différentes | K40: HT,ij | L40: =SUM(K33:K39) -> #REF! | M40: [W/K] | S40: B | T40: Sol | X40: =ABS(($AA$48-Y60)/$AA$49) -> 0.30769231 | Y40: =49.0625 -> 49.0625 | Z40: =Parois!L49 -> 0.3993743 | AA40: =PRODUCT(X40:Z40) -> 6.0290159
C41: Coefficient total de déperditions par transmission | H41: HT,l = Ht,ie+HT,iue+HT,lg+HT,ij W/K | L41: =L40+L29+L24+L11 -> #REF! | M41: [W/K] | S41: S | T41: Paroi blanche | X41: =(AA48-Y53)/(AA48-AA47) -> -0.076923077 | Y41: =(2.875*3.6)-(2.03*0.81) -> 8.7057 | Z41: =J37 -> 1.8115854 | AA41: =PRODUCT(X41:Z41) -> -1.213163
...

Sheet Salle d'attente (1)
B2: Salle d'attente 17 | C2: Déperdition vers l'exterieur
B3: BY Sabir | C3: Code | D3: Paroi | H3: Ak | I3: Uk | J3: ek | K3: Ak.Uk.ek
H4: m2 | I4: W/(m²*K) | J4: - | K4: W/K
D5: Aucune
C6: Total des parois ΣkAk.Uk.ek W/K | K6: =K5 -> 0
C7: Code | D7: Ponts thermiques | H7: Ψk | I7: lk | J7: ek | K7: Ψk.Ik.Ek
H8: W/(m.K) | I8: m | J8: - | K8: W/K
D9: /
C10: Total des ponts thermiques ΣkΨk.lk.ek W/K | K10: =0 -> 0
C11: Coefficients total de déperditions directe vers l'extérieur | I11: HT,ie | L11: =K6+K10 -> 0 | M11: [W/K]
C12: Déperdition à travers espaces non-chauffés
C13: Code | D13: Paroi | H13: Ak | I13: Uk | J13: bu | K13: Ak.Uk.bu
H14: m2 | I14: W/(m²*K) | J14: - | K14: W/K
C15: N-O | D15: Paroi blanche WC | H15: =((2.3+2+1.5)*3.945)-((0.81*2.03))-(1.01*2.03) -> 19.1864 | I15: =Parois!L42 -> 1.8115854 | J15: =(K46-I58)/K47 -> 0.14285714 | K15: =PRODUCT(H15:J15) -> 4.9654002
C17: E | D17: Paroi coffre-fort | H17: =(10)*3.945 -> 39.45 | I17: =Parois!L35 -> 1.7703178 | J17: =(Données!E25-Données!G35)/(Données!E25-Données!G11) -> 0.27607143 | K17: =PRODUCT(H17:J17) -> 19.280563
C18: N-O | D18: Porte | H18: =((0.81*2.03))+(1.01*2.03) -> 3.6946 | I18: 2.5 | J18: =J15 -> 0.14285714 | K18: =PRODUCT(H18:J18) -> 1.3195
C20: Total des parois ΣkAk.Uk.ek W/K | K20: =SUM(K15:K18) -> 25.565463
C21: Code | D21: Ponts thermiques | H21: Ψk | I21: lk | J21: bu | K21: Ψk.Ik.bu
H22: W/(m.K) | I22: m | J22: - | K22: W/K
D23: /
C24: Total des ponts thermiques ΣkΨk.lk.ek W/K | K24: 0
C25: Coefficients total de déperditions directe à travers des espaces non chauffées | K25: Hₜ,ᵢᵤₑ | L25: =K20+K23 -> 25.565463 | M25: [W/K]
C26: Déperditions directes par le sol
C27: Code | D27: Paroi | H27: Ak | I27: Uk | J27: ek | K27: Ak.Uk.ek
H28: m2 | I28: W/(m²*K) | J28: - | K28: W/K
D29: Aucune
C30: Coefficients total de déperditions directe à travers le sol | I30: Ht,ig | L30: =K29 -> 0 | M30: [W/K]
C31: Déperditions vers des espaces chauffés à des températures différentes
C32: Code | D32: Paroi | H32: fij | I32: Ak | J32: Uk | K32: fij.Ak.Uk
H33: - | I33: m2 | J33: W/(m²*K) | K33: W/K
D34: Paroi interieur rouge bornes | H34: =(20-18)/K47 -> 0.071428571 | I34: =(2.275+5.575)*3.78 -> 29.673 | J34: =Parois!L28 -> 2.6423919 | K34: =PRODUCT(H34:J34) -> 5.6005497
C35: S | D35: Vitre | H35: =(K46-I52)/(K46-K45) -> -0.071428571 | I35: =4*(SUM(Parois!AB25:AC25)) -> 5.121 | J35: =Parois!AE25 -> 1.8029885 | K35: =J35*I35*H35 -> -0.65950743 | O35: S | P35: Paroi blanche SDR | T35: =(K46-I52)/(K46-K45) -> -0.071428571 | U35: =3.6*12.395-(0.81*2.03) -> 42.9777 | V35: =Parois!L42 -> 1.8115854 | W35: =V35*U35*T35 -> -5.5612695
D36: Paroi blanche SECRETARIAT | I36: =2.4*3.78-I35 -> 3.951 | J36: =Parois!L42 -> 1.8115854
D37: Paroi rouge trappes | H37: =(20-16)/K47 -> 0.14285714 | I37: =(1.05*3.675)*3.78 -> 14.586075 | J37: =Parois!L65 -> 2.9148685 | K37: =PRODUCT(H37:J37) -> 6.0737843
C38: S-E | D38: Paroi intérieur rouge couloir anis | H38: =(20-18)/K47 -> 0.071428571 | I38: =(1.85*3.78)-(0.81*2.03) -> 5.3487 | J38: =Parois!L28 -> 2.6423919 | K38: =PRODUCT(H38:J38) -> 1.0095258
D39: Paroi interieur blanche toilette homme | H39: =(20-16)/K47 -> 0.14285714 | I39: =(1.645+2.05)*3.78-((0.81*2.03)*2) -> 10.6785 | J39: =Parois!L42 -> 1.8115854 | K39: =PRODUCT(H39:J39) -> 2.7635735
D40: sol | H40: =10/K47 -> 0.35714286 | I40: =2.275*2.4+3.75*2.7+4.725*2.2+5.3*4.8+1.7*0.975+1.495*1.45+1.45*2.725+1.595*2.05 -> 62.46625 | J40: =Parois!L49 -> 0.3993743 | K40: =H40*I40*J40 -> 8.909791
C42: Coefficient total de déperditions vers des espaces chauffés à des températures différentes | K42: HT,ij | L42: =SUM(K34:K41)-K35 -> 24.357224 | M42: [W/K]
C43: Coefficient total de déperditions par transmission | H43: HT,l = Ht,ie+HT,iue+HT,lg+HT,ij W/K | L43: =L42+L30+L25+L11 -> 49.922687 | M43: [W/K]
C44: Données de température
...

Sheet SDR (3)
B3: Bureau 4
B4: by BEN | C4: Déperdition vers l'exterieur
C5: Code | D5: Paroi | H5: Ak | I5: Uk | J5: ek | K5: Ak.Uk.ek
H6: m2 | I6: W/(m²*K) | J6: - | K6: W/K | Y6: SDR 16
C7: a | D7: Mur | H7: =7.115*3.94 -> 28.0331 | I7: =Parois!L13 -> 0.31196949 | J7: 1 | K7: =H7*I7*J7 -> 8.7454718 | Y7: by Sabir | Z7: Déperdition vers l'exterieur
C8: b | D8: Mur | H8: =4.915*3.78-Parois!AB9-Parois!AC9 -> 15.2262 | I8: =Parois!L13 -> 0.31196949 | J8: 1 | K8: =H8*I8*J8 -> 4.7501098 | Z8: Code | AA8: Paroi | AE8: Ak | AF8: Uk | AG8: ek | AH8: Ak.Uk.ek | AX8: kitchenette BEN | AY8: Kitchen
C9: F | D9: fenetre | H9: =Parois!AB9+Parois!AC9 -> 3.3525 | I9: =Parois!AG9 -> 1.4056725 | J9: 1 | K9: =H9*I9*J9 -> 4.7125171 | N9: =Parois!AB9+Parois!AC9 -> 3.3525 | AE9: m2 | AF9: W/(m²*K) | AG9: - | AH9: W/K | AZ9: Déperdition vers l'exterieur
K10: =H10*I10*J10 -> 0 | Z10: O | AA10: Mur | AG10: 1 | AZ10: Code | BA10: Paroi | BE10: Ak | BF10: Uk | BG10: ek | BH10: Ak.Uk.ek
K11: =K7+K9+K10+K8 -> 18.208099 | AA11: Plafond | AE11: =Données!G29 -> 32.175 | AF11: =Parois!L59 -> 0.14630088 | AG11: 1 | BE11: m2 | BF11: W/(m²*K) | BG11: - | BH11: W/K
C12: Code | D12: Ponts thermiques | H12: Ψk | I12: lk | J12: ek | K12: Ψk.Ik.Ek | AG12: 1 | AH12: =AE12*AF12*AG12 -> 0 | AZ12: a | BA12: Mur | BE12: =4.65*3.78--Parois!AB15-Parois!AC15 -> 19.5132 | BF12: =Parois!L13 -> 0.31196949 | BG12: 1 | BH12: =BE12*BF12*BG12 -> 6.087523
