Workbook

Sheet Damètre conduites
B3: Information
B4: ρeau | C4: 1000 | D4: [kg/m3]
B5: ∆T | C5: 20 | D5: [°C]
B6: Cp eau | C6: 4186 | D6: [J/kg.K]
B7: Vmax collecteur | C7: 0.5 | D7: [m/s]
B8: Vmax consommateur | C8: 1 | D8: [m/s]
B9: Régime | C9: 70/50 | D9: °C
B10: DN>32
B11: Pdc max | C11: 150 | D11: [Pa/m]
B12: DN < 32
B13: Pdc max | C13: 100 | D13: [Pa/m]
B21: Circuit Froid -Retour
B22: Circuit Chaud -Départ
C23: Puissance [kw] | D23: Débits [kg/s] | E23: Débits [m³/s] | F23: Section [m²] | G23: D calculé[mm] | H23: DN abaques | I23: Section corrigé | J23: Débits [kg/h] | K23: PDC [Pa/m] | L23: v réelle [m/s]
B24: Chaudière 1 | C24: =0.39*600 -> 234 | D24: =C24/'Damètre conduites'!$C$6/'Damètre conduites'!$C$5*1000 -> 2.7950311 | E24: =D24/'Damètre conduites'!$C$4 -> 0.0027950311 | F24: =E24/'Damètre conduites'!$C$8 -> 0.0027950311 | G24: =SQRT((4*F24)/PI())*10^3 -> 59.65521 | H24: 65 | I24: =PI()*(H24/1000)^2/4 -> 0.0033183072 | J24: =D24*3600 -> 10062.112 | K24: 80 | L24: =J24/3600/'Damètre conduites'!$C$4/I24 -> 0.84230629
B25: Chaudière 2 | C25: =0.39*600 -> 234 | D25: =C25/'Damètre conduites'!$C$6/'Damètre conduites'!$C$5*1000 -> 2.7950311 | E25: =D25/'Damètre conduites'!$C$4 -> 0.0027950311 | F25: =E25/'Damètre conduites'!$C$8 -> 0.0027950311 | G25: =SQRT((4*F25)/PI())*10^3 -> 59.65521 | H25: 65 | I25: =PI()*(H25/1000)^2/4 -> 0.0033183072 | J25: =D25*3600 -> 10062.112 | K25: 80 | L25: =J25/3600/'Damètre conduites'!$C$4/I25 -> 0.84230629
B26: Chaudière 3 | C26: =0.39*600 -> 234 | D26: =C26/'Damètre conduites'!$C$6/'Damètre conduites'!$C$5*1000 -> 2.7950311 | E26: =D26/'Damètre conduites'!$C$4 -> 0.0027950311 | F26: =E26/'Damètre conduites'!$C$8 -> 0.0027950311 | G26: =SQRT((4*F26)/PI())*10^3 -> 59.65521 | H26: 65 | I26: =PI()*(H26/1000)^2/4 -> 0.0033183072 | J26: =D26*3600 -> 10062.112 | K26: 80 | L26: =J26/3600/'Damètre conduites'!$C$4/I26 -> 0.84230629
B27: Préchauffe | C27: 129.97983 | D27: =C27/'Damètre conduites'!$C$6/'Damètre conduites'!$C$5*1000 -> 1.5525541 | E27: =D27/'Damètre conduites'!$C$4 -> 0.0015525541 | F27: =E27/'Damètre conduites'!$C$8 -> 0.0015525541 | G27: =SQRT((4*F27)/PI())*10^3 -> 44.460918 | H27: 50 | I27: =PI()*(H27/1000)^2/4 -> 0.0019634954 | J27: =D27*3600 -> 5589.1947 | K27: 110 | L27: =J27/3600/'Damètre conduites'!$C$4/I27 -> 0.7907093
B28: Postchauffe | C28: 67.97 | D28: =C28/'Damètre conduites'!$C$6/'Damètre conduites'!$C$5*1000 -> 0.81187291 | E28: =D28/'Damètre conduites'!$C$4 -> 0.00081187291 | F28: =E28/'Damètre conduites'!$C$8 -> 0.00081187291 | G28: =SQRT((4*F28)/PI())*10^3 -> 32.15134 | H28: 40 | I28: =PI()*(H28/1000)^2/4 -> 0.0012566371 | J28: =D28*3600 -> 2922.7425 | K28: 105 | L28: =J28/3600/'Damètre conduites'!$C$4/I28 -> 0.64606793
B29: Départ 1 | C29: =(600-C27-C28)/2 -> 201.02509 | D29: =C29/'Damètre conduites'!$C$6/'Damètre conduites'!$C$5*1000 -> 2.4011597 | E29: =D29/'Damètre conduites'!$C$4 -> 0.0024011597 | F29: =E29/'Damètre conduites'!$C$8 -> 0.0024011597 | G29: =SQRT((4*F29)/PI())*10^3 -> 55.292417 | H29: 65 | I29: =PI()*(H29/1000)^2/4 -> 0.0033183072 | J29: =D29*3600 -> 8644.1748 | K29: 58 | L29: =J29/3600/'Damètre conduites'!$C$4/I29 -> 0.72360981
B30: Départ 2 | C30: =(600-C27-C28)/2 -> 201.02509 | D30: =C30/'Damètre conduites'!$C$6/'Damètre conduites'!$C$5*1000 -> 2.4011597 | E30: =D30/'Damètre conduites'!$C$4 -> 0.0024011597 | F30: =E30/'Damètre conduites'!$C$8 -> 0.0024011597 | G30: =SQRT((4*F30)/PI())*10^3 -> 55.292417 | H30: 65 | I30: =PI()*(H30/1000)^2/4 -> 0.0033183072 | J30: =D30*3600 -> 8644.1748 | K30: 58 | L30: =J30/3600/'Damètre conduites'!$C$4/I30 -> 0.72360981
B31: Collecteur | C31: =SUM(C27:C30) -> 600 | D31: =C31/'Damètre conduites'!$C$6/'Damètre conduites'!$C$5*1000 -> 7.1667463 | E31: =D31/'Damètre conduites'!$C$4 -> 0.0071667463 | F31: =E31/'Damètre conduites'!$C$7 -> 0.014333493 | G31: =SQRT((4*F31)/PI())*10^3 -> 135.09245 | H31: 150 | I31: =PI()*(H31/1000)^2/4 -> 0.017671459 | J31: =D31*3600 -> 25800.287 | K31: 9 | L31: =J31/3600/'Damètre conduites'!$C$4/I31 -> 0.40555488
B32: Eau de ville | H32: 25 | I32: =PI()*(H32/1000)^2/4 -> 0.00049087385
B33: Entre chaudière 2 et 3
J56: =2*H27+2*H28+2*H29+2*H30 -> 440
J58: couloir 1400
J60: donc avec isolant on est large pour tout faire passer dans le couloir

Sheet Choix des organes
B29: Choix des chaudières
C30: Régime 70/50[kW] | D30: Régime 70/50[kW] | E30: ΔPdC[bar] | F30: Type | H30: Volume [L]
B31: Chaudière n°1 | C31: ='Damètre conduites'!C24 -> 234 | D31: =R33 -> 293.66667 | E31: =6*10^-3 -> 0.006 | F31: Vitocrossal 200;294kW; CM2 | H31: 279
B32: Chaudière n°2 | C32: ='Damètre conduites'!C25 -> 234 | D32: =D31 -> 293.66667 | E32: =6*10^-3 -> 0.006 | F32: Vitocrossal 200;294kW; CM2 | H32: 279
B33: Chaudière n°3 | C33: ='Damètre conduites'!C26 -> 234 | D33: =D31 -> 293.66667 | E33: =6*10^-3 -> 0.006 | F33: Vitocrossal 200; 294kW; CM2 | H33: 279 | N33: INTERPOLATION POUR TROUVER LA PUISSANCE EN 70/50; HYPOTHESE QUE LA TEMPERATURE DES FUMEES EST DE 150°C | R33: =285+((150-60-(150-70))/(150-40-(150-70)))*(311-285) -> 293.66667
H34: =SUM(H31:H33) -> 837
C49: page 46 tableau du haut et 48 du mt 31
L50: page 46 tableau du bas et 48 du mt 31
B51: Vanne d'isolement manuelle | K51: Vanne d'isolement motorisée
B52: n° | C52: Q [m3/h] | D52: DN [mm] | E52: v réelle [m/s] | F52: ΔPdC[bar] | G52: Nom | K52: n° | L52: Q [m3/h] | M52: DN [mm] | N52: v réelle [m/s] | O52: ΔPdC[bar] | P52: Nom
B53: 1 | C53: ='Damètre conduites'!J24/1000 -> 10.062112 | D53: 65 | E53: 0.84314944 | F53: 0.0025 | G53: JIP-FF PN 16 065N4282 | K53: 1 | L53: 10.062112 | M53: 65 | N53: 0.84314944 | O53: 0.0025 | P53: JIP-FF PN 16 065N0232
B54: 2 | C54: =C53 -> 10.062112 | D54: 65 | E54: 0.84314944 | F54: 0.0025 | G54: JIP-FF PN 16 065N4282 | K54: 2 | L54: 10.062112 | M54: 65 | N54: 0.84314944 | O54: 0.0025 | P54: JIP-FF PN 16 065N0232
B55: 3 | C55: =C54 -> 10.062112 | D55: 65 | E55: 0.84314944 | F55: 0.0025 | G55: JIP-FF PN 16 065N4282 | K55: 3 | L55: 10.062112 | M55: 65 | N55: 0.84314944 | O55: 0.0025 | P55: JIP-FF PN 16 065N0232
B56: 4 | C56: ='Damètre conduites'!J31/1000 -> 25.800287 | D56: 150 | E56: ='Damètre conduites'!L31 -> 0.40555488 | F56: 0.00018 | G56: JIP-FF PN 16 065N0850
B57: 5 | C57: =C56 -> 25.800287 | D57: 150 | E57: =E56 -> 0.40555488 | F57: 0.00018 | G57: JIP-FF PN 16 065N0850
B58: 6 | C58: =C56 -> 25.800287 | D58: 150 | E58: =E56 -> 0.40555488 | F58: 0.00018 | G58: JIP-FF PN 16 065N0850
B59: 7 | C59: =C56 -> 25.800287 | D59: 150 | E59: =E56 -> 0.40555488 | F59: 0.00018 | G59: JIP-FF PN 16 065N0850
B60: 8 | C60: =C56 -> 25.800287 | D60: 150 | E60: =E56 -> 0.40555488 | F60: 0.00018 | G60: JIP-FF PN 16 065N0850
B61: 9 | C61: =C56 -> 25.800287 | D61: 150 | E61: =E56 -> 0.40555488 | F61: 0.00018 | G61: JIP-FF PN 16 065N0850
B62: 10 | C62: / | D62: / | E62: / | F62: /
B63: 11 | C63: / | D63: / | E63: / | F63: /
B64: 12 | C64: Vase d'expansion
B65: 13 | C65: ='Damètre conduites'!J27/1000 -> 5.5891947 | D65: 50 | E65: ='Damètre conduites'!L27 -> 0.7907093 | F65: 0.0009 | G65: JIP-FF PN 50 065N0325
B66: 14 | C66: =C65 -> 5.5891947 | D66: 50 | E66: ='Damètre conduites'!L27 -> 0.7907093 | F66: 0.0009 | G66: JIP-FF PN 50 065N0325
B67: 15 | C67: =C65 -> 5.5891947 | D67: 50 | E67: =E65 -> 0.7907093 | F67: 0.0009 | G67: JIP-FF PN 50 065N0325
B68: 16 | C68: ='Damètre conduites'!J28/1000 -> 2.9227425 | D68: 40 | E68: ='Damètre conduites'!L28 -> 0.64606793 | F68: 0.0008 | G68: JIP-FF PN 40 065N0320
B69: 17 | C69: =C68 -> 2.9227425 | D69: 40 | E69: =E68 -> 0.64606793 | F69: 0.0008 | G69: JIP-FF PN 40 065N0320
B70: 18 | C70: =C68 -> 2.9227425 | D70: 40 | E70: =E68 -> 0.64606793 | F70: 0.0008 | G70: JIP-FF PN 40 065N0320

Sheet PDC singuliere-repartie
J1: mettre collecteur coller aux murs
B3: j'ai calculé avec la plus grosse chaudiere | J3: mettres les departs dans la tremie proche des murs et pas au mileu
B4: aw
J5: ne pas passer au dessus de la porte du local hvac
B30: Pertes de charges réparties | I30: Perte de charges singulières (coudes,…) | O30: Pertes de charges singulières organes
B31: Conduit | C31: Longueur [m] | D31: DN | E31: PdC répartie[Pa/m] | F31: ΔPdC [bar] | I31: Nom | J31: 𝛏 | K31: ρ [kg/m^3] | L31: v [m/s] | M31: ΔP [bar] | O31: Types | P31: n° | Q31: ΔPdC[bar] | R31: ΔPdC[Pa]
A32: depart chaudiere-collecteur rouge | B32: AA-BB | C32: =5-1.45 -> 3.55 | D32: ='Damètre conduites'!H24 -> 65 | E32: ='Damètre conduites'!K24 -> 80 | F32: =C32*E32/100000 -> 0.00284 | G32: =C32*'Damètre conduites'!I$24 -> 0.011779991 | H32: depart chaudiere-collecteur rouge | I32: BB | J32: 1.3 | K32: 1000 | L32: ='Damètre conduites'!L24 -> 0.84230629 | M32: =(J32*K32*L32^2)/2/100000 -> 0.0046116192 | O32: Vanne d'isolement manuelle | P32: 1 | Q32: ='Choix des organes'!F53 -> 0.0025 | R32: =Q32*100000 -> 250
B33: CC-DD | C33: =C32 -> 3.55 | D33: =D32 -> 65 | E33: =E32 -> 80 | F33: =C33*E33/100000 -> 0.00284 | G33: =C33*'Damètre conduites'!I$33 -> 0 | I33: DD | J33: 1.5 | K33: 1000 | L33: ='Damètre conduites'!L25 -> 0.84230629 | M33: =(J33*K33*L33^2)/2/100000 -> 0.0053210991 | P33: 2 | Q33: ='Choix des organes'!F54 -> 0.0025 | R33: =Q33*100000 -> 250
B34: EE-FF | C34: =C32 -> 3.55 | D34: =D32 -> 65 | E34: =E32 -> 80 | F34: =C34*E34/100000 -> 0.00284 | G34: =C34*'Damètre conduites'!I$33 -> 0 | I34: FF | J34: 1.5 | K34: 1000 | L34: ='Damètre conduites'!L26 -> 0.84230629 | M34: =(J34*K34*L34^2)/2/100000 -> 0.0053210991 | P34: 3 | Q34: ='Choix des organes'!F55 -> 0.0025 | R34: =Q34*100000 -> 250
B35: BB-DD | C35: =1.3 -> 1.3 | D35: =D32 -> 65 | E35: =E32 -> 80 | F35: =C35*E35/100000 -> 0.00104 | G35: =C35*'Damètre conduites'!I$33 -> 0 | I35: GG | J35: 1.3 | K35: 1000 | L35: ='Damètre conduites'!L31 -> 0.40555488 | M35: =(J35*K35*L35^2)/2/100000 -> 0.0010690859 | P35: 4 | Q35: ='Choix des organes'!F56 -> 0.00018 | R35: =Q35*100000 -> 18
B36: DD-FF | C36: =C35 -> 1.3 | D36: ='Damètre conduites'!H33 -> 0 | E36: ='Damètre conduites'!K33 -> 0 | F36: =C36*E36/100000 -> 0 | G36: =C36*'Damètre conduites'!I$31 -> 0.022972896 | I36: HH | J36: 1.3 | K36: 1000 | L36: =L35 -> 0.40555488 | M36: =(J36*K36*L36^2)/2/100000 -> 0.0010690859 | P36: 5 | Q36: ='Choix des organes'!F57 -> 0.00018 | R36: =Q36*100000 -> 18
B37: FF-GG | C37: 0.5 | D37: ='Damètre conduites'!H31 -> 150 | E37: ='Damètre conduites'!K31 -> 9 | F37: =C37*E37/100000 -> 4.5e-05 | G37: =C37*'Damètre conduites'!I$31 -> 0.0088357293 | I37: II | J37: 1.3 | K37: 1000 | L37: =L36 -> 0.40555488 | M37: =(J37*K37*L37^2)/2/100000 -> 0.0010690859 | P37: 6 | Q37: ='Choix des organes'!F58 -> 0.00018 | R37: =Q37*100000 -> 18
B38: GG-HH | C38: 6 | D38: =D37 -> 150 | E38: =E37 -> 9 | F38: =C38*E38/100000 -> 0.00054 | G38: =C38*'Damètre conduites'!I$31 -> 0.10602875 | I38: JJ | J38: 1.3 | K38: 1000 | L38: =L37 -> 0.40555488 | M38: =(J38*K38*L38^2)/2/100000 -> 0.0010690859 | P38: 7 | Q38: ='Choix des organes'!F59 -> 0.00018 | R38: =Q38*100000 -> 18
B39: HH-II | C39: 0.9 | D39: =D38 -> 150 | E39: =E37 -> 9 | F39: =C39*E39/100000 -> 8.1e-05 | G39: =C39*'Damètre conduites'!I$31 -> 0.015904313 | H39: postchauffe en bleu | I39: KK' | J39: 0.74 | K39: 1000 | L39: =L41 -> 0.64606793 | M39: =(J39*K39*L39^2)/2/100000 -> 0.001544394 | N39: =L41/L38 -> 1.5930469 | P39: 8 | Q39: ='Choix des organes'!F60 -> 0.00018 | R39: =Q39*100000 -> 18
B40: II-JJ | C40: 4.7 | D40: =D39 -> 150 | E40: =E37 -> 9 | F40: =C40*E40/100000 -> 0.000423 | G40: =C40*'Damètre conduites'!I$31 -> 0.083055856 | I40: E | J40: 1.3 | K40: 1000 | L40: =L39 -> 0.64606793 | M40: =(J40*K40*L40^2)/2/100000 -> 0.0027131245 | P40: 9 | Q40: ='Choix des organes'!F61 -> 0.00018 | R40: =Q40*100000 -> 18
B41: JJ-KK | C41: 0.9 | D41: ='Damètre conduites'!H31 -> 150 | E41: ='Damètre conduites'!K31 -> 9 | F41: =C41*E41/100000 -> 8.1e-05 | G41: =C41*'Damètre conduites'!I$31 -> 0.015904313 | I41: F | J41: 1.3 | K41: 1000 | L41: ='Damètre conduites'!L28 -> 0.64606793 | M41: =(J41*K41*L41^2)/2/100000 -> 0.0027131245 | P41: 10 | Q41: / | R41: /
A42: depart chaudiere-collecteur bleu | B42: AA'-BB' | C42: =C32-0.3 -> 3.25 | D42: =D32 -> 65 | E42: =E32 -> 80 | F42: =C42*E42/100000 -> 0.0026 | I42: G | J42: 1.3 | K42: 1000 | L42: =L41 -> 0.64606793 | M42: =(J42*K42*L42^2)/2/100000 -> 0.0027131245 | P42: 11 | Q42: / | R42: /
B43: CC'-DD' | C43: =C42 -> 3.25 | D43: =D33 -> 65 | E43: =E33 -> 80 | F43: =C43*E43/100000 -> 0.0026 | I43: H | J43: 1.3 | K43: 1000 | L43: =L42 -> 0.64606793 | M43: =(J43*K43*L43^2)/2/100000 -> 0.0027131245 | P43: 12 | Q43: / | R43: /
B44: EE'-FF' | C44: =C42 -> 3.25 | D44: =D34 -> 65 | E44: =E34 -> 80 | F44: =C44*E44/100000 -> 0.0026 | I44: I | J44: 1.3 | K44: 1000 | L44: =L43 -> 0.64606793 | M44: =(J44*K44*L44^2)/2/100000 -> 0.0027131245 | P44: 13 | Q44: ='Choix des organes'!F65 -> 0.0009 | R44: =Q44*100000 -> 90
B45: BB'-DD' | C45: =C35 -> 1.3 | D45: =D35 -> 65 | E45: =E35 -> 80 | F45: =C45*E45/100000 -> 0.00104 | I45: J | J45: 1.3 | K45: 1000 | L45: =L44 -> 0.64606793 | M45: =(J45*K45*L45^2)/2/100000 -> 0.0027131245 | P45: 14 | Q45: ='Choix des organes'!F66 -> 0.0009 | R45: =Q45*100000 -> 90
B46: DD'-FF' | C46: =C45 -> 1.3 | D46: =D36 -> 0 | E46: =E36 -> 0 | F46: =C46*E46/100000 -> 0 | I46: K | J46: 1.3 | K46: 1000 | L46: =L45 -> 0.64606793 | M46: =(J46*K46*L46^2)/2/100000 -> 0.0027131245 | P46: 15 | Q46: ='Choix des organes'!F67 -> 0.0009 | R46: =Q46*100000 -> 90
B47: FF'-GG' | C47: =C37+C39-0.3 -> 1.1 | D47: =D37 -> 150 | E47: =E37 -> 9 | F47: =C47*E47/100000 -> 9.9e-05 | I47: L | J47: 1.3 | K47: 1000 | L47: =L46 -> 0.64606793 | M47: =(J47*K47*L47^2)/2/100000 -> 0.0027131245 | P47: 16 | Q47: ='Choix des organes'!F68 -> 0.0008 | R47: =Q47*100000 -> 80
B48: GG'-HH' | C48: =C38-C41-1-1-0.5 -> 2.6 | D48: =D38 -> 150 | E48: =E38 -> 9 | F48: =C48*E48/100000 -> 0.000234 | I48: M | J48: 1.3 | K48: 1000 | L48: =L47 -> 0.64606793 | M48: =(J48*K48*L48^2)/2/100000 -> 0.0027131245 | P48: 17 | Q48: ='Choix des organes'!F69 -> 0.0008 | R48: =Q48*100000 -> 80
B49: HH'-II' | C49: =C40-0.3 -> 4.4 | D49: =D48 -> 150 | E49: =E48 -> 9 | F49: =C49*E49/100000 -> 0.000396 | H49: prechauffe en bleu | I49: MM' | J49: 0.74 | K49: 1000 | L49: =L51 -> 0.7907093 | M49: =(J49*K49*L49^2)/2/100000 -> 0.0023133184 | N49: =L50/L38 -> 1.9496974 | P49: 18 | Q49: ='Choix des organes'!F70 -> 0.0008 | R49: =Q49*100000 -> 80
B50: II'-JJ' | C50: 0.5 | D50: =D49 -> 150 | E50: =E49 -> 9 | F50: =C50*E50/100000 -> 4.5e-05 | I50: E' | J50: 1.3 | K50: =K49 -> 1000 | L50: =L49 -> 0.7907093 | M50: =(J50*K50*L50^2)/2/100000 -> 0.0040639377 | O50: Chaudière | P50: 1 | Q50: ='Choix des organes'!E31 -> 0.006 | R50: =Q50*100000 -> 600
A51: postchauffe en rouge | B51: QQ-O | C51: =C69 -> 4.7 | D51: =D52 -> 40 | E51: =E52 -> 105 | F51: =C51*E51/100000 -> 0.004935 | G51: =+'Damètre conduites'!I$28 -> 0.0012566371 | I51: F' | J51: 1.3 | K51: 1000 | L51: ='Damètre conduites'!L27 -> 0.7907093 | M51: =(J51*K51*L51^2)/2/100000 -> 0.0040639377 | P51: 2 | Q51: ='Choix des organes'!E32 -> 0.006 | R51: =Q51*100000 -> 600
B52: O-P | C52: =C107-0.1 -> 5.5 | D52: ='Damètre conduites'!$H$28 -> 40 | E52: ='Damètre conduites'!$K$28 -> 105 | F52: =C52*E52/100000 -> 0.005775 | G52: =+'Damètre conduites'!I$28 -> 0.0012566371 | I52: G' | J52: 1.3 | K52: 1000 | L52: 0.791 | M52: =(J52*K52*L52^2)/2/100000 -> 0.0040669265 | P52: 3 | Q52: ='Choix des organes'!E33 -> 0.006 | R52: =Q52*100000 -> 600
B53: P-Q | C53: 8.8 | D53: ='Damètre conduites'!$H$28 -> 40 | E53: ='Damètre conduites'!$K$28 -> 105 | F53: =C53*E53/100000 -> 0.00924 | G53: =+'Damètre conduites'!I$28 -> 0.0012566371 | I53: H' | J53: 1.3 | K53: 1000 | L53: 0.791 | M53: =(J53*K53*L53^2)/2/100000 -> 0.0040669265 | O53: Vanne d'isolement motorisée | P53: 1 | Q53: ='Choix des organes'!O53 -> 0.0025 | R53: =Q53*100000 -> 250
B54: Q-R | C54: 3.2 | D54: ='Damètre conduites'!$H$28 -> 40 | E54: ='Damètre conduites'!$K$28 -> 105 | F54: =C54*E54/100000 -> 0.00336 | G54: =+'Damètre conduites'!I$28 -> 0.0012566371 | I54: I' | J54: 1.3 | K54: 1000 | L54: 0.791 | M54: =(J54*K54*L54^2)/2/100000 -> 0.0040669265 | P54: 2 | Q54: ='Choix des organes'!O54 -> 0.0025 | R54: =Q54*100000 -> 250
B55: R-S | C55: =C64 -> 0.9 | D55: ='Damètre conduites'!$H$28 -> 40 | E55: ='Damètre conduites'!$K$28 -> 105 | F55: =C55*E55/100000 -> 0.000945 | G55: =+'Damètre conduites'!I$28 -> 0.0012566371 | I55: KK | J55: 1.5 | K55: 1000 | L55: 0.791 | M55: =(J55*K55*L55^2)/2/100000 -> 0.0046926075 | P55: 3 | Q55: ='Choix des organes'!O55 -> 0.0025 | R55: =Q55*100000 -> 250
B56: S-T | C56: =C65+0.3 -> 0.9 | D56: ='Damètre conduites'!$H$28 -> 40 | E56: ='Damètre conduites'!$K$28 -> 105 | F56: =C56*E56/100000 -> 0.000945 | G56: =+'Damètre conduites'!I$28 -> 0.0012566371 | I56: J' | J56: 1.3 | K56: 1000 | L56: 0.791 | M56: =(J56*K56*L56^2)/2/100000 -> 0.0040669265 | O56: Préchauffe | P56: 1 | Q56: =R56/100000 -> 0.0008 | R56: 80
B57: T-U | C57: 2.5 | D57: ='Damètre conduites'!$H$28 -> 40 | E57: ='Damètre conduites'!$K$28 -> 105 | F57: =C57*E57/100000 -> 0.002625 | G57: =+'Damètre conduites'!I$28 -> 0.0012566371 | I57: K' | J57: 1.3 | K57: 1000 | L57: 0.791 | M57: =(J57*K57*L57^2)/2/100000 -> 0.0040669265 | O57: Postchauffe | P57: 1 | Q57: =R57/100000 -> 0.00074 | R57: 74
B58: U-V | C58: =C67-0.1 -> 4.2 | D58: ='Damètre conduites'!$H$28 -> 40 | E58: ='Damètre conduites'!$K$28 -> 105 | F58: =C58*E58/100000 -> 0.00441 | G58: =+'Damètre conduites'!I$28 -> 0.0012566371 | H58: postchauffe en rouge | I58: QQ | J58: 0.74 | K58: 1000 | L58: ='Damètre conduites'!L31 -> 0.40555488 | M58: =(J58*K58*L58^2)/2/100000 -> 0.00060855661 | N58: =L59/L38 -> 1.5930469 | O58: Total | R58: =SUM(R32:R57) -> 4072
B59: V-W | C59: =5.09-0.6 -> 4.49 | D59: ='Damètre conduites'!$H$28 -> 40 | E59: ='Damètre conduites'!$K$28 -> 105 | F59: =C59*E59/100000 -> 0.0047145 | G59: =+'Damètre conduites'!I$28 -> 0.0012566371 | I59: O | J59: =1.3 -> 1.3 | K59: 1000 | L59: ='Damètre conduites'!L28 -> 0.64606793 | M59: =(J59*K59*L59^2)/2/100000 -> 0.0027131245
A60: postchauffe en bleu | B60: KK'-E | C60: =C69 -> 4.7 | D60: =D58 -> 40 | E60: =E58 -> 105 | F60: =C60*E60/100000 -> 0.004935 | I60: P | J60: 1.3 | K60: 1000 | L60: =0.646 -> 0.646 | M60: =(J60*K60*L60^2)/2/100000 -> 0.002712554
B61: E-F | C61: =C101-0.1 -> 5.9 | D61: ='Damètre conduites'!$H$28 -> 40 | E61: ='Damètre conduites'!$K$28 -> 105 | F61: =C61*E61/100000 -> 0.006195 | I61: Q | J61: 1.3 | K61: 1000 | L61: =0.646 -> 0.646 | M61: =(J61*K61*L61^2)/2/100000 -> 0.002712554
B62: F-G | C62: 10.5 | D62: ='Damètre conduites'!$H$28 -> 40 | E62: ='Damètre conduites'!$K$28 -> 105 | F62: =C62*E62/100000 -> 0.011025 | I62: R | J62: 1.3 | K62: 1000 | L62: =0.646 -> 0.646 | M62: =(J62*K62*L62^2)/2/100000 -> 0.002712554
B63: G-H | C63: =C54 -> 3.2 | D63: ='Damètre conduites'!$H$28 -> 40 | E63: ='Damètre conduites'!$K$28 -> 105 | F63: =C63*E63/100000 -> 0.00336 | I63: S | J63: 1.3 | K63: 1000 | L63: =0.646 -> 0.646 | M63: =(J63*K63*L63^2)/2/100000 -> 0.002712554
B64: H-I | C64: 0.9 | D64: ='Damètre conduites'!$H$28 -> 40 | E64: ='Damètre conduites'!$K$28 -> 105 | F64: =C64*E64/100000 -> 0.000945 | I64: T | J64: 1.3 | K64: 1000 | L64: =0.646 -> 0.646 | M64: =(J64*K64*L64^2)/2/100000 -> 0.002712554
B65: I-J | C65: 0.6 | D65: ='Damètre conduites'!$H$28 -> 40 | E65: ='Damètre conduites'!$K$28 -> 105 | F65: =C65*E65/100000 -> 0.00063 | I65: U | J65: 1.3 | K65: 1000 | L65: =0.646 -> 0.646 | M65: =(J65*K65*L65^2)/2/100000 -> 0.002712554
...

Sheet Choix des organes (2)
AQ3: V Bat
AQ4: =2*1.2*1.2*1000 -> 2880
AP7: Vnet | AQ7: Vinst | AR7: C expansion
AP8: =AQ8*0.01+AQ8*AR8 -> 214.07379 | AQ8: =('PDC singuliere-repartie'!G86+'Choix des organes'!H34+AQ4)*1.5 -> 6607.2157 | AR8: 0.0224
AQ9: 600 car installation de 600KW
AP11: Pgonflage | AR11: h
AP12: =0.3+AR12/10 -> 1.3 | AR12: =10 -> 10
AP15: Pmax | AR15: Pfin
AP16: 3 | AR16: =AP16-0.5 -> 2.5
AP18: Vreel
AP19: =AP8/(AR16-AP12/(AR16+1)) -> 100.57158
AP21: Vreserve | AR21: Pini
AP22: =(AR16-AP12/(AR16+1))*AP19-AQ8*AR8 -> 66.072157 | AR22: =((AP12+1)/(AP19-AP22))*AP19-1 -> 5.7048843
B29: Vanne d'équilibrage de base | T29: si le a n est pas entre 0,4 et 0,6 faut changer DN et donc perte de charge vanne augmentes
B30: n° | C30: Q [m3/h] | D30: DN [mm] | E30: position | F30: ΔPdC [bar]
B31: 1 | C31: ='Damètre conduites'!J24/1000 -> 10.062112 | D31: ='Damètre conduites'!H24 -> 65 | E31: 6 | F31: =17/100 -> 0.17
B32: 2 | C32: =C31 -> 10.062112 | D32: =D31 -> 65 | E32: 6 | F32: =F31 -> 0.17
B33: 3 | C33: =C32 -> 10.062112 | D33: =D32 -> 65 | E33: 6 | F33: =F31 -> 0.17
B34: 4 | C34: ='Damètre conduites'!J27/1000 -> 5.5891947 | D34: ='Damètre conduites'!H27 -> 50 | E34: 6 | F34: =17/100 -> 0.17 | R34: evasement | S34: contraction | U34: evasement | V34: contraction
B35: 5 | C35: ='Damètre conduites'!J28/1000 -> 2.9227425 | D35: ='Damètre conduites'!H28 -> 40 | E35: 6 | F35: =11/100 -> 0.11 | Q35: A | R35: =40/50 -> 0.8 | S35: =40/50 -> 0.8 | U35: =25/40 -> 0.625 | V35: =25/40 -> 0.625 | AR35: effet utile | AS35: volume total
Q36: xsi | R36: 0.25 | S36: 0.02 | U36: 0.25 | V36: 0.06 | AR36: =((AR16+1)-(AP12+1))/(AR16+1) -> 0.34285714 | AS36: =AP8/AR36 -> 624.38189
B37: Vanne de régulation 2 voies | Q37: w | R37: ='Damètre conduites'!J27/3600/'Damètre conduites'!C4/'Damètre conduites'!I28 -> 1.2354833 | S37: =R37 -> 1.2354833 | U37: ='Damètre conduites'!J28/3600/'Damètre conduites'!C4/'Damètre conduites'!I32 -> 1.6539339 | V37: =U37 -> 1.6539339
B38: n° | C38: Q [m3/h] | D38: DN [mm] | E38: ΔPdC vanne [bar] | F38: ΔPdC circuit debit variable [bar] | G38: a | H38: Nom | K38: si le a n est pas entre 0,4 et 0,6 faut changer DN et donc perte de charge vanne augmentes | R38: =(R36*1000*R37^2)/2/100000 -> 0.0019080236 | S38: =(S36*1000*S37^2)/2/100000 -> 0.00015264189 | U38: =(U36*1000*U37^2)/2/100000 -> 0.0034193717 | V38: =(V36*1000*V37^2)/2/100000 -> 0.00082064921
B39: 1 | C39: ='Damètre conduites'!J28/1000 -> 2.9227425 | D39: =40 -> 40 | E39: 0.064 | F39: =F35+'PDC singuliere-repartie'!Q57+SUM('PDC singuliere-repartie'!Q47:Q49)+SUM('PDC singuliere-repartie'!F51:F68)+SUM('PDC singuliere-repartie'!M39:M48,'PDC singuliere-repartie'!M58:M67) -> 0.24001863 | G39: =E39/(E39+F39) -> 0.21051342 | R39: =R38+S38 -> 0.0020606655 | U39: =U38+V38 -> 0.0042400209
D40: 25 | E40: 0.35 | F40: =F39+U39 -> 0.24425865 | G40: =E40/(E40+F40) -> 0.58896913 | H40: VFFF31.25 DN25 Kvs5
B42: Vanne de régulation 3 voies
B43: n° | C43: Q [m3/h] | D43: DN [mm] | E43: ΔPdC vanne[bar] | F43: ΔPdC circuit debit variable [bar] | G43: a | H43: Nom
B44: 1 | C44: ='Damètre conduites'!J27/1000 -> 5.5891947 | D44: 50 | E44: =0.032 -> 0.032 | F44: =SUM('PDC singuliere-repartie'!F69:F74,'PDC singuliere-repartie'!F77:F82,'PDC singuliere-repartie'!F85,'PDC singuliere-repartie'!M49:M55,'PDC singuliere-repartie'!M68:M74)+F34+'PDC singuliere-repartie'!Q45 -> 0.28682179 | G44: =F44/(E44+F44) -> 0.89963045
D45: 40 | E45: =0.23 -> 0.23 | F45: =F44+R39 -> 0.28888246 | G45: =F45/(E45+F45) -> 0.55673969 | H45: VXF31.40 DN40 Kvs12
B47: Vanne d'équilibrage
B48: n° | C48: Q [m3/h] | D48: DN [mm] | E48: ΔPdC circuit [bar] | F48: ΔPdC [bar] | G48: position | H48: Nom
B49: 1 | C49: =C31 -> 10.062112 | D49: =D31 -> 65 | E49: =F31+SUM('PDC singuliere-repartie'!F32,'PDC singuliere-repartie'!F35,'PDC singuliere-repartie'!F36:F41,'PDC singuliere-repartie'!F42,'PDC singuliere-repartie'!F45,'PDC singuliere-repartie'!F46:F50,'PDC singuliere-repartie'!Q32,'PDC singuliere-repartie'!Q35:Q38,'PDC singuliere-repartie'!Q53,'PDC singuliere-repartie'!M32:M38,'PDC singuliere-repartie'!M77:M83) -> 0.22424432 | F49: =MAX($E$49:$E$51)-E49 -> 0 | G49: 6 | H49: TA-BVS 240- DN65 Kv25,2 position 6
B50: 2 | C50: =C32 -> 10.062112 | D50: =D32 -> 65 | E50: =F32+SUM('PDC singuliere-repartie'!F33,'PDC singuliere-repartie'!F36:F41,'PDC singuliere-repartie'!F43,'PDC singuliere-repartie'!F46:F50,'PDC singuliere-repartie'!Q32,'PDC singuliere-repartie'!Q35:Q38,'PDC singuliere-repartie'!Q53,'PDC singuliere-repartie'!M33:M38,'PDC singuliere-repartie'!M78:M83) -> 0.21294108 | F50: =MAX($E$49:$E$51)-E50 -> 0.011303238 | G50: 6.5 | H50: TA-BVS 240- DN65 Kv61,2 position 9
B51: 3 | C51: =C33 -> 10.062112 | D51: =D33 -> 65 | E51: =F32+SUM('PDC singuliere-repartie'!F34,'PDC singuliere-repartie'!F37:F41,'PDC singuliere-repartie'!F43,'PDC singuliere-repartie'!F47:F50,'PDC singuliere-repartie'!Q32,'PDC singuliere-repartie'!Q35:Q38,'PDC singuliere-repartie'!Q53,'PDC singuliere-repartie'!M34:M38,'PDC singuliere-repartie'!M79:M83) -> 0.20229889 | F51: =MAX($E$49:$E$51)-E51 -> 0.021945437 | G51: 6.5 | H51: TA-BVS 240- DN65 Kv61,2 position 9
B54: Vanne d'équilibrage
B55: n° | C55: Q [m3/h] | D55: DN [mm] | E55: ΔPdC [bar] | F55: position | G55: Nom
B56: 4 | C56: ='Damètre conduites'!J27/1000 -> 5.5891947 | D56: =D34 -> 50 | E56: =F34 -> 0.17 | F56: 6 | G56: TA-BVS 240- DN50 Kv14 position 6
B57: 5 | C57: ='Damètre conduites'!J28/1000 -> 2.9227425 | D57: =40 -> 40 | E57: =ABS(F45+E45-(F40+E40)) -> 0.075376191 | F57: 6.5 | G57: TA-BVS 240- DN40 Kv10,2 position 6,5
D59: verification de l autorite des 2 vannes apres equilibrage
B60: Vanne de régulation 2 voies
...

Sheet Feuil1

Sheet Métré
C8: Hydraulique
C9: Types / Quantité | G9: Caractéristique
C10: Chaudières | E10: Modèlen°1 | G10: Vitocrossal 200;294kW; CM2
E11: Quantité Total | F11: =3 -> 3
C13: Vanne d'isolement manuelle | E13: Modèle n°1 | G13: JIP-FF PN 16 065N4282
E14: Quantité | F14: 3
E15: Modèle n°2 | G15: JIP-FF PN 16 065N0850
E16: Quantité | F16: 6
E17: Modèle n°4 | G17: JIP-FF PN 40 065N0325
E18: Quantité | F18: 3
E19: Modèle n°5 | G19: JIP-FF PN 40 065N0320
E20: Quantité | F20: 3
E21: Quantité Total | F21: =SUM(F14,F16,F18,F20) -> 15
C23: Vanne d'isolement motorisée | E23: Modèlen°1 | G23: JIP-FF PN 16 065N0232
E24: Quantité Total | F24: =3 -> 3
C26: Vanne de régulation 2 voies | E26: Modèle n°1 | G26: VFFF31.25 DN25 Kvs5
E27: Quantité | F27: 1
E28: Quantité Total | F28: =SUM(F27) -> 1
C30: Vanne de régulation 3 voies | E30: Modèle n°1 | G30: VFFF31.40 DN40 Kvs12
E31: Quantité Total | F31: 1
C33: Vanne d'équilibrage | E33: Modèle n°1 | G33: TA-BVS 240- DN65 Kv25,2 position 6
E34: Quantité | F34: 1
E35: Modèle n°2 | G35: TA-BVS 240- DN65 Kv61,2 position 9
E36: Quantité | F36: 2
E37: Modèle n°3 | G37: TA-BVS 240- DN50 Kv14 position 6
E38: Quantité | F38: 1
E39: Modèle n°4 | G39: TA-BVS 240- DN40 Kv10,2 position 6,5
E40: Quantité | F40: 1
E41: Quantité Total | F41: =SUM(F34,F36,F38) -> 4
C43: Pompe | E43: Modèle n°1 | G43: Wilo-CrolLine-IL-E 150/200-7,5/4 (P=2 kW n =69%)
E44: Quantité Total | F44: =2 -> 2
C46: Circulateur | E46: Modèle n°1 | G46: Wilo-Stratos 50/1-10 P = 55 W
E47: Quantité Total | F47: =1 -> 1
C49: Conduit | E49: Modèle n°1 | G49: 150mm x 5m
E50: Quantité | F50: 2
E51: Modèle n°2 | G51: 65mm x 7,34m
E52: Quantité | F52: 2
E53: Modèle n°3 | G53: 65mm x 5,36m
E54: Quantité | F54: 1
E55: Modèle n°4 | G55: 65mm x 1,83m
...
