Workbook

Sheet Données
B2: Local | D2: Surface [m²] | E2: Hauteur [m] | F2: Volume [m³] | G2: Faux plafond Utile [cm] | H2: Qi m³/h été | I2: Qi m³/h HIVER | J2: D été | K2: D norma été | L2: L NORMA ÉTÉ ( rectangle)
B3: 1.COFFRE FORT | D3: 30.36 | E3: 3.6 | F3: =D3*E3 -> 109.296 | G3: 0 | H3: =550 -> 550 | I3: =550 -> 550 | J3: =(H3/4/3600/PI()*4)^(1/2) -> 0.22052364 | K3: DN250 | L3: X
B4: 2.KITCHENETTE | D4: 22.85 | E4: 3.6 | F4: =D4*E4 -> 82.26 | G4: =55-10 -> 45 | H4: =ROUND(H41/5,0)*5 -> 365 | I4: =ROUND(I41/5,0)*5 -> 365 | J4: =(H4/4/3600/PI()*4)^(1/2) -> 0.17964711 | K4: 0
B5: 3.ESCALIER | D5: 12.41 | E5: 3.6 | F5: =D5*E5 -> 44.676 | G5: 0 | H5: =ROUND(H42/5,0)*5 -> 0 | I5: =ROUND(I42/5,0)*5 -> 0 | J5: =(H5/4/3600/PI()*4)^(1/2) -> 0 | K5: =(I5/4/3600/PI()*4)^(1/2) -> 0 | L5: =(J5/4/3600/PI()*4)^(1/2) -> 0
B6: 4.Bureau 4 | D6: 27.488889 | E6: 3.6 | F6: =D6*E6 -> 98.96 | G6: =55-10 -> 45 | H6: =ROUND(H43/5,0)*5 -> 880 | I6: =ROUND(I43/5,0)*5 -> 440 | J6: =(H6/4/3600/PI()*4)^(1/2) -> 0.2789428 | K6: DN315
B7: 5.Bureau5 | D7: 18.019444 | E7: 3.6 | F7: =D7*E7 -> 64.87 | G7: =55-10 -> 45 | H7: =ROUND(H44/5,0)*5 -> 575 | I7: =ROUND(I44/5,0)*5 -> 290 | J7: =(H7/4/3600/PI()*4)^(1/2) -> 0.22547985 | K7: DN250
B8: 6.Bureau 6 | D8: 18.13 | E8: 3.6 | F8: =D8*E8 -> 65.268 | G8: =55-10 -> 45 | H8: =ROUND(H45/5,0)*5 -> 580 | I8: =ROUND(I45/5,0)*5 -> 290 | J8: =(H8/4/3600/PI()*4)^(1/2) -> 0.22645807 | K8: DN250
B9: 7.Bureau 7 | D9: 18.13 | E9: 3.6 | F9: =D9*E9 -> 65.268 | G9: =55-10 -> 45 | H9: =ROUND(H46/5,0)*5 -> 580 | I9: =ROUND(I46/5,0)*5 -> 290 | J9: =(H9/4/3600/PI()*4)^(1/2) -> 0.22645807 | K9: DN250
B10: 8.SDR | D10: 33.3 | E10: 3.6 | F10: =D10*E10 -> 119.88 | G10: 0 | H10: =ROUND(H47/5,0)*5 -> 965 | I10: =ROUND(I47/5,0)*5 -> 535 | J10: =(H10/4/3600/PI()*4)^(1/2) -> 0.29210398 | K10: DN315 | L10: X
B11: 9.Couloir droite | D11: 45.8 | E11: 3.6 | F11: =D11*E11 -> 164.88 | G11: =55-10 -> 45 | H11: =ROUND(H48/5,0)*5 -> 1375 | I11: =ROUND(I48/5,0)*5 -> 640 | J11: =(H11/4/3600/PI()*4)^(1/2) -> 0.34867849 | K11: DN400
B12: 10.Approvisionnement | D12: 7.24 | E12: 3.6 | F12: =D12*E12 -> 26.064 | G12: =55-10 -> 45 | H12: =54 -> 54 | I12: 54 | J12: =(H12/4/3600/PI()*4)^(1/2) -> 0.06909883 | K12: DN80
B13: 11/12/13. Entrée | D13: 18.2075 | E13: 3.6 | F13: =D13*E13 -> 65.547 | G13: 0 | H13: =ROUND(H50/5,0)*5 -> 545 | I13: =H13 -> 545 | J13: =(H13/4/3600/PI()*4)^(1/2) -> 0.21951897 | K13: DN250
B14: 14.Distrib | D14: 21.21 | E14: 3.6 | F14: =D14*E14 -> 76.356 | G14: =55-10 -> 45 | H14: 160 | I14: =ROUND(I51/5,0)*5 -> 295 | J14: =(H14/4/3600/PI()*4)^(1/2) -> 0.11894161 | K14: DN125
B15: 15.Secretariat | D15: 30.02 | E15: 3.6 | F15: =D15*E15 -> 108.072 | G15: 0 | H15: =ROUND(H52/5,0)*5 -> 960 | I15: =ROUND(I52/5,0)*5 -> 480 | J15: =(H15/4/3600/PI()*4)^(1/2) -> 0.29134625 | K15: DN315 | L15: X
B16: 16.SDR | D16: 52.62 | E16: 3.6 | F16: =D16*E16 -> 189.432 | G16: =55-10 -> 45 | H16: =ROUND(H53/5,0)*5 -> 1580 | I16: =ROUND(I53/5,0)*5 -> 840 | J16: =(H16/4/3600/PI()*4)^(1/2) -> 0.37376821 | K16: DN400
B17: 17. Salle d'attente | D17: 55.32 | E17: 3.6 | F17: =D17*E17 -> 199.152 | G17: =55-10 -> 45 | H17: =ROUND(H54/5,0)*5 -> 1770 | I17: =ROUND(I54/5,0)*5 -> 885 | J17: =(H17/4/3600/PI()*4)^(1/2) -> 0.39560379 | K17: DN400
B18: 18.WC individuelle | D18: 4.73 | E18: 3.6 | F18: =D18*E18 -> 17.028 | G18: =95-10 -> 85 | H18: =ROUND(H55/5,0)*5 -> 50 | I18: =ROUND(I55/5,0)*5 -> 50 | J18: =(H18/4/3600/PI()*4)^(1/2) -> 0.06649038 | K18: DN80
B19: 19.WC PMR | D19: 4.37 | E19: 3.6 | F19: =D19*E19 -> 15.732 | G19: =95-10 -> 85 | H19: =ROUND(H56/5,0)*5 -> 100 | I19: =ROUND(I56/5,0)*5 -> 100 | J19: =(H19/4/3600/PI()*4)^(1/2) -> 0.094031597 | K19: DN100
B20: 20.WC femme | D20: 17.4 | E20: 3.6 | F20: =D20*E20 -> 62.64 | G20: =95-10 -> 85 | H20: =ROUND(H57/5,0)*5 -> 50 | I20: =ROUND(I57/5,0)*5 -> 50 | J20: =(H20/4/3600/PI()*4)^(1/2) -> 0.06649038 | K20: DN80
B21: 21.WC homme | D21: 12.27 | E21: 3.6 | F21: =D21*E21 -> 44.172 | G21: =95-10 -> 85 | H21: =ROUND(H58/5,0)*5 -> 50 | I21: =ROUND(I58/5,0)*5 -> 50 | J21: =(H21/4/3600/PI()*4)^(1/2) -> 0.06649038 | K21: DN80
B22: 22.Trappe | D22: 10.89 | E22: 3.6 | F22: =D22*E22 -> 39.204 | G22: 0 | H22: =ROUND(H59/5,0)*5 -> 0 | I22: =ROUND(I59/5,0)*5 -> 0 | J22: =(H22/4/3600/PI()*4)^(1/2) -> 0 | K22: =(I22/4/3600/PI()*4)^(1/2) -> 0 | L22: =(J22/4/3600/PI()*4)^(1/2) -> 0
B23: 23.Trémis | D23: 3.514 | E23: 3.6 | F23: =D23*E23 -> 12.6504 | G23: 0 | H23: =ROUND(H60/5,0)*5 -> 0 | I23: =ROUND(I60/5,0)*5 -> 0 | J23: =(H23/4/3600/PI()*4)^(1/2) -> 0 | K23: =(I23/4/3600/PI()*4)^(1/2) -> 0 | L23: =(J23/4/3600/PI()*4)^(1/2) -> 0
D24: =SUM(D3:D23) -> 464.27983 | F24: =SUM(F3:F23) -> 1671.4074 | H24: =SUM(H3:H23) -> 11189 | I24: =SUM(I3:I23) -> 6749 | J24: FAIRE LES VRAI DIAMETRES ET DIMENSIONS DANS LA FEUILLE pdc
B25: zone de d'occupation | D25: =3.975*9.6 -> 38.16 | E25: 1.25 | F25: =D25*E25 -> 47.7
C27: Qmax | E27: D m | G27: D normalisée avec Patm/m=1
B28: LOCAL TECH | C28: =H24 -> 11189 | D28: VMAX=7 | E28: =(C28/7/3600/PI()*4)^(1/2) -> 0.75188328 | F28: 1000x500
G29: FAIRE RECTANGLE
C30: pour les autres pieces | D30: VMAX=4
H40: 0 | I40: 0
H41: 365.6 | I41: 365.6
H42: 0 | I42: 0
H43: 879.64444 | I43: 439.82222
H44: 576.62222 | I44: 288.31111
H45: 580.16 | I45: 290.08
H46: 580.16 | I46: 290.08
H47: 965.7 | I47: 532.8
H48: 1374 | I48: 641.2
H50: =D13*30 -> 546.225 | I50: =D13*14 -> 254.905
H51: =D14*30 -> 636.3 | I51: =D14*14 -> 296.94
H52: 960.64 | I52: 480.32
...

Sheet Bouche GP-GE 
C2: GP | N2: VL doit etre plus petit que 0,4 | Q2: ∆TL doit etre plus petit que -1 degre
I4: LWNR=35 max | K4: ∆Tz | L4: =-6 -> -6 | N4: VH doit etre plus petit que 0,2
E5: H1=3,6 - 1,8 - faux plafond | I5: LWNR=LWNC+1
J6: X=L - H1 | K6: on a pas de A mais = à B
C8: Local | E8: Qi m³/h été | F8: H1 | G8: Nom de la bouche | H8: Perte de charge | I8: LWNC [dB (A)] | J8: X [m] | K8: A [m] | L8: B [m] | M8: ∆Tl/∆Tz | N8: VL [m/s] | O8: VH [m/s] | P8: ∆TL [°C]
C9: 1.COFFRE FORT | E9: =Données!H3 -> 550 | F9: 1.8 | G9: VDW-Q-600x24-H | H9: =21 -> 21 | I9: 0 | J9: 1.2 | K9: / | L9: / | M9: 0.058 | N9: 0.35 | O9: / | P9: =M9*L4 -> -0.348
C10: 2.KITCHENETTE | E10: =Données!H4 -> 365 | F10: 1.25 | G10: VDW-Q-500x24-H | H10: 20 | I10: 26 | J10: 1.25 | K10: / | L10: / | M10: 0.047 | N10: 0.34 | O10: / | P10: =M10*$L$4 -> -0.282
C11: 3.ESCALIER | E11: =Données!H5 -> 0 | F11: / | G11: / | H11: / | I11: / | J11: / | K11: / | L11: / | M11: / | N11: / | O11: / | P11: /
C12: 4.Bureau 4 | E12: =Données!H6 -> 880 | F12: 1.25 | G12: VDW-Q- 825x72-H | H12: =12.5 -> 12.5 | I12: =21 -> 21 | J12: 2.75 | K12: / | L12: / | M12: 0.048 | N12: 0.34 | O12: / | P12: =M12*$L$4 -> -0.288
C13: 5.Bureau5 | E13: =Données!H7 -> 575 | F13: 1.25 | G13: VDW-Q-600x24-H | H13: 19 | I13: 28 | J13: 1.75 | K13: / | L13: / | M13: 0.058 | N13: 0.36 | O13: / | P13: =M13*$L$4 -> -0.348
C14: 6.Bureau 6 | E14: =Données!H8 -> 580 | F14: 1.25 | G14: VDW-Q-600x24-H | H14: 20 | I14: 29 | J14: 1.75 | K14: / | L14: / | M14: 0.058 | N14: 0.36 | O14: / | P14: =M14*$L$4 -> -0.348
C15: 7.Bureau 7 | E15: =Données!H9 -> 580 | F15: 1.25 | G15: VDW-Q-600x24-H | H15: 20 | I15: 29 | J15: 1.75 | K15: / | L15: / | M15: 0.058 | N15: 0.36 | O15: / | P15: =M15*$L$4 -> -0.348
C16: 8.SDR | E16: =Données!H10 -> 965 | F16: 1.8 | G16: VDW-Q- 825x72-H | H16: 16 | I16: 25 | J16: 2.7 | K16: / | L16: / | M16: 0.046 | N16: 0.34 | O16: / | P16: =M16*$L$4 -> -0.276
C17: 9.Couloir droite | E17: =Données!H11 -> 1375 | F17: 1.25 | G17: 2x VDW-Q- 625x54-H | H17: =19*2 -> 38 | I17: =26+3 -> 29 | J17: 1.25 | K17: / | L17: 3 | M17: 0.15 | N17: 0.25 | O17: 0.16 | P17: =M17*$L$4 -> -0.9
C18: 10.Approvisionnement | E18: =Données!H12 -> 54 | F18: 1.25 | G18: VDW-Q- 300x8-H | H18: 6 | J18: 1.25 | K18: / | L18: / | M18: 0.02 | N18: 0.14 | O18: / | P18: =M18*$L$4 -> -0.12
C19: 11. Entrée droite | E19: 125 | F19: 1.8 | G19: VDW-Q-300x8-H | H19: 12.5 | I19: 13 | J19: 0.2 | K19: / | L19: / | M19: 0.035 | N19: 0.25 | O19: / | P19: =M19*$L$4 -> -0.21
C20: 12. Entrée princ | E20: 300 | F20: 1.8 | G20: VDW-Q-400x16-H | H20: 22.5 | I20: 25 | J20: 0.7 | K20: / | L20: / | M20: 0.037 | N20: 0.34 | O20: / | P20: =M20*$L$4 -> -0.222
C21: 13. Entrée gauche | E21: 125 | F21: 1.8 | G21: VDW-Q-300x8-H | H21: =H19 -> 12.5 | I21: =I19 -> 13 | J21: =J19 -> 0.2 | K21: / | L21: / | M21: =M19 -> 0.035 | N21: =N19 -> 0.25 | O21: / | P21: =P19 -> -0.21
C22: 14.Distrib | E22: =Données!H14 -> 160 | F22: 1.25 | G22: VDW-Q- 300x8-H | H22: =21 -> 21 | I22: =19 -> 19 | J22: 0.75 | K22: / | L22: / | M22: 0.044 | N22: 0.31 | O22: / | P22: =M22*$L$4 -> -0.264
C23: 15.Secretariat | E23: =Données!H15 -> 960 | F23: 1.8 | G23: VDW-Q- 825x72-H | H23: =12.5 -> 12.5 | I23: =I21 -> 13 | J23: 2 | K23: / | L23: / | M23: 0.05 | N23: 0.38 | O23: / | P23: =M23*$L$4 -> -0.3 | Q23: pas besoin de respecter X et B dans les couloirs ou salle d'attente
C24: 16.SDR | E24: =Données!H16 -> 1580 | F24: 1.25 | G24: 2x VDW-Q- 625x54-H | H24: =24*2 -> 48 | I24: =30+3 -> 33 | J24: 1.75 | K24: / | L24: 4 | M24: 0.125 | N24: 0.3 | O24: 0.15 | P24: =M24*$L$4 -> -0.75
C25: 17. Salle d'attente | E25: =Données!H17 -> 1770 | F25: 1.25 | G25: 2x VDW-Q- 625x54-H | H25: =32*2 -> 64 | I25: =34 -> 34 | J25: 1.75 | K25: / | L25: 4 | M25: 0.16 | N25: 0.25 | O25: 0.16 | P25: =M25*$L$4 -> -0.96
C26: 18.WC individuelle | E26: =Données!H18 -> 50 | F26: 0.95 | G26: / | H26: / | I26: / | J26: / | K26: / | L26: / | M26: / | N26: / | O26: / | P26: /
C27: 19.WC PMR | E27: =Données!H19 -> 100 | F27: 0.95 | G27: / | H27: / | I27: / | J27: / | K27: / | L27: / | M27: / | N27: / | O27: / | P27: /
C28: 20.WC femme | E28: =Données!H20 -> 50 | F28: 0.95 | G28: / | H28: / | I28: / | J28: / | K28: / | L28: / | M28: / | N28: / | O28: / | P28: /
C29: 21.WC homme | E29: =Données!H21 -> 50 | F29: 0.95 | G29: / | H29: / | I29: / | J29: / | K29: / | L29: / | M29: / | N29: / | O29: / | P29: /
C30: 22.Trappe | E30: =Données!H22 -> 0 | F30: / | G30: / | H30: / | I30: / | J30: / | K30: / | L30: / | M30: / | N30: / | O30: / | P30: /
C31: 23.Trémis | E31: =Données!H23 -> 0 | F31: / | G31: / | H31: / | I31: / | J31: / | K31: / | L31: / | M31: / | N31: / | O31: / | P31: /
H32: =SUM(H9:H25) -> 365.5
C33: ENTREE | E33: DANS LES PTITES PIECES JE METS DES PETITES BOUCHE MAIS DANS L4ENTRREE PRINCIPALE JE METS DES GROISSES BOUCHES CAR TROP DE PERTE DE CHARGE A 300M3/H DONC J4AI PRIS LA TAILLE SUIVANTE DE BOUCHE
E34: JE METS DES PETITES BOUCHES DANS LES PTITES PIECES POUR BLOQUER LE FROID/ CHAUD DES FENETRES
C38: GE | M38: GE SANITAIRE
C41: Local | E41: Qi m³/h été | F41: H1 | G41: Nom de la bouche | H41: Perte de charge | I41: LWNC [dB (A)] | M41: Local | O41: Qi m³/h été | P41: H1 | Q41: Nom de la bouche | R41: Perte de charge | S41: LWNC [dB (A)]
C42: 1.COFFRE FORT | E42: 550 | F42: 1.8 | G42: VDW-Q-600x24-H | H42: 7 | I42: 15 | M42: 18.WC individuelle | O42: 50 | P42: 0.95 | Q42: TLH-100 | R42: 12.5 | S42: =14-4 -> 10
C43: 2.KITCHENETTE | E43: 365 | F43: 1.25 | G43: VDW-Q-500x24-H | H43: 6.5 | I43: <25 | M43: 19.WC PMR | O43: 100 | P43: 0.95 | Q43: TLH-125 | R43: 12.5 | S43: =20-4 -> 16
C44: 3.ESCALIER | E44: 0 | F44: / | G44: / | H44: / | I44: / | M44: 20.WC femme | O44: 50 | P44: 0.95 | Q44: TLH-100 | R44: =R42 -> 12.5 | S44: =S42 -> 10
C45: 4.Bureau 4 | E45: 880 | F45: 1.25 | G45: VDW-Q- 825x72-H | H45: 4.25 | I45: <25 | M45: 21.WC homme | O45: 50 | P45: 0.95 | Q45: TLH-100 | R45: =R42 -> 12.5 | S45: =S42 -> 10
C46: 5.Bureau5 | E46: 575 | F46: 1.25 | G46: VDW-Q-600x24-H | H46: 7.75 | I46: 16
C47: 6.Bureau 6 | E47: 580 | F47: 1.25 | G47: VDW-Q-600x24-H | H47: 7.8 | I47: 16 | M47: https://www.trox.be/bouches-circulaires/tlh-e1a320b39a2de552
C48: 7.Bureau 7 | E48: 580 | F48: 1.25 | G48: VDW-Q-600x24-H | H48: 7.8 | I48: 16
...

Sheet PDC répartie-Dimension gaine
C3: faux plafond est egale a 45 cm donc l doit etre egale a 22,5 max ou du moins prcq ya GP et GE qui peuvent se croiser donc ca fera 22,5*2
B5: Vitesse [m/s]
B6: Local tech. | C6: 7
B7: Local occup. | C7: 4
A9: Charges réparties | B9: GP
B12: Tronçon | C12: Pièce | D12: L tronçon [m] | E12: Débit [m3/h] | F12: Section [mm2] | G12: Cercle/rectangle | H12: D [mm] | I12: Pertes de charge [Pa/m] | J12: Pertes réparties [Pa] | K12: Dimension normalisée [mm] | L12: Section réel [mm2] | M12: Vitesse réel [m/s]
B13: W-X | C13: =Données!B3 -> 1.COFFRE FORT | D13: =2.42 -> 2.42 | E13: =Données!H3 -> 550 | F13: =E13/(3600*$C$7) * 10^6 -> 38194.444 | G13: cercle | H13: =SQRT((4*F13)/PI()) -> 220.52364 | I13: 0.54 | J13: =D13*I13 -> 1.3068 | K13: DN250 | L13: =(PI()*250^2)/4 -> 49087.385 | M13: =E13/(L13*10^-6)/3600 -> 3.1123633
B14: W-Z | C14: =Données!B4 -> 2.KITCHENETTE | D14: =3.025 -> 3.025 | E14: =Données!H4 -> 365 | F14: =E14/(3600*$C$7) * 10^6 -> 25347.222 | G14: rectangle | I14: 1 | J14: =D14*I14 -> 3.025 | K14: 150x200 | L14: =200*150 -> 30000 | M14: =E14/(L14*10^-6)/3600 -> 3.3796296
B15: R-T | C15: =Données!B6 -> 4.Bureau 4 | D15: =1.525 -> 1.525 | E15: =Données!H6 -> 880 | F15: =E15/(3600*$C$7) * 10^6 -> 61111.111 | G15: rectangle | I15: 0.48 | J15: =D15*I15 -> 0.732 | K15: 200x400 | L15: =200*400 -> 80000 | M15: =E15/(L15*10^-6)/3600 -> 3.0555556
B16: T-T'' | C16: =C15 -> 4.Bureau 4 | D16: 4 | E16: =E15 -> 880 | F16: =F15 -> 61111.111 | G16: rectangle | I16: =I15 -> 0.48 | J16: =D16*I16 -> 1.92 | K16: 200x400 | L16: =L15 -> 80000 | M16: =M15 -> 3.0555556
B17: O-Q | C17: =Données!B7 -> 5.Bureau5 | D17: 4.4375 | E17: =Données!H7 -> 575 | F17: =E17/(3600*$C$7) * 10^6 -> 39930.556 | G17: rectangle | I17: 0.44 | J17: =D17*I17 -> 1.9525 | K17: 200x300 | L17: =200*300 -> 60000 | M17: =E17/(L17*10^-6)/3600 -> 2.662037
B18: C-D | C18: =Données!B8 -> 6.Bureau 6 | D18: 4.4375 | E18: =Données!H8 -> 580 | F18: =E18/(3600*$C$7) * 10^6 -> 40277.778 | G18: rectangle | I18: 0.44 | J18: =D18*I18 -> 1.9525 | K18: 200x300 | L18: =200*300 -> 60000 | M18: =E18/(L18*10^-6)/3600 -> 2.6851852
B19: E-G | C19: =Données!B9 -> 7.Bureau 7 | D19: =4.4375 -> 4.4375 | E19: =Données!H9 -> 580 | F19: =E19/(3600*$C$7) * 10^6 -> 40277.778 | G19: rectangle | I19: 0.44 | J19: =D19*I19 -> 1.9525 | K19: 200x300 | L19: =200*300 -> 60000 | M19: =E19/(L19*10^-6)/3600 -> 2.6851852
B20: M-N | C20: =Données!B10 -> 8.SDR | D20: =3.4875 -> 3.4875 | E20: =Données!H10 -> 965 | F20: =E20/(3600*$C$7) * 10^6 -> 67013.889 | G20: cercle | H20: =SQRT((4*F20)/PI()) -> 292.10398 | I20: 0.48 | J20: =D20*I20 -> 1.674 | K20: DN315 | L20: =(PI()*315^2)/4 -> 77931.133 | M20: =E20/(L20*10^-6)/3600 -> 3.4396466
B21: L-M | C21: =C20 -> 8.SDR | D21: 1.47 | E21: =E20 -> 965 | F21: =E21/(3600*$C$7) * 10^6 -> 67013.889 | G21: cercle | H21: =SQRT((4*F21)/PI()) -> 292.10398 | I21: 0.48 | J21: =D21*I21 -> 0.7056 | K21: DN315 | L21: =(PI()*315^2)/4 -> 77931.133 | M21: =E21/(L21*10^-6)/3600 -> 3.4396466
B22: R-W | C22: 9.Couloir droite | D22: 5.7625 | E22: =E14+E13 -> 915 | F22: =E22/(3600*$C$7) * 10^6 -> 63541.667 | G22: rectangle | I22: 0.25 | J22: =D22*I22 -> 1.440625 | K22: 200x600 | L22: =200*600 -> 120000 | M22: =E22/(L22*10^-6)/3600 -> 2.1180556
B23: P-O | C23: 9.Couloir droite | D23: 1.375 | E23: =E25+E17 -> 2370 | F23: =E23/(3600*$C$7) * 10^6 -> 164583.33 | G23: rectangle | I23: 0.42 | J23: =D23*I23 -> 0.5775 | K23: 300x600 | L23: =300*600 -> 180000 | M23: =E23/(L23*10^-6)/3600 -> 3.6574074
B24: P-U | C24: 9.Couloir droite | D24: 0.1875 | E24: =Données!H11/2 -> 687.5 | F24: =E24/(3600*$C$7) * 10^6 -> 47743.056 | G24: rectangle | I24: 0.9 | J24: =D24*I24 -> 0.16875 | K24: 200x250 | L24: =250*200 -> 50000 | M24: =E24/(L24*10^-6)/3600 -> 3.8194444
B25: R-O | C25: 9.Couloir droite | D25: =1.375 -> 1.375 | E25: =E22+E15 -> 1795 | F25: =E25/(3600*$C$7) * 10^6 -> 124652.78 | G25: rectangle | I25: 0.5 | J25: =D25*I25 -> 0.6875 | K25: 250x500 | L25: =250*500 -> 125000 | M25: =E25/(L25*10^-6)/3600 -> 3.9888889
B26: P-C | C26: 9.Couloir droite | D26: 5.6 | E26: =E23+E24 -> 3057.5 | F26: =E26/(3600*$C$7) * 10^6 -> 212326.39 | G26: rectangle | I26: 0.35 | J26: =D26*I26 -> 1.96 | K26: 300x800 | L26: =300*800 -> 240000 | M26: =E26/(L26*10^-6)/3600 -> 3.5387731
B27: C-B | C27: 9.Couloir droite | D27: 0.75 | E27: =E26+E18 -> 3637.5 | F27: =E27/(3600*$C$7) * 10^6 -> 252604.17 | G27: rectangle | I27: 0.28 | J27: =D27*I27 -> 0.21 | K27: 300x1000 | L27: =300*1000 -> 300000 | M27: =E27/(L27*10^-6)/3600 -> 3.3680556
B28: H-B | C28: 9.Couloir droite | D28: 2.325 | E28: =E27 -> 3637.5 | F28: =E28/(3600*$C$7) * 10^6 -> 252604.17 | G28: rectangle | I28: 0.28 | J28: =D28*I28 -> 0.651 | K28: 300x1000 | L28: =300*1000 -> 300000 | M28: =E28/(L28*10^-6)/3600 -> 3.3680556
B29: H-F | C29: 9.Couloir droite | D29: 2.25 | E29: =E21+E35+E19+E31 -> 2286.5 | F29: =E29/(3600*$C$7) * 10^6 -> 158784.72 | G29: rectangle | I29: 0.28 | J29: =D29*I29 -> 0.63 | K29: 200x800 | L29: =200*800 -> 160000 | M29: =E29/(L29*10^-6)/3600 -> 3.9696181
B30: F-V | C30: 9.Couloir droite | D30: 1.5 | E30: =E29 -> 2286.5 | F30: =E30/(3600*$C$7) * 10^6 -> 158784.72 | G30: rectangle | I30: 0.28 | J30: =D30*I30 -> 0.42 | K30: 200x800 | L30: =200*800 -> 160000 | M30: =E30/(L30*10^-6)/3600 -> 3.9696181
B31: S-V | C31: 9.Couloir droite | D31: 0.1875 | E31: =Données!H11/2 -> 687.5 | F31: =E31/(3600*$C$7) * 10^6 -> 47743.056 | G31: rectangle | I31: 0.9 | J31: =D31*I31 -> 0.16875 | K31: 200x250 | L31: =250*200 -> 50000 | M31: =E31/(L31*10^-6)/3600 -> 3.8194444
B32: V-E | C32: 9.Couloir droite | D32: 1.5 | E32: =E19+E35+E20 -> 1599 | F32: =E32/(3600*$C$7) * 10^6 -> 111041.67 | G32: rectangle | I32: 0.3 | J32: =D32*I32 -> 0.45 | K32: 200x800 | L32: =200*800 -> 160000 | M32: =E32/(L32*10^-6)/3600 -> 2.7760417
B33: E-I | C33: 9.Couloir droite | D33: 0.9 | E33: =E21+E35 -> 1019 | F33: =E33/(3600*$C$7) * 10^6 -> 70763.889 | G33: rectangle | I33: 0.36 | J33: =D33*I33 -> 0.324 | K33: 200x600 | L33: =200*600 -> 120000 | M33: =E33/(L33*10^-6)/3600 -> 2.3587963
B34: I-L | C34: 9.Couloir droite | D34: 0.975 | E34: =E21 -> 965 | F34: =E34/(3600*$C$7) * 10^6 -> 67013.889 | G34: rectangle | I34: 0.55 | J34: =D34*I34 -> 0.53625 | K34: 200x400 | L34: =200*400 -> 80000 | M34: =E34/(L34*10^-6)/3600 -> 3.3506944
B35: I-K | C35: =Données!B12 -> 10.Approvisionnement | D35: =2.6875 -> 2.6875 | E35: 54 | F35: =E35/(3600*$C$7) * 10^6 -> 3750 | G35: rectangle | I35: 0.14 | J35: =D35*I35 -> 0.37625 | K35: 100x200 | L35: =100*200 -> 20000 | M35: =E35/(L35*10^-6)/3600 -> 0.75
B36: W'-X' | C36: 11. Entrée droite | D36: 0.9 | E36: 125 | F36: =E36/(3600*$C$7) * 10^6 -> 8680.5556 | G36: cercle | H36: =SQRT((4*F36)/PI()) -> 105.13052 | I36: 0.9 | J36: =D36*I36 -> 0.81 | K36: DN125 | L36: =(PI()*125^2)/4 -> 12271.846 | M36: =E36/(L36*10^-6)/3600 -> 2.8294212
B37: V'-W' | C37: =C36 -> 11. Entrée droite | D37: 0.2 | E37: 125 | F37: =E37/(3600*$C$7) * 10^6 -> 8680.5556 | G37: cercle | H37: =SQRT((4*F37)/PI()) -> 105.13052 | I37: 0.9 | J37: =D37*I37 -> 0.18 | K37: DN125 | L37: =(PI()*125^2)/4 -> 12271.846 | M37: =E37/(L37*10^-6)/3600 -> 2.8294212
B38: T'-U' | C38: 12. Entrée principale | D38: 0.2 | E38: 300 | F38: =E38/(3600*$C$7) * 10^6 -> 20833.333 | G38: cercle | H38: =SQRT((4*F38)/PI()) -> 162.8675 | I38: 0.54 | J38: =D38*I38 -> 0.108 | K38: DN200 | L38: =(PI()*200^2)/4 -> 31415.927 | M38: =E38/(L38*10^-6)/3600 -> 2.6525824
B39: T'-V' | C39: =C38 -> 12. Entrée principale | D39: 3.7 | E39: 125 | F39: =E39/(3600*$C$7) * 10^6 -> 8680.5556 | G39: cercle | H39: =SQRT((4*F39)/PI()) -> 105.13052 | I39: 0.9 | J39: =D39*I39 -> 3.33 | K39: DN125 | L39: =(PI()*125^2)/4 -> 12271.846 | M39: =E39/(L39*10^-6)/3600 -> 2.8294212
B40: S'-T' | C40: =C39 -> 12. Entrée principale | D40: 0.7 | E40: =E38+E39 -> 425 | F40: =E40/(3600*$C$7) * 10^6 -> 29513.889 | G40: cercle | H40: =SQRT((4*F40)/PI()) -> 193.8511 | I40: 1 | J40: =D40*I40 -> 0.7 | K40: DN200 | L40: =(PI()*200^2)/4 -> 31415.927 | M40: =E40/(L40*10^-6)/3600 -> 3.757825
B41: Q'-R' | C41: 13. Entrée gauche | D41: 0.92 | E41: =125 -> 125 | F41: =E41/(3600*$C$7) * 10^6 -> 8680.5556 | G41: cercle | H41: =SQRT((4*F41)/PI()) -> 105.13052 | I41: 0.9 | J41: =D41*I41 -> 0.828 | K41: DN125 | L41: =(PI()*125^2)/4 -> 12271.846 | M41: =E41/(L41*10^-6)/3600 -> 2.8294212
B42: P'-Q' | C42: =C41 -> 13. Entrée gauche | D42: 0.2 | E42: =E38+E36+E41 -> 550 | F42: =E42/(3600*$C$7) * 10^6 -> 38194.444 | G42: cercle | H42: =SQRT((4*F42)/PI()) -> 220.52364 | I42: 0.55 | J42: =D42*I42 -> 0.11 | K42: DN250 | L42: =(PI()*250^2)/4 -> 49087.385 | M42: =E42/(L42*10^-6)/3600 -> 3.1123633
B43: Q'-S' | C43: =C41 -> 13. Entrée gauche | D43: 1.125 | E43: =E40 -> 425 | F43: =E43/(3600*$C$7) * 10^6 -> 29513.889 | G43: cercle | H43: =SQRT((4*F43)/PI()) -> 193.8511 | I43: 1 | J43: =D43*I43 -> 1.125 | K43: DN200 | L43: =(PI()*200^2)/4 -> 31415.927 | M43: =E43/(L43*10^-6)/3600 -> 3.757825
B44: H'-J' | C44: =Données!B14 -> 14.Distrib | D44: 1.975 | E44: ='Bouche GP-GE '!E22 -> 160 | F44: =E44/(3600*$C$7) * 10^6 -> 11111.111 | G44: rectangle | I44: 0.6 | J44: =D44*I44 -> 1.185 | K44: 100x200 | L44: =200*100 -> 20000 | M44: =E44/(L44*10^-6)/3600 -> 2.2222222
B45: K'-L' | C45: 15. Sécretariat | D45: 2 | E45: =E46+E42 -> 1510 | F45: =E45/(3600*$C$7) * 10^6 -> 104861.11 | G45: cercle | H45: =SQRT((4*F45)/PI()) -> 365.39474 | I45: 0.31 | J45: =D45*I45 -> 0.62 | K45: DN400 | L45: =(PI()*400^2)/4 -> 125663.71 | M45: =E45/(L45*10^-6)/3600 -> 3.3378328
B46: L'-M' | C46: 15. Sécretariat | D46: 2.7 | E46: ='Bouche GP-GE '!E23 -> 960 | F46: =E46/(3600*$C$7) * 10^6 -> 66666.667 | G46: cercle | H46: =SQRT((4*F46)/PI()) -> 291.34625 | I46: 0.48 | J46: =D46*I46 -> 1.296 | K46: DN315 | L46: =(PI()*315^2)/4 -> 77931.133 | M46: =E46/(L46*10^-6)/3600 -> 3.4218246
...

Sheet PDC singuliere-Clapet
B3: GP
A5: Clapet
B6: Clapets coupe-feu | C6: Tronçon | D6: Débit [m3/h] | E6: Gaine | F6: v réelle [m/s] | G6: Poids [kg] | H6: ΔPdC [Pa] | I6: Sélection
B7: 1.Coffre-fort | C7: ='PDC répartie-Dimension gaine'!B13 -> W-X | D7: ='PDC répartie-Dimension gaine'!E13 -> 550 | E7: ='PDC répartie-Dimension gaine'!K13 -> DN250 | F7: ='PDC répartie-Dimension gaine'!M13 -> 3.1123633 | G7: 5 | H7: 5 | I7: FKRS-EU / BE / 250
B8: 10. Approv | C8: ='PDC répartie-Dimension gaine'!B35 -> I-K | D8: ='PDC répartie-Dimension gaine'!E35 -> 54 | E8: ='PDC répartie-Dimension gaine'!K35 -> 100x200 | F8: ='PDC répartie-Dimension gaine'!M35 -> 0.75 | G8: 4 | H8: 0 | I8: FKA2-EU/200x100x305
B9: 13. Entrée gauche | C9: ='PDC répartie-Dimension gaine'!B42 -> P'-Q' | D9: ='PDC répartie-Dimension gaine'!E42 -> 550 | E9: ='PDC répartie-Dimension gaine'!K42 -> DN250 | F9: ='PDC répartie-Dimension gaine'!M42 -> 3.1123633 | G9: 5 | H9: 5 | I9: FKRS-EU / BE / 250 | K9: Aller sur le site et mettre largeur hauteur et debit et pour circulaire regarder ds le mt30
B10: 14.Distributeur | C10: ='PDC répartie-Dimension gaine'!B44 -> H'-J' | D10: ='Bouche GP-GE '!E22 -> 160 | E10: ='PDC répartie-Dimension gaine'!K44 -> 100x200 | F10: =D10/'PDC répartie-Dimension gaine'!L44/3600*1000000 -> 2.2222222 | G10: 4 | H10: 3 | I10: FKA2-EU/200x100x305
B11: 23.Trémis | C11: ='PDC répartie-Dimension gaine'!B28 -> H-B | D11: ='PDC répartie-Dimension gaine'!E28 -> 3637.5 | E11: ='PDC répartie-Dimension gaine'!K28 -> 300x1000 | F11: ='PDC répartie-Dimension gaine'!M28 -> 3.3680556 | G11: 19 | H11: 2 | I11: FKA2-EU / 1000x300x305
B12: 23.Trémis | C12: ='PDC répartie-Dimension gaine'!B29 -> H-F | D12: ='PDC répartie-Dimension gaine'!E29 -> 2286.5 | E12: ='PDC répartie-Dimension gaine'!K29 -> 200x800 | F12: ='PDC répartie-Dimension gaine'!M29 -> 3.9696181 | G12: 12 | H12: 4 | I12: FKA2-EU / 800x200x305 | K12: FKA2-EU | S.A. TROX Belgium/TROX Belgium N.V.
B13: 23.Trémis | C13: ='PDC répartie-Dimension gaine'!B51 -> N'-B' | D13: ='PDC répartie-Dimension gaine'!E51 -> 3350 | E13: ='PDC répartie-Dimension gaine'!K51 -> 300x1000 | F13: ='PDC répartie-Dimension gaine'!M51 -> 3.1018519 | G13: 19 | H13: 2 | I13: FKA2-EU /1000x300x305
B14: 23.Trémis | C14: ='PDC répartie-Dimension gaine'!B57 -> N'-E' | D14: ='PDC répartie-Dimension gaine'!E57 -> 1670 | E14: ='PDC répartie-Dimension gaine'!K57 -> 300x400 | F14: ='PDC répartie-Dimension gaine'!M57 -> 3.8657407 | G14: 11 | H14: 4 | I14: FKA2-EU / 400x300x305
B15: 23.Trémis-LT HVAC | C15: A''-B'' | D15: ='PDC répartie-Dimension gaine'!E62+'PDC répartie-Dimension gaine'!E61 -> 10944 | E15: ='PDC répartie-Dimension gaine'!K64 -> 600x800 | F15: ='PDC répartie-Dimension gaine'!M64 -> 6.3333333 | G15: 31 | H15: 9 | I15: FKA2-EU / 800x600x305
H16: =SUM(H7:H15) -> 34
A18: Pertes de charges singulière
B19: Coude à angle vif | C19: angle [°] | D19: 𝛏 | E19: v [m/s] | F19: ρ [kg/m3] | G19: ΔPdC [Pa] | I19: page 13 du mt30 pour xsi
B20: T | C20: 90 | D20: 1.2 | E20: ='PDC répartie-Dimension gaine'!M16 -> 3.0555556 | F20: 1.2 | G20: =(D20*F20*E20^2)/2 -> 6.7222222
B21: B | C21: 90 | D21: 1.2 | E21: ='PDC répartie-Dimension gaine'!M27 -> 3.3680556 | F21: 1.2 | G21: =(D21*F21*E21^2)/2 -> 8.1675347
B22: F | C22: 90 | D22: 1.2 | E22: ='PDC répartie-Dimension gaine'!M29 -> 3.9696181 | F22: 1.2 | G22: =(D22*F22*E22^2)/2 -> 11.345665
B23: M | C23: 90 | D23: 1.2 | E23: ='PDC répartie-Dimension gaine'!M20 -> 3.4396466 | F23: 1.2 | G23: =(D23*F23*E23^2)/2 -> 8.5184415
B24: E' | C24: 90 | D24: 1.2 | E24: ='PDC répartie-Dimension gaine'!M33 -> 2.3587963 | F24: 1.2 | G24: =(D24*F24*E24^2)/2 -> 4.0060224
B25: I' | C25: 90 | D25: 1.2 | E25: ='PDC répartie-Dimension gaine'!M58 -> 3.8657407 | F25: 1.2 | G25: =(D25*F25*E25^2)/2 -> 10.759645
B26: O' | C26: 90 | D26: 1.2 | E26: ='PDC répartie-Dimension gaine'!M48 -> 3.1123633 | F26: 1.2 | G26: =(D26*F26*E26^2)/2 -> 6.9745
B27: F' | C27: 90 | D27: 1.2 | E27: ='PDC répartie-Dimension gaine'!M56 -> 3.5111111 | F27: 1.2 | G27: =(D27*F27*E27^2)/2 -> 8.8760889
B28: W' | C28: 90 | D28: 1.2 | E28: ='PDC répartie-Dimension gaine'!M37 -> 2.8294212 | F28: 1.2 | G28: =(D28*F28*E28^2)/2 -> 5.7640496
B29: A'' | C29: 90 | D29: 1.2 | E29: ='PDC répartie-Dimension gaine'!M64 -> 6.3333333 | F29: 1.2 | G29: =(D29*F29*E29^2)/2 -> 28.88
B30: B'' | C30: 90 | D30: 1.2 | E30: ='PDC répartie-Dimension gaine'!M65 -> 6.3333333 | F30: 1.2 | G30: =(D30*F30*E30^2)/2 -> 28.88
G31: =SUM(G20:G30) -> 128.89417
B32: Derivations | C32: 𝛼 [°] | D32: A1/A3 | E32: q2/q3 | F32: 𝛏1 | G32: 𝛏2 | H32: v1 [m/s] | I32: v2 [m/s] | J32: ρ [kg/m3] | K32: ΔPdC 1[Pa] | L32: ΔPdC2 [Pa] | M32: ΔPdC tot [Pa]
B33: H | C33: 90 | D33: ='PDC répartie-Dimension gaine'!L62/'PDC répartie-Dimension gaine'!L28 -> 0.83333333 | E33: ='PDC répartie-Dimension gaine'!E29/'PDC répartie-Dimension gaine'!E28 -> 0.62859107 | F33: 0.2 | G33: 0.2 | H33: ='PDC répartie-Dimension gaine'!M62 -> 6.5822222 | I33: ='PDC répartie-Dimension gaine'!M29 -> 3.9696181 | J33: 1.2 | K33: =J33*H33^2*F33/2 -> 5.1990779 | L33: =J33*I33^2*G33/2 -> 1.8909441 | M33: =SUM(K33:L33) -> 7.090022 | N33: page 29 du mt 30
B34: V | C34: 90 | D34: ='PDC répartie-Dimension gaine'!L30/'PDC répartie-Dimension gaine'!L32 -> 1 | E34: ='PDC répartie-Dimension gaine'!E31/'PDC répartie-Dimension gaine'!E32 -> 0.42995622 | F34: 0 | G34: 0.4 | H34: ='PDC répartie-Dimension gaine'!M30 -> 3.9696181 | I34: ='PDC répartie-Dimension gaine'!M31 -> 3.8194444 | J34: 1.2 | K34: =J34*H34^2*F34/2 -> 0 | L34: =J34*I34^2*G34/2 -> 3.5011574 | M34: =SUM(K34:L34) -> 3.5011574
B35: E | C35: 90 | D35: ='PDC répartie-Dimension gaine'!L32/'PDC répartie-Dimension gaine'!L33 -> 1.3333333 | E35: ='PDC répartie-Dimension gaine'!E19/'PDC répartie-Dimension gaine'!E33 -> 0.56918548 | F35: 0.2 | G35: 0.3 | H35: ='PDC répartie-Dimension gaine'!M32 -> 2.7760417 | I35: ='PDC répartie-Dimension gaine'!M33 -> 2.3587963 | J35: 1.2 | K35: =J35*H35^2*F35/2 -> 0.92476888 | L35: =J35*I35^2*G35/2 -> 1.0015056 | M35: =K35+L35 -> 1.9262745
B36: I | C36: 90 | D36: ='PDC répartie-Dimension gaine'!L33/'PDC répartie-Dimension gaine'!L34 -> 1.5 | E36: ='PDC répartie-Dimension gaine'!E35/'PDC répartie-Dimension gaine'!E34 -> 0.055958549 | F36: 0 | G36: 0.4 | H36: ='PDC répartie-Dimension gaine'!M32 -> 2.7760417 | I36: ='PDC répartie-Dimension gaine'!M33 -> 2.3587963 | J36: 1.2 | K36: =J36*H36^2*F36/2 -> 0 | L36: =J36*I36^2*G36/2 -> 1.3353408 | M36: =K36+L36 -> 1.3353408
B37: C | C37: 90 | D37: ='PDC répartie-Dimension gaine'!L27/'PDC répartie-Dimension gaine'!L26 -> 1.25 | E37: ='PDC répartie-Dimension gaine'!E18/'PDC répartie-Dimension gaine'!E26 -> 0.18969747 | F37: -0.1 | G37: 0.6 | H37: ='PDC répartie-Dimension gaine'!M27 -> 3.3680556 | I37: ='PDC répartie-Dimension gaine'!M18 -> 2.6851852 | J37: 1.2 | K37: =J37*H37^2*F37/2 -> -0.68062789 | L37: =J37*I37^2*G37/2 -> 2.595679 | M37: =K37+L37 -> 1.9150511
B38: P | C38: 90 | D38: ='PDC répartie-Dimension gaine'!L26/'PDC répartie-Dimension gaine'!L23 -> 1.3333333 | E38: ='PDC répartie-Dimension gaine'!E24/'PDC répartie-Dimension gaine'!E26 -> 0.22485691 | F38: -0.1 | G38: 0.6 | H38: ='PDC répartie-Dimension gaine'!M26 -> 3.5387731 | I38: ='PDC répartie-Dimension gaine'!M24 -> 3.8194444 | J38: 1.2 | K38: =J38*H38^2*F38/2 -> -0.75137492 | L38: =J38*I38^2*G38/2 -> 5.2517361 | M38: =K38+L38 -> 4.5003612
B39: O | C39: 90 | D39: ='PDC répartie-Dimension gaine'!L23/'PDC répartie-Dimension gaine'!L25 -> 1.44 | E39: ='PDC répartie-Dimension gaine'!E17/'PDC répartie-Dimension gaine'!E25 -> 0.32033426 | F39: -0.1 | G39: 0.5 | H39: ='PDC répartie-Dimension gaine'!M23 -> 3.6574074 | I39: ='PDC répartie-Dimension gaine'!M17 -> 2.662037 | J39: 1.2 | K39: =J39*H39^2*F39/2 -> -0.80259774 | L39: =J39*I39^2*G39/2 -> 2.1259324 | M39: =K39+L39 -> 1.3233346
B40: R | C40: 90 | D40: ='PDC répartie-Dimension gaine'!L25/'PDC répartie-Dimension gaine'!L22 -> 1.0416667 | E40: ='PDC répartie-Dimension gaine'!E15/'PDC répartie-Dimension gaine'!E22 -> 0.96174863 | F40: 0.5 | G40: 0.4 | H40: ='PDC répartie-Dimension gaine'!M25 -> 3.9888889 | I40: ='PDC répartie-Dimension gaine'!M22 -> 2.1180556 | J40: 1.2 | K40: =J40*H40^2*F40/2 -> 4.7733704 | L40: =J40*I40^2*G40/2 -> 1.0766782 | M40: =K40+L40 -> 5.8500486
B41: N' | C41: 90 | D41: ='PDC répartie-Dimension gaine'!L61/'PDC répartie-Dimension gaine'!L51 -> 0.8 | E41: ='PDC répartie-Dimension gaine'!E57/'PDC répartie-Dimension gaine'!E51 -> 0.49850746 | F41: 0.1 | G41: 0.45 | H41: ='PDC répartie-Dimension gaine'!M61 -> 5.8101852 | I41: ='PDC répartie-Dimension gaine'!M57 -> 3.8657407 | J41: 1.2 | K41: =J41*H41^2*F41/2 -> 2.0254951 | L41: =J41*I41^2*G41/2 -> 4.0348669 | M41: =K41+L41 -> 6.060362
B42: B' | C42: 90 | D42: ='PDC répartie-Dimension gaine'!L51/'PDC répartie-Dimension gaine'!L53 -> 1.5 | E42: ='PDC répartie-Dimension gaine'!E52/'PDC répartie-Dimension gaine'!E53 -> 0.35902637 | F42: 0 | G42: 0.4 | H42: ='PDC répartie-Dimension gaine'!M51 -> 3.1018519 | I42: ='PDC répartie-Dimension gaine'!M52 -> 2.7314815 | J42: 1.2 | K42: =J42*H42^2*F42/2 -> 0 | L42: =J42*I42^2*G42/2 -> 1.7906379 | M42: =K42+L42 -> 1.7906379
B43: Y' | C43: 90 | D43: ='PDC répartie-Dimension gaine'!L54/'PDC répartie-Dimension gaine'!L55 -> 1.6666667 | E43: ='PDC répartie-Dimension gaine'!E50/'PDC répartie-Dimension gaine'!E55 -> 0.89265537 | F43: 0.45 | G43: 0.2 | H43: ='PDC répartie-Dimension gaine'!M54 -> 3.7222222 | I43: ='PDC répartie-Dimension gaine'!M50 -> 3.5111111 | J43: 1.2 | K43: =J43*H43^2*F43/2 -> 3.7408333 | L43: =J43*I43^2*G43/2 -> 1.4793481 | M43: =K43+L43 -> 5.2201815
B44: H' | C44: 90 | D44: ='PDC répartie-Dimension gaine'!L59/'PDC répartie-Dimension gaine'!L60 -> 1 | E44: ='PDC répartie-Dimension gaine'!E44/'PDC répartie-Dimension gaine'!E60 -> 0.10596026 | F44: 0 | G44: 0.7 | H44: ='PDC répartie-Dimension gaine'!M59 -> 3.8657407 | I44: ='PDC répartie-Dimension gaine'!M44 -> 2.2222222 | J44: 1.2 | K44: =J44*H44^2*F44/2 -> 0 | L44: =J44*I44^2*G44/2 -> 2.0740741 | M44: =K44+L44 -> 2.0740741
...

Sheet PDC total-Equilibrage
A1: Résumé des pertes de charges | B1: GP
B3: Trajet C''-N | G3: Trajet C''-K | L3: Trajet C''-G | Q3: Trajet C''-S | V3: Trajet C''-D
B4: Tronçons | C4: Pertes réparties [Pa] | D4: Pertes accessoires [Pa] | E4: Pertes de charges singulières [Pa] | G4: Tronçons | H4: Pertes réparties [Pa] | I4: Pertes accessoires [Pa] | J4: Pertes de charges singulières [Pa] | L4: Tronçons | M4: Pertes réparties [Pa] | N4: Pertes accessoires [Pa] | O4: Pertes de charges singulières [Pa] | Q4: Tronçons | R4: Pertes réparties [Pa] | S4: Pertes accessoires [Pa] | T4: Pertes de charges singulières [Pa] | V4: Tronçons | W4: Pertes réparties [Pa] | X4: Pertes accessoires [Pa] | Y4: Pertes de charges singulières [Pa]
B5: C''-B'' | C5: ='PDC répartie-Dimension gaine'!J65 -> 0.31 | E5: ='PDC singuliere-Clapet'!G30 -> 28.88 | G5: =B5 -> C''-B'' | H5: =C5 -> 0.31 | I5: =D5 -> 0 | J5: =E5 -> 28.88 | L5: =B5 -> C''-B'' | M5: =C5 -> 0.31 | N5: =D5 -> 0 | O5: =E5 -> 28.88 | Q5: =G5 -> C''-B'' | R5: =H5 -> 0.31 | S5: =I5 -> 0 | T5: =J5 -> 28.88 | V5: =B5 -> C''-B'' | W5: =C5 -> 0.31 | X5: =D5 -> 0 | Y5: =E5 -> 28.88
B6: B''-A'' | C6: ='PDC répartie-Dimension gaine'!J64 -> 1.86 | D6: ='PDC singuliere-Clapet'!$H$15 -> 9 | E6: ='PDC singuliere-Clapet'!G29 -> 28.88 | G6: =B6 -> B''-A'' | H6: =C6 -> 1.86 | I6: =D6 -> 9 | J6: =E6 -> 28.88 | L6: =B6 -> B''-A'' | M6: =C6 -> 1.86 | N6: =D6 -> 9 | O6: =E6 -> 28.88 | Q6: =G6 -> B''-A'' | R6: =H6 -> 1.86 | S6: =I6 -> 9 | T6: =J6 -> 28.88 | V6: =B6 -> B''-A'' | W6: =C6 -> 1.86 | X6: =D6 -> 9 | Y6: =E6 -> 28.88
B7: A"-A | C7: ='PDC répartie-Dimension gaine'!J63 -> 4.6748 | E7: ='PDC singuliere-Clapet'!M55 -> 24.909979 | G7: =B7 -> A"-A | H7: =C7 -> 4.6748 | I7: =D7 -> 0 | J7: =E7 -> 24.909979 | L7: =B7 -> A"-A | M7: =C7 -> 4.6748 | N7: =D7 -> 0 | O7: =E7 -> 24.909979 | Q7: =G7 -> A"-A | R7: =H7 -> 4.6748 | S7: =I7 -> 0 | T7: =J7 -> 24.909979 | V7: =B7 -> A"-A | W7: =C7 -> 4.6748 | X7: =D7 -> 0 | Y7: =E7 -> 24.909979
B8: A-H | C8: ='PDC répartie-Dimension gaine'!$J$62 -> 0.6716 | E8: ='PDC singuliere-Clapet'!$M$33 -> 7.090022 | G8: A-H | H8: ='PDC répartie-Dimension gaine'!$J$62 -> 0.6716 | J8: ='PDC singuliere-Clapet'!$M$33 -> 7.090022 | L8: A-H | M8: ='PDC répartie-Dimension gaine'!$J$62 -> 0.6716 | O8: ='PDC singuliere-Clapet'!$M$33 -> 7.090022 | Q8: A-H | R8: ='PDC répartie-Dimension gaine'!$J$62 -> 0.6716 | T8: ='PDC singuliere-Clapet'!$M$33 -> 7.090022 | V8: A-H | W8: ='PDC répartie-Dimension gaine'!$J$62 -> 0.6716 | Y8: ='PDC singuliere-Clapet'!$M$33 -> 7.090022
B9: H-F | C9: ='PDC répartie-Dimension gaine'!J29 -> 0.63 | D9: ='PDC singuliere-Clapet'!$H$12 -> 4 | E9: ='PDC singuliere-Clapet'!$G$22 -> 11.345665 | G9: H-F | H9: ='PDC répartie-Dimension gaine'!J29 -> 0.63 | I9: ='PDC singuliere-Clapet'!$H$12 -> 4 | J9: ='PDC singuliere-Clapet'!$G$22 -> 11.345665 | L9: H-F | M9: ='PDC répartie-Dimension gaine'!J29 -> 0.63 | N9: ='PDC singuliere-Clapet'!$H$12 -> 4 | O9: ='PDC singuliere-Clapet'!$G$22 -> 11.345665 | Q9: H-F | R9: ='PDC répartie-Dimension gaine'!J29 -> 0.63 | S9: ='PDC singuliere-Clapet'!$H$12 -> 4 | T9: ='PDC singuliere-Clapet'!$G$22 -> 11.345665 | V9: H-B | W9: ='PDC répartie-Dimension gaine'!J28 -> 0.651 | X9: ='PDC singuliere-Clapet'!$H$11 -> 2 | Y9: ='PDC singuliere-Clapet'!$G$21 -> 8.1675347
B10: F-V | C10: ='PDC répartie-Dimension gaine'!J30 -> 0.42 | E10: ='PDC singuliere-Clapet'!$M$34 -> 3.5011574 | G10: F-V | H10: ='PDC répartie-Dimension gaine'!J30 -> 0.42 | J10: ='PDC singuliere-Clapet'!$M$34 -> 3.5011574 | L10: F-V | M10: ='PDC répartie-Dimension gaine'!J30 -> 0.42 | O10: ='PDC singuliere-Clapet'!$M$34 -> 3.5011574 | Q10: F-V | R10: ='PDC répartie-Dimension gaine'!J30 -> 0.42 | T10: ='PDC singuliere-Clapet'!$M$34 -> 3.5011574 | V10: B-C | W10: ='PDC répartie-Dimension gaine'!J27 -> 0.21 | Y10: ='PDC singuliere-Clapet'!$M$37 -> 1.9150511
B11: V-E | C11: ='PDC répartie-Dimension gaine'!J32 -> 0.45 | E11: ='PDC singuliere-Clapet'!$M$35 -> 1.9262745 | G11: V-E | H11: ='PDC répartie-Dimension gaine'!J32 -> 0.45 | J11: ='PDC singuliere-Clapet'!$M$35 -> 1.9262745 | L11: V-E | M11: ='PDC répartie-Dimension gaine'!J32 -> 0.45 | O11: ='PDC singuliere-Clapet'!$M$35 -> 1.9262745 | Q11: V-S | R11: ='PDC répartie-Dimension gaine'!J31 -> 0.16875 | S11: ='Bouche GP-GE '!I17/2 -> 14.5 | V11: C-D | W11: ='PDC répartie-Dimension gaine'!J18 -> 1.9525 | X11: ='Bouche GP-GE '!H14 -> 20
B12: E-I | C12: ='PDC répartie-Dimension gaine'!J33 -> 0.324 | E12: ='PDC singuliere-Clapet'!$M$36 -> 1.3353408 | G12: E-I | H12: ='PDC répartie-Dimension gaine'!J33 -> 0.324 | J12: ='PDC singuliere-Clapet'!$M$36 -> 1.3353408 | L12: E-G | M12: ='PDC répartie-Dimension gaine'!J19 -> 1.9525 | N12: ='Bouche GP-GE '!H15 -> 20 | Q12: ΔPdC total[Pa] | T12: =MROUND(SUM(R5:T11),5) -> 140 | V12: ΔPdC total[Pa] | Y12: =MROUND(SUM(W5:Y11),5) -> 140
B13: I-L | C13: ='PDC répartie-Dimension gaine'!J34 -> 0.53625 | G13: I-K | H13: ='PDC répartie-Dimension gaine'!J35 -> 0.37625 | I13: ='PDC singuliere-Clapet'!$H$8+'Bouche GP-GE '!H18 -> 6 | L13: ΔPdC total[Pa] | O13: =MROUND(SUM(M5:O12),5) -> 150
B14: L-M | C14: ='PDC répartie-Dimension gaine'!J21 -> 0.7056 | E14: ='PDC singuliere-Clapet'!$G$23 -> 8.5184415 | G14: ΔPdC total[Pa] | J14: =MROUND(SUM(H5:J13),5) -> 135
B15: M-N | C15: ='PDC répartie-Dimension gaine'!J20 -> 1.674 | D15: ='Bouche GP-GE '!H16 -> 16
B16: ΔPdC total[Pa] | E16: =MROUND(SUM(C5:E15),5) -> 160
B18: Trajet C''-U | G18: Trajet C''-Q | L18: Trajet C''-T" | Q18: Trajet C''-Z | V18: Trajet C''-X
B19: Tronçons | C19: Pertes réparties [Pa] | D19: Pertes accessoires [Pa] | E19: Pertes de charges singulières [Pa] | G19: Tronçons | H19: Pertes réparties [Pa] | I19: Pertes accessoires [Pa] | J19: Pertes de charges singulières [Pa] | L19: Tronçons | M19: Pertes réparties [Pa] | N19: Pertes accessoires [Pa] | O19: Pertes de charges singulières [Pa] | Q19: Tronçons | R19: Pertes réparties [Pa] | S19: Pertes accessoires [Pa] | T19: Pertes de charges singulières [Pa] | V19: Tronçons | W19: Pertes réparties [Pa] | X19: Pertes accessoires [Pa] | Y19: Pertes de charges singulières [Pa]
B20: =B5 -> C''-B'' | C20: =C5 -> 0.31 | D20: =D5 -> 0 | E20: =E5 -> 28.88 | G20: =B5 -> C''-B'' | H20: =C5 -> 0.31 | I20: =D5 -> 0 | J20: =E5 -> 28.88 | L20: =G5 -> C''-B'' | M20: =H5 -> 0.31 | N20: =I5 -> 0 | O20: =J5 -> 28.88 | Q20: =B5 -> C''-B'' | R20: =C5 -> 0.31 | S20: =D5 -> 0 | T20: =E5 -> 28.88 | V20: =B5 -> C''-B'' | W20: =C5 -> 0.31 | X20: =D5 -> 0 | Y20: =E5 -> 28.88
B21: =B6 -> B''-A'' | C21: =C6 -> 1.86 | D21: =D6 -> 9 | E21: =E6 -> 28.88 | G21: =B6 -> B''-A'' | H21: =C6 -> 1.86 | I21: =D6 -> 9 | J21: =E6 -> 28.88 | L21: =G6 -> B''-A'' | M21: =H6 -> 1.86 | N21: =I6 -> 9 | O21: =J6 -> 28.88 | Q21: =B6 -> B''-A'' | R21: =C6 -> 1.86 | S21: =D6 -> 9 | T21: =E6 -> 28.88 | V21: =B6 -> B''-A'' | W21: =C6 -> 1.86 | X21: =D6 -> 9 | Y21: =E6 -> 28.88
B22: =B7 -> A"-A | C22: =C7 -> 4.6748 | D22: =D7 -> 0 | E22: =E7 -> 24.909979 | G22: =B7 -> A"-A | H22: =C7 -> 4.6748 | I22: =D7 -> 0 | J22: =E7 -> 24.909979 | L22: =G7 -> A"-A | M22: =H7 -> 4.6748 | N22: =I7 -> 0 | O22: =J7 -> 24.909979 | Q22: =B7 -> A"-A | R22: =C7 -> 4.6748 | S22: =D7 -> 0 | T22: =E7 -> 24.909979 | V22: =B7 -> A"-A | W22: =C7 -> 4.6748 | X22: =D7 -> 0 | Y22: =E7 -> 24.909979
B23: A-H | C23: ='PDC répartie-Dimension gaine'!$J$62 -> 0.6716 | E23: ='PDC singuliere-Clapet'!$M$33 -> 7.090022 | G23: A-H | H23: ='PDC répartie-Dimension gaine'!$J$62 -> 0.6716 | J23: ='PDC singuliere-Clapet'!$M$33 -> 7.090022 | L23: A-H | M23: ='PDC répartie-Dimension gaine'!$J$62 -> 0.6716 | O23: ='PDC singuliere-Clapet'!$M$33 -> 7.090022 | Q23: A-H | R23: ='PDC répartie-Dimension gaine'!$J$62 -> 0.6716 | T23: ='PDC singuliere-Clapet'!$M$33 -> 7.090022 | V23: A-H | W23: ='PDC répartie-Dimension gaine'!$J$62 -> 0.6716 | Y23: ='PDC singuliere-Clapet'!$M$33 -> 7.090022
B24: H-B | C24: ='PDC répartie-Dimension gaine'!J28 -> 0.651 | D24: =X9 -> 2 | E24: =Y9 -> 8.1675347 | G24: H-B | H24: ='PDC répartie-Dimension gaine'!J28 -> 0.651 | I24: =X9 -> 2 | J24: =Y9 -> 8.1675347 | L24: H-B | M24: ='PDC répartie-Dimension gaine'!J28 -> 0.651 | N24: =X9 -> 2 | O24: =Y9 -> 8.1675347 | Q24: H-B | R24: ='PDC répartie-Dimension gaine'!J28 -> 0.651 | S24: =X9 -> 2 | T24: =Y9 -> 8.1675347 | V24: H-B | W24: ='PDC répartie-Dimension gaine'!J28 -> 0.651 | X24: =X9 -> 2 | Y24: =Y9 -> 8.1675347
B25: B-C | C25: ='PDC répartie-Dimension gaine'!J27 -> 0.21 | E25: =Y10 -> 1.9150511 | G25: B-C | H25: ='PDC répartie-Dimension gaine'!J27 -> 0.21 | J25: =Y10 -> 1.9150511 | L25: B-C | M25: ='PDC répartie-Dimension gaine'!J27 -> 0.21 | O25: =Y10 -> 1.9150511 | Q25: B-C | R25: ='PDC répartie-Dimension gaine'!J27 -> 0.21 | T25: =Y10 -> 1.9150511 | V25: B-C | W25: ='PDC répartie-Dimension gaine'!J27 -> 0.21 | Y25: =Y10 -> 1.9150511
B26: C-P | C26: ='PDC répartie-Dimension gaine'!J26 -> 1.96 | E26: ='PDC singuliere-Clapet'!$M$38 -> 4.5003612 | G26: C-P | H26: ='PDC répartie-Dimension gaine'!J26 -> 1.96 | J26: =E26 -> 4.5003612 | L26: C-P | M26: ='PDC répartie-Dimension gaine'!J26 -> 1.96 | O26: =E26 -> 4.5003612 | Q26: C-P | R26: ='PDC répartie-Dimension gaine'!J26 -> 1.96 | T26: =E26 -> 4.5003612 | V26: C-P | W26: ='PDC répartie-Dimension gaine'!J26 -> 1.96 | Y26: =E26 -> 4.5003612
B27: P-U | C27: ='PDC répartie-Dimension gaine'!J24 -> 0.16875 | D27: ='Bouche GP-GE '!I17/2 -> 14.5 | G27: P-O | H27: ='PDC répartie-Dimension gaine'!J23 -> 0.5775 | J27: ='PDC singuliere-Clapet'!$M$39 -> 1.3233346 | L27: P-O | M27: ='PDC répartie-Dimension gaine'!J23 -> 0.5775 | O27: ='PDC total-Equilibrage'!J27 -> 1.3233346 | Q27: P-O | R27: ='PDC répartie-Dimension gaine'!J23 -> 0.5775 | T27: =J27 -> 1.3233346 | V27: P-O | W27: ='PDC répartie-Dimension gaine'!J23 -> 0.5775 | Y27: =J27 -> 1.3233346
B28: ΔPdC total[Pa] | E28: =MROUND(SUM(C20:E27),5) -> 140 | G28: O-Q | H28: ='PDC répartie-Dimension gaine'!J17 -> 1.9525 | I28: ='Bouche GP-GE '!H13 -> 19 | L28: O-R | M28: ='PDC répartie-Dimension gaine'!J25 -> 0.6875 | O28: ='PDC singuliere-Clapet'!$M$40 -> 5.8500486 | Q28: O-R | R28: ='PDC répartie-Dimension gaine'!J25 -> 0.6875 | T28: =O28 -> 5.8500486 | V28: O-R | W28: ='PDC répartie-Dimension gaine'!J25 -> 0.6875 | Y28: =O28 -> 5.8500486
G29: ΔPdC total[Pa] | J29: =MROUND(SUM(H20:J28),5) -> 150 | L29: R-T | M29: ='PDC répartie-Dimension gaine'!J15 -> 0.732 | O29: ='PDC singuliere-Clapet'!$G$20 -> 6.7222222 | Q29: R-W | R29: ='PDC répartie-Dimension gaine'!J22 -> 1.440625 | T29: ='PDC singuliere-Clapet'!$M$54 -> 69.658716 | V29: R-W | W29: ='PDC répartie-Dimension gaine'!J22 -> 1.440625 | Y29: =T29 -> 69.658716
L30: T-T" | M30: ='PDC répartie-Dimension gaine'!J16 -> 1.92 | N30: ='Bouche GP-GE '!H12 -> 12.5 | Q30: W-Z | R30: ='PDC répartie-Dimension gaine'!J14 -> 3.025 | S30: ='Bouche GP-GE '!H10 -> 20 | V30: W-X | W30: ='PDC répartie-Dimension gaine'!J13 -> 1.3068 | X30: ='Bouche GP-GE '!H9+'PDC singuliere-Clapet'!$H$7 -> 26
L31: ΔPdC total[Pa] | O31: =MROUND(SUM(M20:O30),5) -> 155 | Q31: ΔPdC total[Pa] | T31: =MROUND(SUM(R20:T30),5) -> 230 | V31: ΔPdC total[Pa] | Y31: =MROUND(SUM(W20:Y30),5) -> 235
U32: m | W32: =(SUM(W20:W30)/Y31)*100 -> 6.1063085 | X32: =(SUM(X20:X30)/Y31)*100 -> 15.744681 | Y32: =(SUM(Y20:Y30)/Y31)*100 -> 77.095765
B34: Trajet C''-X' | G34: Trajet C''-U' | L34: Trajet C''-R' | Q34: Trajet C''-M' | V34: Trajet C''-J'
B35: Tronçons | C35: Pertes réparties [Pa] | D35: Pertes accessoires [Pa] | E35: Pertes de charges singulières [Pa] | G35: Tronçons | H35: Pertes réparties [Pa] | I35: Pertes accessoires [Pa] | J35: Pertes de charges singulières [Pa] | L35: Tronçons | M35: Pertes réparties [Pa] | N35: Pertes accessoires [Pa] | O35: Pertes de charges singulières [Pa] | Q35: Tronçons | R35: Pertes réparties [Pa] | S35: Pertes accessoires [Pa] | T35: Pertes de charges singulières [Pa] | V35: Tronçons | W35: Pertes réparties [Pa] | X35: Pertes accessoires [Pa] | Y35: Pertes de charges singulières [Pa]
B36: C''-B'' | C36: ='PDC répartie-Dimension gaine'!J65 -> 0.31 | E36: ='PDC singuliere-Clapet'!G30 -> 28.88 | G36: C''-B'' | H36: =C36 -> 0.31 | I36: =D36 -> 0 | J36: =E36 -> 28.88 | L36: C''-B'' | M36: =C36 -> 0.31 | N36: =D36 -> 0 | O36: =E36 -> 28.88 | Q36: C''-B'' | R36: =C36 -> 0.31 | S36: =D36 -> 0 | T36: =E36 -> 28.88 | V36: C''-B'' | W36: =C36 -> 0.31 | X36: =D36 -> 0 | Y36: =E36 -> 28.88
B37: B''-A'' | C37: ='PDC répartie-Dimension gaine'!J64 -> 1.86 | D37: =D6 -> 9 | E37: ='PDC singuliere-Clapet'!G29 -> 28.88 | G37: B''-A'' | H37: =C37 -> 1.86 | I37: =D37 -> 9 | J37: =E37 -> 28.88 | L37: B''-A'' | M37: =C37 -> 1.86 | N37: =D37 -> 9 | O37: =E37 -> 28.88 | Q37: B''-A'' | R37: =C37 -> 1.86 | S37: =D37 -> 9 | T37: =E37 -> 28.88 | V37: B''-A'' | W37: =C37 -> 1.86 | X37: =D37 -> 9 | Y37: =E37 -> 28.88
B38: A"-A | C38: ='PDC répartie-Dimension gaine'!J63 -> 4.6748 | E38: ='PDC singuliere-Clapet'!M55 -> 24.909979 | G38: A"-A | H38: =C38 -> 4.6748 | I38: =D38 -> 0 | J38: =E38 -> 24.909979 | L38: A"-A | M38: =C38 -> 4.6748 | N38: =D38 -> 0 | O38: =E38 -> 24.909979 | Q38: A"-A | R38: =C38 -> 4.6748 | S38: =D38 -> 0 | T38: =E38 -> 24.909979 | V38: A"-A | W38: =C38 -> 4.6748 | X38: =D38 -> 0 | Y38: =E38 -> 24.909979
B39: A-N' | C39: ='PDC répartie-Dimension gaine'!J61 -> 0.7154 | E39: ='PDC singuliere-Clapet'!$M$41 -> 6.060362 | G39: A-N' | H39: ='PDC répartie-Dimension gaine'!J61 -> 0.7154 | J39: =E39 -> 6.060362 | L39: A-N' | M39: ='PDC répartie-Dimension gaine'!J61 -> 0.7154 | O39: =E39 -> 6.060362 | Q39: A-N' | R39: ='PDC répartie-Dimension gaine'!J61 -> 0.7154 | T39: =E39 -> 6.060362 | V39: A-N' | W39: ='PDC répartie-Dimension gaine'!J61 -> 0.7154 | Y39: =J39 -> 6.060362
B40: N'-E' | C40: ='PDC répartie-Dimension gaine'!J57 -> 0.684 | D40: ='PDC singuliere-Clapet'!$H$14 -> 4 | E40: ='PDC singuliere-Clapet'!$G$24 -> 4.0060224 | G40: N'-E' | H40: ='PDC répartie-Dimension gaine'!J57 -> 0.684 | I40: =D40 -> 4 | J40: =E40 -> 4.0060224 | L40: N'-E' | M40: ='PDC répartie-Dimension gaine'!J57 -> 0.684 | N40: =D40 -> 4 | O40: =E39 -> 6.060362 | Q40: N'-E' | R40: ='PDC répartie-Dimension gaine'!J57 -> 0.684 | S40: =D40 -> 4 | T40: =E40 -> 4.0060224 | V40: N'-E' | W40: ='PDC répartie-Dimension gaine'!J57 -> 0.684 | X40: =D40 -> 4 | Y40: =E40 -> 4.0060224
B41: E'-I' | C41: ='PDC répartie-Dimension gaine'!J58 -> 2.808 | E41: ='PDC singuliere-Clapet'!$G$25 -> 10.759645 | G41: E'-I' | H41: ='PDC répartie-Dimension gaine'!J58 -> 2.808 | J41: =E41 -> 10.759645 | L41: E'-I' | M41: ='PDC répartie-Dimension gaine'!J58 -> 2.808 | O41: =E41 -> 10.759645 | Q41: E'-I' | R41: ='PDC répartie-Dimension gaine'!J58 -> 2.808 | T41: =E41 -> 10.759645 | V41: E'-I' | W41: ='PDC répartie-Dimension gaine'!J58 -> 2.808 | Y41: =E41 -> 10.759645
B42: I'-H' | C42: ='PDC répartie-Dimension gaine'!J59 -> 0.7296 | E42: ='PDC singuliere-Clapet'!$M$44 -> 2.0740741 | G42: I'-H' | H42: ='PDC répartie-Dimension gaine'!J59 -> 0.7296 | J42: =E42 -> 2.0740741 | L42: I'-H' | M42: ='PDC répartie-Dimension gaine'!J59 -> 0.7296 | O42: =E42 -> 2.0740741 | Q42: I'-H' | R42: ='PDC répartie-Dimension gaine'!J59 -> 0.7296 | T42: =E42 -> 2.0740741 | V42: I'-H' | W42: ='PDC répartie-Dimension gaine'!J59 -> 0.7296 | Y42: =E42 -> 2.0740741
B43: H'-K' | C43: ='PDC répartie-Dimension gaine'!J60 -> 0.55 | G43: H'-K' | H43: ='PDC répartie-Dimension gaine'!J60 -> 0.55 | L43: H'-K' | M43: ='PDC répartie-Dimension gaine'!J60 -> 0.55 | Q43: H'-K' | R43: ='PDC répartie-Dimension gaine'!J60 -> 0.55 | V43: H'-J' | W43: ='PDC répartie-Dimension gaine'!J44 -> 1.185 | X43: ='Bouche GP-GE '!H22+'PDC singuliere-Clapet'!$H$10 -> 24
...

Sheet Ventilateur
B2: GP
B4: Organe de la gaine
B5: Elément | D5: ΔPdC [Pa]
B6: Filtre | D6: 212
B7: Batterie post chauffe | D7: 74
B8: Batterie froide | D8: 69
B9: Batterie post chauffe | D9: 80
B10: Total | D10: =SUM(D6:D9) -> 435
B12: GE
B14: Organe de la gaine
B15: Elément | C15: ΔPdC [Pa]
B16: Filtre | C16: 175
B17: Total | C17: =C16 -> 175
B24: RAJOUTER 75 Pa POUR LA PRISSE D'AIR DE L'EXTERIEUR VERS LA CTA
B26: augmenter les pertes de charges avec un coefficient entre 10 et 20% au cas ou ya eu des oublies
C28: Débit été [m3/h] | D28: Débit hiver [m3/h] | E28: ΔPdC total [Pa] | F28: ΔPdC total majore [Pa] | G28: Modèle | H28: Rendement [%] | I28: Puissances [kW]
B30: GP | C30: ='PDC répartie-Dimension gaine'!E127 -> 10944 | D30: =Données!I24 -> 6749 | E30: =D10+'PDC total-Equilibrage'!E72+75 -> 745 | F30: =E30+E30*0.15 -> 856.75 | G30: VZR 71-0355 | H30: 69 | I30: 3.5
B31: GE | C31: ='PDC répartie-Dimension gaine'!E127 -> 10944 | D31: =Données!I24 -> 6749 | E31: =C17+'PDC total-Equilibrage'!E166+75 -> 405 | F31: =E31+E31*0.15 -> 465.75 | G31: VZR 71-0355 | H31: 55 | I31: 2.4
B32: GE | C32: ='PDC répartie-Dimension gaine'!E150 -> 250 | D32: ='PDC répartie-Dimension gaine'!E150 -> 250 | E32: =C17+'PDC total-Equilibrage'!E167+75 -> 250 | F32: =E32+E32*0.15 -> 287.5
E33: branche + batterie +filtre

Sheet PRESENTATION
E2: BOUCHE | F2: DEBIT | G2: SOMME PDC SING | H2: SOMME PDC LINE | I2: SOMME PDC accesoires | J2: PDC A EQUILIBRER | K2: SOMME TOTAL PDC ET ELLES DOIVENT ETRE PAREILS POUR TOUTES LES BOUCEHS
B4: chaque bouche | D4: debit
D5: pdc
D6: partie lineraire
D7: accessoir
D9: calcul global avec choix de ventilo et ensuite expliquer comment on a realiser l'equilibrage
D10: comment on a choix la pdc
D11: comment on a reprensenter l'installation
D12: expliquer et montrer la branche la plus contraingnante
D13: detail du calcul de cette branche
D14: et expliquer le detail du calcul qu'on a fait sur les autre branche pour l'equilibrage
D15: choix du ventilo avec pdc de l'installation mais aussi des composant a l'interieur du grp
D16: Dans branche dimensionnante donner pourcentage des pertes de charges
C22: GP | L22: GE
C23: Bouche | D23: Débit | E23: Pertes réparties [Pa] | F23: Pertes accessoires [Pa] | G23: Pertes de charges singulières [Pa] | H23: Pertes de charges à équilibrer [Pa] | I23: Somme totale des pertes de charges [Pa] | L23: Bouche | M23: Débit | N23: Pertes réparties [Pa] | O23: Pertes accessoires [Pa] | P23: Pertes de charges singulières [Pa] | Q23: Pertes de charges à équilibrer [Pa] | R23: Somme totale des pertes de charges [Pa]
C24: 1.COFFRE FORT | D24: ='Bouche GP-GE '!E9 -> 550 | E24: =SUM('PDC total-Equilibrage'!W20:W30) -> 14.349825 | F24: =SUM('PDC total-Equilibrage'!X20:X30) -> 37 | G24: =SUM('PDC total-Equilibrage'!Y20:Y29) -> 181.17505 | H24: ='PDC total-Equilibrage'!D84 -> 0 | I24: =MROUND(SUM(E24:H24),5) -> 235 | L24: 1.COFFRE FORT | M24: =D24 -> 550 | N24: =SUM('PDC total-Equilibrage'!R116:R128) -> 13.873 | O24: =SUM('PDC total-Equilibrage'!S116:S128) -> 23 | P24: =SUM('PDC total-Equilibrage'!T116:T128) -> 107.29885 | Q24: ='PDC total-Equilibrage'!D177 -> 10 | R24: =MROUND(SUM(N24:Q24),5) -> 155
C25: 2.KITCHENETTE | D25: ='Bouche GP-GE '!E10 -> 365 | E25: =SUM('PDC total-Equilibrage'!R20:R30) -> 16.068025 | F25: =SUM('PDC total-Equilibrage'!S20:S30) -> 31 | G25: =SUM('PDC total-Equilibrage'!T20:T29) -> 181.17505 | H25: ='PDC total-Equilibrage'!D83 -> 5 | I25: =MROUND(SUM(E25:H25),5) -> 235 | L25: 2.KITCHENETTE | M25: =D25 -> 365 | N25: =SUM('PDC total-Equilibrage'!W116:W128) -> 14.978 | O25: =SUM('PDC total-Equilibrage'!X116:X128) -> 17.5 | P25: =SUM('PDC total-Equilibrage'!Y116:Y128) -> 107.29885 | Q25: ='PDC total-Equilibrage'!D178 -> 15 | R25: =MROUND(SUM(N25:Q25),5) -> 155
C26: 4.Bureau 4 | D26: ='Bouche GP-GE '!E12 -> 880 | E26: =SUM('PDC total-Equilibrage'!M20:M30) -> 14.2544 | F26: =SUM('PDC total-Equilibrage'!N20:N30) -> 23.5 | G26: =SUM('PDC total-Equilibrage'!O20:O29) -> 118.23855 | H26: ='PDC total-Equilibrage'!D82 -> 80 | I26: =MROUND(SUM(E26:H26),5) -> 235 | L26: 4.Bureau 4 | M26: =D26 -> 880 | N26: =SUM('PDC total-Equilibrage'!M116:M127) -> 11.423 | O26: =SUM('PDC total-Equilibrage'!N116:N127) -> 15.25 | P26: =SUM('PDC total-Equilibrage'!O116:O127) -> 108.46127 | Q26: ='PDC total-Equilibrage'!D176 -> 20 | R26: =MROUND(SUM(N26:Q26),5) -> 155
C27: 5.Bureau5 | D27: ='Bouche GP-GE '!E13 -> 575 | E27: =SUM('PDC total-Equilibrage'!H20:H28) -> 12.8674 | F27: =SUM('PDC total-Equilibrage'!I20:I28) -> 30 | G27: =SUM('PDC total-Equilibrage'!J20:J27) -> 105.66628 | H27: ='PDC total-Equilibrage'!D81 -> 85 | I27: =MROUND(SUM(E27:H27),5) -> 235 | L27: 5.Bureau5 | M27: =D27 -> 575 | N27: =SUM('PDC total-Equilibrage'!C116:C125) -> 9.331 | O27: =SUM('PDC total-Equilibrage'!D116:D125) -> 18.75 | P27: =SUM('PDC total-Equilibrage'!E116:E125) -> 79.84609 | Q27: ='PDC total-Equilibrage'!D174 -> 45 | R27: =MROUND(SUM(N27:Q27),5) -> 155
C28: 6.Bureau 6 | D28: ='Bouche GP-GE '!E14 -> 580 | E28: =SUM('PDC total-Equilibrage'!W5:W11) -> 10.3299 | F28: =SUM('PDC total-Equilibrage'!X5:X11) -> 31 | G28: =SUM('PDC total-Equilibrage'!Y5:Y10) -> 99.842587 | H28: ='PDC total-Equilibrage'!D79 -> 95 | I28: =MROUND(SUM(E28:H28),5) -> 235 | L28: 6.Bureau 6 | M28: =D28 -> 580 | N28: =SUM('PDC total-Equilibrage'!W100:W108) -> 8.946 | O28: =SUM('PDC total-Equilibrage'!X100:X108) -> 18.8 | P28: =SUM('PDC total-Equilibrage'!Y100:Y108) -> 72.713212 | Q28: ='PDC total-Equilibrage'!D173 -> 55 | R28: =MROUND(SUM(N28:Q28),5) -> 155
C29: 7.Bureau 7 | D29: ='Bouche GP-GE '!E15 -> 580 | E29: =SUM('PDC total-Equilibrage'!M5:M12) -> 10.9689 | F29: =SUM('PDC total-Equilibrage'!N5:N12) -> 33 | G29: =SUM('PDC total-Equilibrage'!O5:O11) -> 106.5331 | H29: ='PDC total-Equilibrage'!D77 -> 85 | I29: =MROUND(SUM(E29:H29),5) -> 235 | L29: 7.Bureau 7 | M29: =D29 -> 580 | N29: =SUM('PDC total-Equilibrage'!M100:M109) -> 13.6215 | O29: =SUM('PDC total-Equilibrage'!N100:N109) -> 20.8 | P29: =SUM('PDC total-Equilibrage'!O100:O109) -> 62.973635 | Q29: ='PDC total-Equilibrage'!D171 -> 60 | R29: =MROUND(SUM(N29:Q29),5) -> 155
C30: 8.SDR | D30: ='Bouche GP-GE '!E16 -> 965 | E30: =SUM('PDC total-Equilibrage'!C5:C15) -> 12.25625 | F30: =SUM('PDC total-Equilibrage'!D5:D15) -> 29 | G30: =SUM('PDC total-Equilibrage'!E5:E15) -> 116.38688 | H30: ='PDC total-Equilibrage'!D75 -> 75 | I30: =MROUND(SUM(E30:H30),5) -> 235 | L30: 8.SDR | M30: =D30 -> 965 | N30: =SUM('PDC total-Equilibrage'!C100:C110) -> 13.4435 | O30: =SUM('PDC total-Equilibrage'!D100:D110) -> 18.5 | P30: =SUM('PDC total-Equilibrage'!E100:E110) -> 69.667336 | Q30: ='PDC total-Equilibrage'!D169 -> 55 | R30: =MROUND(SUM(N30:Q30),5) -> 155
C31: 9.Couloir droite (V-S) | D31: ='Bouche GP-GE '!E17/2 -> 687.5 | E31: =SUM('PDC total-Equilibrage'!R5:R11) -> 8.73515 | F31: =SUM('PDC total-Equilibrage'!S5:S11) -> 27.5 | G31: =SUM('PDC total-Equilibrage'!T5:T11) -> 104.60682 | H31: ='PDC total-Equilibrage'!D78 -> 95 | I31: =MROUND(SUM(E31:H31),5) -> 235 | L31: 9.Couloir droite (TT-UU) | M31: =D31 -> 687.5 | N31: =SUM('PDC total-Equilibrage'!R100:R108) -> 12.7115 | O31: =SUM('PDC total-Equilibrage'!S100:S108) -> 25.5 | P31: =SUM('PDC total-Equilibrage'!T100:T108) -> 59.771562 | Q31: ='PDC total-Equilibrage'!D172 -> 55 | R31: =MROUND(SUM(N31:Q31),5) -> 155
C32: 9.Couloir droite (P-U) | D32: =D31 -> 687.5 | E32: =SUM('PDC total-Equilibrage'!C20:C27) -> 10.50615 | F32: =SUM('PDC total-Equilibrage'!D20:D27) -> 25.5 | G32: =SUM('PDC total-Equilibrage'!E20:'PDC total-Equilibrage'!E20:E27) -> 104.34295 | H32: ='PDC total-Equilibrage'!D80 -> 95 | I32: =MROUND(SUM(E32:H32),5) -> 235 | L32: 9.Couloir droite (KK-LL) | M32: =D32 -> 687.5 | N32: =SUM('PDC total-Equilibrage'!H116:H126) -> 9.863 | O32: =SUM('PDC total-Equilibrage'!I116:I126) -> 23.5 | P32: =SUM('PDC total-Equilibrage'!J116:J126) -> 91.939314 | Q32: ='PDC total-Equilibrage'!D175 -> 30 | R32: =MROUND(SUM(N32:Q32),5) -> 155
C33: 10.Approvisionnement | D33: ='Bouche GP-GE '!E18 -> 54 | E33: =SUM('PDC total-Equilibrage'!H5:H13) -> 9.71665 | F33: =SUM('PDC total-Equilibrage'!I5:I13) -> 19 | G33: =SUM('PDC total-Equilibrage'!J5:J12) -> 107.86844 | H33: ='PDC total-Equilibrage'!D76 -> 100 | I33: =MROUND(SUM(E33:H33),5) -> 235 | L33: 10.Approvisionnement | M33: =D33 -> 54 | N33: =SUM('PDC total-Equilibrage'!H100:H111) -> 13.0407 | O33: =SUM('PDC total-Equilibrage'!I100:I111) -> 20 | P33: =SUM('PDC total-Equilibrage'!J100:J111) -> 70.072336 | Q33: ='PDC total-Equilibrage'!D170 -> 50 | R33: =MROUND(SUM(N33:Q33),5) -> 155
C34: 11. Entrée droite | D34: ='Bouche GP-GE '!E19 -> 125 | E34: =SUM('PDC total-Equilibrage'!C36:C52) -> 20.4113 | F34: =SUM('PDC total-Equilibrage'!D36:D52) -> 30.5 | G34: =SUM('PDC total-Equilibrage'!E36:E52) -> 131.08194 | H34: ='PDC total-Equilibrage'!D85 -> 55 | I34: =MROUND(SUM(E34:H34),5) -> 235 | L34: 11. Entrée droite | M34: =D34 -> 125 | N34: =SUM('PDC total-Equilibrage'!C133:C147) -> 20.3635 | O34: =SUM('PDC total-Equilibrage'!D133:D147) -> 27 | P34: =SUM('PDC total-Equilibrage'!E133:E147) -> 107.51636 | Q34: ='PDC total-Equilibrage'!D179 -> 0 | R34: =MROUND(SUM(N34:Q34),5) -> 155
C35: 12. Entrée princ | D35: ='Bouche GP-GE '!E20 -> 300 | E35: =SUM('PDC total-Equilibrage'!H36:H50) -> 17.2143 | F35: =SUM('PDC total-Equilibrage'!I36:I50) -> 40.5 | G35: =SUM('PDC total-Equilibrage'!J36:J50) -> 125.31789 | H35: ='PDC total-Equilibrage'!D86 -> 50 | I35: =MROUND(SUM(E35:H35),5) -> 235 | L35: 12. Entrée princ | M35: =D35 -> 300 | N35: =SUM('PDC total-Equilibrage'!H133:H146) -> 18.613 | O35: =SUM('PDC total-Equilibrage'!I133:I146) -> 26 | P35: =SUM('PDC total-Equilibrage'!J133:J146) -> 101.75231 | Q35: ='PDC total-Equilibrage'!D180 -> 10 | R35: =MROUND(SUM(N35:Q35),5) -> 155
C36: 13. Entrée gauche | D36: ='Bouche GP-GE '!E21 -> 125 | E36: =SUM('PDC total-Equilibrage'!M36:M48) -> 16.1093 | F36: =SUM('PDC total-Equilibrage'!N36:N48) -> 35.5 | G36: =SUM('PDC total-Equilibrage'!O36:O48) -> 121.86934 | H36: ='PDC total-Equilibrage'!D87 -> 60 | I36: =MROUND(SUM(E36:H36),5) -> 235 | L36: 13. Entrée gauche | M36: =D36 -> 125 | N36: =SUM('PDC total-Equilibrage'!M133:M145) -> 14.731 | O36: =SUM('PDC total-Equilibrage'!N133:N145) -> 27 | P36: =SUM('PDC total-Equilibrage'!O133:O145) -> 100.90797 | Q36: ='PDC total-Equilibrage'!D181 -> 10 | R36: =MROUND(SUM(N36:Q36),5) -> 155
C37: 14.Distrib | D37: ='Bouche GP-GE '!E22 -> 160 | E37: =SUM('PDC total-Equilibrage'!W36:W43) -> 12.9668 | F37: =SUM('PDC total-Equilibrage'!X36:X43) -> 37 | G37: =SUM('PDC total-Equilibrage'!Y36:Y43) -> 105.57008 | H37: ='PDC total-Equilibrage'!D89 -> 80 | I37: =MROUND(SUM(E37:H37),5) -> 235 | L37: 14.Distrib | M37: =D37 -> 160 | N37: =SUM('PDC total-Equilibrage'!W133:W143) -> 16.48 | O37: =SUM('PDC total-Equilibrage'!X133:X143) -> 27.5 | P37: =SUM('PDC total-Equilibrage'!Y133:Y143) -> 81.847159 | Q37: ='PDC total-Equilibrage'!D183 -> 30 | R37: =MROUND(SUM(N37:Q37),5) -> 155
C38: 15.Secretariat | D38: ='Bouche GP-GE '!E23 -> 960 | E38: =SUM('PDC total-Equilibrage'!R36:R45) -> 14.2478 | F38: =SUM('PDC total-Equilibrage'!S36:S45) -> 25.5 | G38: =SUM('PDC total-Equilibrage'!T36:T45) -> 111.02002 | H38: ='PDC total-Equilibrage'!D88 -> 85 | I38: =MROUND(SUM(E38:H38),5) -> 235 | L38: 15.Secretariat | M38: =D38 -> 960 | N38: =SUM('PDC total-Equilibrage'!R133:R143) -> 12.9625 | O38: =SUM('PDC total-Equilibrage'!S133:S143) -> 17 | P38: =SUM('PDC total-Equilibrage'!T133:T143) -> 79.69667 | Q38: ='PDC total-Equilibrage'!D182 -> 45 | R38: =MROUND(SUM(N38:Q38),5) -> 155
C39: 16.SDR (Y'-Z') | D39: =('Bouche GP-GE '!E24)/2 -> 790 | E39: =SUM('PDC total-Equilibrage'!H57:H64) -> 14.4812 | F39: =SUM('PDC total-Equilibrage'!I57:I64) -> 27.5 | G39: =SUM('PDC total-Equilibrage'!J57:J64) -> 123.23314 | H39: ='PDC total-Equilibrage'!D91 -> 70 | I39: =MROUND(SUM(E39:H39),5) -> 235 | L39: 16.SDR (EE'-FF') | M39: =D39 -> 790 | N39: =SUM('PDC total-Equilibrage'!H152:H161) -> 12.838 | O39: =SUM('PDC total-Equilibrage'!I152:I161) -> 18 | P39: =SUM('PDC total-Equilibrage'!J152:J161) -> 64.748266 | Q39: ='PDC total-Equilibrage'!D185 -> 60 | R39: =MROUND(SUM(N39:Q39),5) -> 155
C40: 16.SDR (F'-G') | D40: =('Bouche GP-GE '!E24)/2 -> 790 | E40: =SUM('PDC total-Equilibrage'!M57:M64) -> 14.0982 | F40: =SUM('PDC total-Equilibrage'!N57:N64) -> 27.5 | G40: =SUM('PDC total-Equilibrage'!O57:O64) -> 126.88905 | H40: ='PDC total-Equilibrage'!D92 -> 65 | I40: =MROUND(SUM(E40:H40),5) -> 235 | L40: 16.SDR (GG'-HH') | M40: =D40 -> 790 | N40: =SUM('PDC total-Equilibrage'!R152:R160) -> 14.598 | O40: =SUM('PDC total-Equilibrage'!S152:S160) -> 18 | P40: =SUM('PDC total-Equilibrage'!T152:T160) -> 64.748266 | Q40: ='PDC total-Equilibrage'!D187 -> 60 | R40: =MROUND(SUM(N40:Q40),5) -> 155
